Workbook

Sheet GBP01 & Convexity
B2: 10-Year Bond | F2: 30-Year Bond | J2: 10 Year Gilt
B3: Price | C3: ='10 year Gilt (2)'!C3 -> 97.955381 | F3: Price | G3: ='30 year Gilt (2)'!C3 -> 86.576454 | J3: Change in BPs | K3: Change in BPs in Percentage | L3: New Yield | M3: Price (Full reval) | N3: PnL Full | O3: PnL DV01 | P3: PnL DV01+Conv | Q3: Error (GBP01) | R3: Error (GBP01+Conv) | T3: Change in BPs | U3: PnL Full | V3: PnL DV01 | W3: PnL DV01+Conv | Y3: Change in BPs | Z3: Error (GBP01) | AA3: Error (GBP01+Conv)
B4: Face Value | C4: ='10 year Gilt (2)'!C4 -> 100 | F4: Face Value | G4: ='30 year Gilt (2)'!C4 -> 100 | J4: -200 | K4: =J4/10000 -> -0.02 | L4: =K4+$C$5 -> 0.02557 | M4: 115.00928 | N4: =M4-$M$8 -> 17.053898 | O4: =-$C$28*K4*10000 -> 15.416422 | P4: =(-$M$8*$C$18*K4)+(0.5*$M$8*$C$23*(K4^2)) -> 17.00275 | Q4: =-($N4-O4) -> -1.637476 | R4: =($N4-P4) -> 0.051148564 | T4: -200 | U4: 16.772941 | V4: 31.146278 | W4: 37.50611 | Y4: -200 | Z4: 14.373337 | AA4: -20.733169
B5: Yield | C5: ='10 year Gilt (2)'!C5 -> 0.04557 | F5: Yield | G5: ='30 year Gilt (2)'!C5 -> 0.0534 | J5: -150 | K5: =J5/10000 -> -0.015 | L5: =K5+$C$5 -> 0.03057 | M5: 110.42118 | N5: =M5-$M$8 -> 12.465795 | O5: =-$C$28*K5*10000 -> 11.562317 | P5: =(-$M$8*$C$18*K5)+(0.5*$M$8*$C$23*(K5^2)) -> 12.454626 | Q5: =-($N5-O5) -> -0.90347809 | R5: =($N5-P5) -> 0.011168886 | T5: -150 | U5: 12.285734 | V5: 23.359708 | W5: 26.937675 | Y5: -150 | Z5: 11.073975 | AA5: -14.651942
B6: Coupon Rate | C6: ='10 year Gilt (2)'!C6 -> 0.0425 | F6: Coupon Rate | G6: ='30 year Gilt (2)'!C6 -> 0.04375 | J6: -100 | K6: =J6/10000 -> -0.01 | L6: =K6+$C$5 -> 0.03557 | M6: 106.05756 | N6: =M6-$M$8 -> 8.1021749 | O6: =-$C$28*K6*10000 -> 7.7082111 | P6: =(-$M$8*$C$18*K6)+(0.5*$M$8*$C$23*(K6^2)) -> 8.104793 | Q6: =-($N6-O6) -> -0.39396382 | R6: =($N6-P6) -> -0.0026180523 | T6: -100 | U6: 8.0010007 | V6: 15.573139 | W6: 17.163845 | Y6: -100 | Z6: 7.5721381 | AA6: -9.1628443
B7: Coupon | C7: ='10 year Gilt (2)'!C7 -> 4.25 | F7: Coupon | G7: ='30 year Gilt (2)'!C7 -> 4.375 | J7: -50 | K7: =J7/10000 -> -0.005 | L7: =K7+$C$5 -> 0.04057 | M7: 101.90614 | N7: =M7-$M$8 -> 3.9507589 | O7: =-$C$28*K7*10000 -> 3.8541056 | P7: =(-$M$8*$C$18*K7)+(0.5*$M$8*$C$23*(K7^2)) -> 3.953251 | Q7: =-($N7-O7) -> -0.096653363 | R7: =($N7-P7) -> -0.002492104 | T7: -50 | U7: 3.9088755 | V7: 7.7865694 | W7: 8.18462 | Y7: -50 | Z7: 3.8776939 | AA7: -4.2757445
B8: Semi-Annually Coupon | C8: ='10 year Gilt (2)'!C8 -> 2.125 | F8: Semi-Annually Coupon | G8: ='30 year Gilt (2)'!C8 -> 2.1875 | J8: 0 | K8: =J8/10000 -> 0 | L8: =K8+$C$5 -> 0.04557 | M8: 97.955381 | N8: =M8-$M$8 -> 0 | O8: =-$C$28*K8*10000 -> 0 | P8: =(-$M$8*$C$18*K8)+(0.5*$M$8*$C$23*(K8^2)) -> 0 | Q8: =-($N8-O8) -> 0 | R8: =($N8-P8) -> 0 | T8: 0 | U8: 0 | V8: 0 | W8: 0 | Y8: 0 | Z8: 0 | AA8: 0
J9: 50 | K9: =J9/10000 -> 0.005 | L9: =K9+$C$5 -> 0.05057 | M9: 94.194418 | N9: =M9-$M$8 -> -3.7609627 | O9: =-$C$28*K9*10000 -> -3.8541056 | P9: =(-$M$8*$C$18*K9)+(0.5*$M$8*$C$23*(K9^2)) -> -3.7549601 | Q9: =-($N9-O9) -> -0.093142912 | R9: =($N9-P9) -> -0.0060025551 | T9: 50 | U9: -3.7345023 | V9: -7.7865694 | W9: -7.3900149 | Y9: 50 | Z9: -4.0520671 | AA9: 3.6555126
J10: 100 | K10: =J10/10000 -> 0.01 | L10: =K10+$C$5 -> 0.05557 | M10: 90.613033 | N10: =M10-$M$8 -> -7.3423479 | O10: =-$C$28*K10*10000 -> -7.7082111 | P10: =(-$M$8*$C$18*K10)+(0.5*$M$8*$C$23*(K10^2)) -> -7.3116293 | Q10: =-($N10-O10) -> -0.36586325 | R10: =($N10-P10) -> -0.030718619 | T10: 100 | U10: -7.3030527 | V10: -15.573139 | W10: -13.985425 | Y10: 100 | Z10: -8.2700862 | AA10: 6.6823722
B11: Macaulay Duration | J11: 150 | K11: =J11/10000 -> 0.015 | L11: =K11+$C$5 -> 0.06057 | M11: 87.201607 | N11: =M11-$M$8 -> -10.753774 | O11: =-$C$28*K11*10000 -> -11.562317 | P11: =(-$M$8*$C$18*K11)+(0.5*$M$8*$C$23*(K11^2)) -> -10.670007 | Q11: =-($N11-O11) -> -0.80854319 | R11: =($N11-P11) -> -0.083766016 | T11: 150 | U11: -10.713641 | V11: -23.359708 | W11: -19.78623 | Y11: 150 | Z11: -12.646067 | AA11: 9.0725884
B12: Bond | C12: Base | D12: Parallel Up | E12: Parallel Down | J12: 200 | K12: =J12/10000 -> 0.02 | L12: =K12+$C$5 -> 0.06557 | M12: 83.951086 | N12: =M12-$M$8 -> -14.004294 | O12: =-$C$28*K12*10000 -> -15.416422 | P12: =(-$M$8*$C$18*K12)+(0.5*$M$8*$C$23*(K12^2)) -> -13.830095 | Q12: =-($N12-O12) -> -1.4121278 | R12: =($N12-P12) -> -0.17419968 | T12: 200 | U12: -13.973851 | V12: -31.146278 | W12: -24.792429 | Y12: 200 | Z12: -17.172427 | AA12: 10.818579
B13: 10 Year Gilt | C13: ='10 Year Scenario'!F26 -> 8.2276994 | D13: ='10 Year Scenario'!P26 -> 7.9713043 | E13: ='10 Year Scenario'!Z26 -> 8.4651883
B14: 30 Year Gilt | C14: ='30 Year Scenario'!F66 -> 15.986482 | D14: ='30 Year Scenario'!P66 -> 12.986392 | E14: ='30 Year Scenario'!Z66 -> 19.462825
J15: 10 Year Gilt
B16: Modified Duration | J16: Change in BPs | K16: Change in BPs in Percentage | L16: New Yield | M16: Price (Full reval) | N16: PnL Full | O16: PnL DV01 | P16: PnL DV01+Conv | Q16: Error (GBP01) | R16: Error (GBP01+Conv) | T16: Change in BPs | U16: PnL Full | V16: PnL DV01 | W16: PnL DV01+Conv | Y16: Change in BPs | Z16: Error (GBP01) | AA16: Error (GBP01+Conv)
B17: Bond | C17: Base | D17: Parallel Up | E17: Parallel Down | J17: -200 | K17: =J17/10000 -> -0.02 | L17: =K17+$G$5 -> 0.0334 | M17: 120.47328 | N17: =M17-$M$21 -> 33.778841 | O17: =-$C$29*K17*10000 -> 26.277823 | P17: =(-$M$21*$C$19*K17)+(0.5*$M$21*$C$24*(K17^2)) -> 32.513766 | Q17: =-($N17-O17) -> -7.5010179 | R17: =($N17-P17) -> 1.2650749 | T17: -200 | U17: 33.778841 | V17: 52.523234 | W17: 78.767934 | Y17: -200 | Z17: 18.744393 | AA17: -44.989093
B18: 10 Year Gilt | C18: ='10 Year Scenario'!F27 -> 7.8691044 | D18: ='10 Year Scenario'!P27 -> 7.6238839 | E18: ='10 Year Scenario'!Z26 -> 8.4651883 | J18: -150 | K18: =J18/10000 -> -0.015 | L18: =K18+$G$5 -> 0.0384 | M18: 110.50219 | N18: =M18-$M$21 -> 23.807747 | O18: =-$C$29*K18*10000 -> 19.708367 | P18: =(-$M$21*$C$19*K18)+(0.5*$M$21*$C$24*(K18^2)) -> 23.2228 | Q18: =-($N18-O18) -> -4.09938 | R18: =($N18-P18) -> 0.58494741 | T18: -150 | U18: 23.807747 | V18: 39.392426 | W18: 54.176859 | Y18: -150 | Z18: 15.584678 | AA18: -30.369111
B19: 30 Year Gilt | C19: ='30 Year Scenario'!F67 -> 15.176079 | D19: ='30 Year Scenario'!P67 -> 12.328073 | E19: ='30 Year Scenario'!Z67 -> 18.476196 | J19: -100 | K19: =J19/10000 -> -0.01 | L19: =K19+$G$5 -> 0.0434 | M19: 101.63646 | N19: =M19-$M$21 -> 14.942023 | O19: =-$C$29*K19*10000 -> 13.138911 | P19: =(-$M$21*$C$19*K19)+(0.5*$M$21*$C$24*(K19^2)) -> 14.70685 | Q19: =-($N19-O19) -> -1.8031116 | R19: =($N19-P19) -> 0.2351729 | T19: -100 | U19: 14.942023 | V19: 26.261617 | W19: 32.851845 | Y19: -100 | Z19: 11.319594 | AA19: -17.909822
J20: -50 | K20: =J20/10000 -> -0.005 | L20: =K20+$G$5 -> 0.0484 | M20: 93.740017 | N20: =M20-$M$21 -> 7.0455751 | O20: =-$C$29*K20*10000 -> 6.5694557 | P20: =(-$M$21*$C$19*K20)+(0.5*$M$21*$C$24*(K20^2)) -> 6.9659169 | Q20: =-($N20-O20) -> -0.4761194 | R20: =($N20-P20) -> 0.079658284 | T20: -50 | U20: 7.0455751 | V20: 13.130809 | W20: 14.792892 | Y20: -50 | Z20: 6.0852334 | AA20: -7.7473166
B21: Convexity | J21: 0 | K21: =J21/10000 -> 0 | L21: =K21+$G$5 -> 0.0534 | M21: 86.694441 | N21: =M21-$M$21 -> 0 | O21: =-$C$29*K21*10000 -> 0 | P21: =(-$M$21*$C$19*K21)+(0.5*$M$21*$C$24*(K21^2)) -> 0 | Q21: =-($N21-O21) -> 0 | R21: =($N21-P21) -> 0 | T21: 0 | U21: 0 | V21: 0 | W21: 0 | Y21: 0 | Z21: 0 | AA21: 0
B22: Bond | C22: Base | D22: Parallel Up | E22: Parallel Down | J22: 50 | K22: =J22/10000 -> 0.005 | L22: =K22+$G$5 -> 0.0584 | M22: 80.396644 | N22: =M22-$M$21 -> -6.2977975 | O22: =-$C$29*K22*10000 -> -6.5694557 | P22: =(-$M$21*$C$19*K22)+(0.5*$M$21*$C$24*(K22^2)) -> -6.1909004 | Q22: =-($N22-O22) -> -0.2716582 | R22: =($N22-P22) -> -0.10689711 | T22: 50 | U22: -6.2977975 | V22: -13.130809 | W22: -11.526831 | Y22: 50 | Z22: -6.833011 | AA22: 5.229033
B23: 10 Year Gilt | C23: ='10 Year Scenario'!F28 -> 80.971942 | D23: ='10 Year Scenario'!P28 -> 73.830123 | E23: ='10 Year Scenario'!Z28 -> 80.030609 | J23: 100 | K23: =J23/10000 -> 0.01 | L23: =K23+$G$5 -> 0.0634 | M23: 74.756785 | N23: =M23-$M$21 -> -11.937656 | O23: =-$C$29*K23*10000 -> -13.138911 | P23: =(-$M$21*$C$19*K23)+(0.5*$M$21*$C$24*(K23^2)) -> -11.606784 | Q23: =-($N23-O23) -> -1.2012551 | R23: =($N23-P23) -> -0.3308719 | T23: 100 | U23: -11.937656 | V23: -26.261617 | W23: -19.7876 | Y23: 100 | Z23: -14.323961 | AA23: 7.8499436
B24: 30 Year Gilt | C24: ='30 Year Scenario'!F68 -> 357.58529 | D24: ='30 Year Scenario'!P68 -> 258.69985 | E24: ='30 Year Scenario'!Z68 -> 476.00867 | J24: 150 | K24: =J24/10000 -> 0.015 | L24: =K24+$G$5 -> 0.0684 | M24: 69.696513 | N24: =M24-$M$21 -> -16.997929 | O24: =-$C$29*K24*10000 -> -19.708367 | P24: =(-$M$21*$C$19*K24)+(0.5*$M$21*$C$24*(K24^2)) -> -16.247652 | Q24: =-($N24-O24) -> -2.7104386 | R24: =($N24-P24) -> -0.75027657 | T24: 150 | U24: -16.997929 | V24: -39.392426 | W24: -24.782308 | Y24: 150 | Z24: -22.394497 | AA24: 7.7843795
J25: 200 | K25: =J25/10000 -> 0.02 | L25: =K25+$G$5 -> 0.0734 | M25: 65.147435 | N25: =M25-$M$21 -> -21.547007 | O25: =-$C$29*K25*10000 -> -26.277823 | P25: =(-$M$21*$C$19*K25)+(0.5*$M$21*$C$24*(K25^2)) -> -20.113503 | Q25: =-($N25-O25) -> -4.7308163 | R25: =($N25-P25) -> -1.4335034 | T25: 200 | U25: -21.547007 | V25: -52.523234 | W25: -26.510955 | Y25: 200 | Z25: -30.976227 | AA25: 4.9639485
B26: GBP01
B27: Bond | C27: Base | D27: Parallel Up | E27: Parallel Down
B28: 10 Year Gilt | C28: ='10 Year Scenario'!F29 -> 0.077082111 | D28: ='10 Year Scenario'!P29 -> 0.063159774 | E28: ='10 Year Scenario'!Z29 -> 0.094805764
B29: 30 Year Gilt | C29: ='30 Year Scenario'!F69 -> 0.13138911 | D29: ='30 Year Scenario'!P69 -> 0.08144587 | E29: ='30 Year Scenario'!Z69 -> 0.23354801

Sheet 10 year Gilt (2)
B2: 10-Year Bond | F2: Period | G2: Cash Flow | H2: PV of CF | I2: PV as % of Sum of PV | J2: TW PV of CF | K2: TW^2 PV of CF | N2: Yield | O2: Price | P2: Duration Implied Price | Q2: Convexity Implied Price
B3: Price | C3: =H23 -> 97.955381 | F3: 0.5 | G3: =$C$8 -> 2.125 | H3: =G3/(1+$C$5)^F3 -> 2.0781763 | I3: =H3/$H$23 -> 0.02121554 | J3: =I3*F3 -> 0.01060777 | K3: =F3*H3*(F3+0.5) -> 1.0390881 | N3: 0.01 | O3: 131.64412 | P3: =$H$23*(1-$C$12*(N3-$C$5)) -> 125.33814 | Q3: =(1+((-$C$12*(N3-$C$5))+(0.5*$C$13*(N3-$C$5)^2)))*$H$23 -> 130.11147
B4: Face Value | C4: 100 | F4: 1 | G4: =$C$8 -> 2.125 | H4: =G4/(1+$C$5)^F4 -> 2.0323842 | I4: =H4/$H$23 -> 0.020748061 | J4: =I4*F4 -> 0.020748061 | K4: =F4*H4*(F4+0.5) -> 3.0485764 | N4: 0.015 | O4: 126.47024 | P4: =$H$23*(1-$C$12*(N4-$C$5)) -> 121.489 | Q4: =(1+((-$C$12*(N4-$C$5))+(0.5*$C$13*(N4-$C$5)^2)))*$H$23 -> 125.0147
B5: Yield | C5: 0.04557 | F5: 1.5 | G5: =$C$8 -> 2.125 | H5: =G5/(1+$C$5)^F5 -> 1.9876013 | I5: =H5/$H$23 -> 0.020290884 | J5: =I5*F5 -> 0.030436326 | K5: =F5*H5*(F5+0.5) -> 5.9628038 | N5: 0.02 | O5: 121.53251 | P5: =$H$23*(1-$C$12*(N5-$C$5)) -> 117.63987 | Q5: =(1+((-$C$12*(N5-$C$5))+(0.5*$C$13*(N5-$C$5)^2)))*$H$23 -> 120.10656
B6: Coupon Rate | C6: 0.0425 | F6: 2 | G6: =$C$8 -> 2.125 | H6: =G6/(1+$C$5)^F6 -> 1.9438051 | I6: =H6/$H$23 -> 0.01984378 | J6: =I6*F6 -> 0.039687561 | K6: =F6*H6*(F6+0.5) -> 9.7190253 | N6: 0.025 | O6: 116.81931 | P6: =$H$23*(1-$C$12*(N6-$C$5)) -> 113.79073 | Q6: =(1+((-$C$12*(N6-$C$5))+(0.5*$C$13*(N6-$C$5)^2)))*$H$23 -> 115.38706
B7: Coupon | C7: =C4*C6 -> 4.25 | F7: 2.5 | G7: =$C$8 -> 2.125 | H7: =G7/(1+$C$5)^F7 -> 1.9009739 | I7: =H7/$H$23 -> 0.019406528 | J7: =I7*F7 -> 0.048516321 | K7: =F7*H7*(F7+0.5) -> 14.257304 | N7: 0.03 | O7: 112.31963 | P7: =$H$23*(1-$C$12*(N7-$C$5)) -> 109.94159 | Q7: =(1+((-$C$12*(N7-$C$5))+(0.5*$C$13*(N7-$C$5)^2)))*$H$23 -> 110.85619
B8: Semi-Annually Coupon | C8: =C7/2 -> 2.125 | F8: 3 | G8: =$C$8 -> 2.125 | H8: =G8/(1+$C$5)^F8 -> 1.8590865 | I8: =H8/$H$23 -> 0.018978911 | J8: =I8*F8 -> 0.056936734 | K8: =F8*H8*(F8+0.5) -> 19.520408 | N8: 0.035 | O8: 108.02303 | P8: =$H$23*(1-$C$12*(N8-$C$5)) -> 106.09246 | Q8: =(1+((-$C$12*(N8-$C$5))+(0.5*$C$13*(N8-$C$5)^2)))*$H$23 -> 106.51396
F9: 3.5 | G9: =$C$8 -> 2.125 | H9: =G9/(1+$C$5)^F9 -> 1.8181221 | I9: =H9/$H$23 -> 0.018560717 | J9: =I9*F9 -> 0.064962508 | K9: =F9*H9*(F9+0.5) -> 25.453709 | N9: 0.04 | O9: 103.91962 | P9: =$H$23*(1-$C$12*(N9-$C$5)) -> 102.24332 | Q9: =(1+((-$C$12*(N9-$C$5))+(0.5*$C$13*(N9-$C$5)^2)))*$H$23 -> 102.36037
F10: 4 | G10: =$C$8 -> 2.125 | H10: =G10/(1+$C$5)^F10 -> 1.7780603 | I10: =H10/$H$23 -> 0.018151737 | J10: =I10*F10 -> 0.072606947 | K10: =F10*H10*(F10+0.5) -> 32.005085 | N10: 0.045 | O10: 100 | P10: 100 | Q10: =(1+((-$C$12*(N10-$C$5))+(0.5*$C$13*(N10-$C$5)^2)))*$H$23 -> 98.395408
B11: Macaulay Duration | C11: =J23 -> 8.2170917 | F11: 4.5 | G11: =$C$8 -> 2.125 | H11: =G11/(1+$C$5)^F11 -> 1.7388812 | I11: =H11/$H$23 -> 0.017751769 | J11: =I11*F11 -> 0.079882958 | K11: =F11*H11*(F11+0.5) -> 39.124828 | N11: 0.05 | O11: 96.255277 | P11: =$H$23*(1-$C$12*(N11-$C$5)) -> 94.545046 | Q11: =(1+((-$C$12*(N11-$C$5))+(0.5*$C$13*(N11-$C$5)^2)))*$H$23 -> 94.619085
B12: Modified Duration | C12: =C11/(1+C5) -> 7.8589589 | F12: 5 | G12: =$C$8 -> 2.125 | H12: =G12/(1+$C$5)^F12 -> 1.7005655 | I12: =H12/$H$23 -> 0.017360614 | J12: =I12*F12 -> 0.086803068 | K12: =F12*H12*(F12+0.5) -> 46.765551 | N12: 0.055 | O12: 92.676999 | P12: =$H$23*(1-$C$12*(N12-$C$5)) -> 90.695909 | Q12: =(1+((-$C$12*(N12-$C$5))+(0.5*$C$13*(N12-$C$5)^2)))*$H$23 -> 91.031397
B13: Convexity | C13: =K23/(H23*(1+C5/2)^2) -> 77.029202 | F13: 5.5 | G13: =$C$8 -> 2.125 | H13: =G13/(1+$C$5)^F13 -> 1.663094 | I13: =H13/$H$23 -> 0.016978078 | J13: =I13*F13 -> 0.093379426 | K13: =F13*H13*(F13+0.5) -> 54.882104 | N13: 0.06 | O13: 89.257151 | P13: =$H$23*(1-$C$12*(N13-$C$5)) -> 86.846773 | Q13: =(1+((-$C$12*(N13-$C$5))+(0.5*$C$13*(N13-$C$5)^2)))*$H$23 -> 87.632345
F14: 6 | G14: =$C$8 -> 2.125 | H14: =G14/(1+$C$5)^F14 -> 1.6264483 | I14: =H14/$H$23 -> 0.016603971 | J14: =I14*F14 -> 0.099623823 | K14: =F14*H14*(F14+0.5) -> 63.431482 | N14: 0.065 | O14: 85.988125 | P14: =$H$23*(1-$C$12*(N14-$C$5)) -> 82.997636 | Q14: =(1+((-$C$12*(N14-$C$5))+(0.5*$C$13*(N14-$C$5)^2)))*$H$23 -> 84.421929
F15: 6.5 | G15: =$C$8 -> 2.125 | H15: =G15/(1+$C$5)^F15 -> 1.59061 | I15: =H15/$H$23 -> 0.016238107 | J15: =I15*F15 -> 0.1055477 | K15: =F15*H15*(F15+0.5) -> 72.372753 | N15: 0.07 | O15: 82.862703 | P15: =$H$23*(1-$C$12*(N15-$C$5)) -> 79.148499 | Q15: =(1+((-$C$12*(N15-$C$5))+(0.5*$C$13*(N15-$C$5)^2)))*$H$23 -> 81.400148
F16: 7 | G16: =$C$8 -> 2.125 | H16: =G16/(1+$C$5)^F16 -> 1.5555613 | I16: =H16/$H$23 -> 0.015880305 | J16: =I16*F16 -> 0.11116214 | K16: =F16*H16*(F16+0.5) -> 81.66697 | N16: 0.075 | O16: 79.874032 | P16: =$H$23*(1-$C$12*(N16-$C$5)) -> 75.299363 | Q16: =(1+((-$C$12*(N16-$C$5))+(0.5*$C$13*(N16-$C$5)^2)))*$H$23 -> 78.567003
F17: 7.5 | G17: =$C$8 -> 2.125 | H17: =G17/(1+$C$5)^F17 -> 1.521285 | I17: =H17/$H$23 -> 0.015530387 | J17: =I17*F17 -> 0.1164779 | K17: =F17*H17*(F17+0.5) -> 91.2771 | N17: 0.08 | O17: 77.015606 | P17: =$H$23*(1-$C$12*(N17-$C$5)) -> 71.450226 | Q17: =(1+((-$C$12*(N17-$C$5))+(0.5*$C$13*(N17-$C$5)^2)))*$H$23 -> 75.922494
F18: 8 | G18: =$C$8 -> 2.125 | H18: =G18/(1+$C$5)^F18 -> 1.4877639 | I18: =H18/$H$23 -> 0.01518818 | J18: =I18*F18 -> 0.12150544 | K18: =F18*H18*(F18+0.5) -> 101.16795
F19: 8.5 | G19: =$C$8 -> 2.125 | H19: =G19/(1+$C$5)^F19 -> 1.4549815 | I19: =H19/$H$23 -> 0.014853513 | J19: =I19*F19 -> 0.12625486 | K19: =F19*H19*(F19+0.5) -> 111.30608
F20: 9 | G20: =$C$8 -> 2.125 | H20: =G20/(1+$C$5)^F20 -> 1.4229214 | I20: =H20/$H$23 -> 0.01452622 | J20: =I20*F20 -> 0.13073598 | K20: =F20*H20*(F20+0.5) -> 121.65978
F21: 9.5 | G21: =$C$8 -> 2.125 | H21: =G21/(1+$C$5)^F21 -> 1.3915677 | I21: =H21/$H$23 -> 0.014206139 | J21: =I21*F21 -> 0.13495832 | K21: =F21*H21*(F21+0.5) -> 132.19894
F22: 10 | G22: =$C$8+C4 -> 102.125 | H22: =G22/(1+$C$5)^F22 -> 65.403491 | I22: =H22/$H$23 -> 0.66768656 | J22: =I22*F22 -> 6.6768656 | K22: =F22*H22*(F22+0.5) -> 6867.3666
H23: =SUM(H3:H22) -> 97.955381 | J23: =SUM(J4:J22) -> 8.2170917 | K23: =SUM(K4:K22) -> 7893.187
H26: =H23 -> 97.955381
G27: 0.02557 | H27: 115.00928
G28: 0.03057 | H28: 110.42118
G29: 0.03557 | H29: 106.05756
G30: 0.04057 | H30: 101.90614
G31: 0.04557 | H31: 97.955381
G32: 0.05057 | H32: 94.194418
G33: 0.05557 | H33: 90.613033
G34: 0.06057 | H34: 87.201607
G35: 0.06557 | H35: 83.951086

Sheet 10 Year Scenario
O2: Parallel Up | P2: 0.0025 | Y2: Parallel Down | Z2: 0.0025
B3: 10-Year Bond | E3: Period | F3: Scenario Rate | G3: Cash Flow | H3: PV of CF | I3: PV as % of CF | J3: TW PV of CF | K3: Reivestment as per theory | L3: TW^2 PV of CF | O3: Period | P3: Scenario Rate | Q3: Cash Flow | R3: PV of CF | S3: PV as % of CF | T3: TW PV of CF | U3: Reivestment as per theory | V3: TW^2 PV of CF | Y3: Period | Z3: Scenario Rate | AA3: Cash Flow | AB3: PV of CF | AC3: PV as % of CF | AD3: TW PV of CF | AE3: Reivestment as per theory | AF3: TW^2 PV of CF
B4: Price | C4: ='10 year Gilt (2)'!C3 -> 97.955381 | E4: 0.5 | F4: =$C$6 -> 0.04557 | G4: =$C$9 -> 2.125 | H4: =G4/(1+F4)^E4 -> 2.0781763 | I4: =H4/$H$24 -> 0.02121554 | J4: =I4*E4 -> 0.01060777 | K4: =H4*(1+F4)^($E$20-E4) -> 2.9682966 | L4: =E4*(E4+1)*H4 -> 1.5586322 | O4: 0.5 | P4: =$C$6 -> 0.04557 | Q4: =$C$9 -> 2.125 | R4: =Q4/(1+P4)^O4 -> 2.0781763 | S4: =R4/$R$24 -> 0.02508523 | T4: =S4*O4 -> 0.012542615 | U4: =R4*(1+P4)^($O$19-O4) -> 2.902891 | V4: =O4*R4*(O4+0.5) -> 1.0390881 | Y4: 0.5 | Z4: =C6 -> 0.04557 | AA4: =$C$9 -> 2.125 | AB4: =AA4/(1+Z4)^Y4 -> 2.0781763 | AC4: =AB4/$AB$24 -> 0.017747253 | AD4: =AC4*Y4 -> 0.0088736265 | AE4: =AB4*(1+Z4)^($Y$20-Y4) -> 2.9682966 | AF4: =Y4*AB4*(Y4+0.5) -> 1.0390881
B5: Face Value | C5: ='10 year Gilt (2)'!C4 -> 100 | E5: 1 | F5: =$C$6 -> 0.04557 | G5: =$C$9 -> 2.125 | H5: =G5/(1+F5)^E5 -> 2.0323842 | I5: =H5/$H$24 -> 0.020748061 | J5: =I5*E5 -> 0.020748061 | K5: =H5*(1+F5)^($E$20-E5) -> 2.8389267 | L5: =E5*(E5+1)*H5 -> 4.0647685 | O5: 1 | P5: =P4+$P$2/2 -> 0.04682 | Q5: =$C$9 -> 2.125 | R5: =Q5/(1+P5)^O5 -> 2.0299574 | S5: =R5/$R$24 -> 0.02450319 | T5: =S5*O5 -> 0.02450319 | U5: =R5*(1+P5)^($O$19-O5) -> 2.7963466 | V5: =O5*R5*(O5+0.5) -> 3.0449361 | Y5: 1 | Z5: =Z4-$P$2/2 -> 0.04432 | AA5: =$C$9 -> 2.125 | AB5: =AA5/(1+Z5)^Y5 -> 2.0348169 | AC5: =AB5/$AB$24 -> 0.017376972 | AD5: =AC5*Y5 -> 0.017376972 | AE5: =AB5*(1+Z5)^($Y$20-Y5) -> 2.8169381 | AF5: =Y5*AB5*(Y5+0.5) -> 3.0522254
B6: Yield | C6: ='10 year Gilt (2)'!C5 -> 0.04557 | E6: 1.5 | F6: =$C$6 -> 0.04557 | G6: =$C$9 -> 2.125 | H6: =G6/(1+F6)^E6 -> 1.9876013 | I6: =H6/$H$24 -> 0.020290884 | J6: =I6*E6 -> 0.030436326 | K6: =H6*(1+F6)^($E$20-E6) -> 2.7151952 | L6: =E6*(E6+1)*H6 -> 7.4535047 | O6: 1.5 | P6: =P5+$P$2/2 -> 0.04807 | Q6: =$C$9 -> 2.125 | R6: =Q6/(1+P6)^O6 -> 1.9804939 | S6: =R6/$R$24 -> 0.023906126 | T6: =S6*O6 -> 0.035859189 | U6: =R6*(1+P6)^($O$19-O6) -> 2.6872643 | V6: =O6*R6*(O6+0.5) -> 5.9414816 | Y6: 1.5 | Z6: =Z5-$P$2/2 -> 0.04307 | AA6: =$C$9 -> 2.125 | AB6: =AA6/(1+Z6)^Y6 -> 1.9947513 | AC6: =AB6/$AB$24 -> 0.017034819 | AD6: =AC6*Y6 -> 0.025552228 | AE6: =AB6*(1+Z6)^($Y$20-Y6) -> 2.67968 | AF6: =Y6*AB6*(Y6+0.5) -> 5.9842538
B7: Coupon Rate | C7: ='10 year Gilt (2)'!C6 -> 0.0425 | E7: 2 | F7: =$C$6 -> 0.04557 | G7: =$C$9 -> 2.125 | H7: =G7/(1+F7)^E7 -> 1.9438051 | I7: =H7/$H$24 -> 0.01984378 | J7: =I7*E7 -> 0.039687561 | K7: =H7*(1+F7)^($E$20-E7) -> 2.5968565 | L7: =E7*(E7+1)*H7 -> 11.66283 | O7: 2 | P7: =P6+$P$2/2 -> 0.04932 | Q7: =$C$9 -> 2.125 | R7: =Q7/(1+P7)^O7 -> 1.9299366 | S7: =R7/$R$24 -> 0.023295859 | T7: =S7*O7 -> 0.046591719 | U7: =R7*(1+P7)^($O$19-O7) -> 2.5762662 | V7: =O7*R7*(O7+0.5) -> 9.6496828 | Y7: 2 | Z7: =Z6-$P$2/2 -> 0.04182 | AA7: =$C$9 -> 2.125 | AB7: =AA7/(1+Z7)^Y7 -> 1.9578236 | AC7: =AB7/$AB$24 -> 0.016719463 | AD7: =AC7*Y7 -> 0.033438925 | AE7: =AB7*(1+Z7)^($Y$20-Y7) -> 2.5552067 | AF7: =Y7*AB7*(Y7+0.5) -> 9.7891179
B8: Coupon | C8: ='10 year Gilt (2)'!C7 -> 4.25 | E8: 2.5 | F8: =$C$6 -> 0.04557 | G8: =$C$9 -> 2.125 | H8: =G8/(1+F8)^E8 -> 1.9009739 | I8: =H8/$H$24 -> 0.019406528 | J8: =I8*E8 -> 0.048516321 | K8: =H8*(1+F8)^($E$20-E8) -> 2.4836754 | L8: =E8*(E8+1)*H8 -> 16.633521 | O8: 2.5 | P8: =P7+$P$2/2 -> 0.05057 | Q8: =$C$9 -> 2.125 | R8: =Q8/(1+P8)^O8 -> 1.8784362 | S8: =R8/$R$24 -> 0.022674209 | T8: =S8*O8 -> 0.056685523 | U8: =R8*(1+P8)^($O$19-O8) -> 2.4639615 | V8: =O8*R8*(O8+0.5) -> 14.088271 | Y8: 2.5 | Z8: =Z7-$P$2/2 -> 0.04057 | AA8: =$C$9 -> 2.125 | AB8: =AA8/(1+Z8)^Y8 -> 1.923892 | AC8: =AB8/$AB$24 -> 0.016429693 | AD8: =AC8*Y8 -> 0.041074232 | AE8: =AB8*(1+Z8)^($Y$20-Y8) -> 2.4423533 | AF8: =Y8*AB8*(Y8+0.5) -> 14.42919
B9: Semi-Annually Coupon | C9: ='10 year Gilt (2)'!C8 -> 2.125 | E9: 3 | F9: =$C$6 -> 0.04557 | G9: =$C$9 -> 2.125 | H9: =G9/(1+F9)^E9 -> 1.8590865 | I9: =H9/$H$24 -> 0.018978911 | J9: =I9*E9 -> 0.056936734 | K9: =H9*(1+F9)^($E$20-E9) -> 2.3754272 | L9: =E9*(E9+1)*H9 -> 22.309038 | O9: 3 | P9: =P8+$P$2/2 -> 0.05182 | Q9: =$C$9 -> 2.125 | R9: =Q9/(1+P9)^O9 -> 1.8261425 | S9: =R9/$R$24 -> 0.022042983 | T9: =S9*O9 -> 0.066128949 | U9: =R9*(1+P9)^($O$19-O9) -> 2.3509413 | V9: =O9*R9*(O9+0.5) -> 19.174496 | Y9: 3 | Z9: =Z8-$P$2/2 -> 0.03932 | AA9: =$C$9 -> 2.125 | AB9: =AA9/(1+Z9)^Y9 -> 1.8928277 | AC9: =AB9/$AB$24 -> 0.01616441 | AD9: =AC9*Y9 -> 0.048493229 | AE9: =AB9*(1+Z9)^($Y$20-Y9) -> 2.3400878 | AF9: =Y9*AB9*(Y9+0.5) -> 19.874691
E10: 3.5 | F10: =$C$6 -> 0.04557 | G10: =$C$9 -> 2.125 | H10: =G10/(1+F10)^E10 -> 1.8181221 | I10: =H10/$H$24 -> 0.018560717 | J10: =I10*E10 -> 0.064962508 | K10: =H10*(1+F10)^($E$20-E10) -> 2.2718968 | L10: =E10*(E10+1)*H10 -> 28.635422 | O10: 3.5 | P10: =P9+$P$2/2 -> 0.05307 | Q10: =$C$9 -> 2.125 | R10: =Q10/(1+P10)^O10 -> 1.7732035 | S10: =R10/$R$24 -> 0.021403968 | T10: =S10*O10 -> 0.074913888 | U10: =R10*(1+P10)^($O$19-O10) -> 2.2377737 | V10: =O10*R10*(O10+0.5) -> 24.82485 | Y10: 3.5 | Z10: =Z9-$P$2/2 -> 0.03807 | AA10: =$C$9 -> 2.125 | AB10: =AA10/(1+Z10)^Y10 -> 1.8645142 | AC10: =AB10/$AB$24 -> 0.015922617 | AD10: =AC10*Y10 -> 0.055729161 | AE10: =AB10*(1+Z10)^($Y$20-Y10) -> 2.2474958 | AF10: =Y10*AB10*(Y10+0.5) -> 26.103199
E11: 4 | F11: =$C$6 -> 0.04557 | G11: =$C$9 -> 2.125 | H11: =G11/(1+F11)^E11 -> 1.7780603 | I11: =H11/$H$24 -> 0.018151737 | J11: =I11*E11 -> 0.072606947 | K11: =H11*(1+F11)^($E$20-E11) -> 2.1728787 | L11: =E11*(E11+1)*H11 -> 35.561206 | O11: 4 | P11: =P10+$P$2/2 -> 0.05432 | Q11: =$C$9 -> 2.125 | R11: =Q11/(1+P11)^O11 -> 1.7197652 | S11: =R11/$R$24 -> 0.020758925 | T11: =S11*O11 -> 0.083035699 | U11: =R11*(1+P11)^($O$19-O11) -> 2.125 | V11: =O11*R11*(O11+0.5) -> 30.955773 | Y11: 4 | Z11: =Z10-$P$2/2 -> 0.03682 | AA11: =$C$9 -> 2.125 | AB11: =AA11/(1+Z11)^Y11 -> 1.8388465 | AC11: =AB11/$AB$24 -> 0.01570342 | AD11: =AC11*Y11 -> 0.062813678 | AE11: =AB11*(1+Z11)^($Y$20-Y11) -> 2.1637676 | AF11: =Y11*AB11*(Y11+0.5) -> 33.099236
E12: 4.5 | F12: =$C$6 -> 0.04557 | G12: =$C$9 -> 2.125 | H12: =G12/(1+F12)^E12 -> 1.7388812 | I12: =H12/$H$24 -> 0.017751769 | J12: =I12*E12 -> 0.079882958 | K12: =H12*(1+F12)^($E$20-E12) -> 2.0781763 | L12: =E12*(E12+1)*H12 -> 43.037311 | O12: 4.5 | P12: =P11+$P$2/2 -> 0.05557 | Q12: =$C$9 -> 2.125 | R12: =Q12/(1+P12)^O12 -> 1.6659703 | S12: =R12/$R$24 -> 0.020109578 | T12: =S12*O12 -> 0.090493102 | U12: =R12*(1+P12)^($O$19-O12) -> 2.0131303 | V12: =O12*R12*(O12+0.5) -> 37.484332 | Y12: 4.5 | Z12: =Z11-$P$2/2 -> 0.03557 | AA12: =$C$9 -> 2.125 | AB12: =AA12/(1+Z12)^Y12 -> 1.8157304 | AC12: =AB12/$AB$24 -> 0.015506012 | AD12: =AC12*Y12 -> 0.069777056 | AE12: =AB12*(1+Z12)^($Y$20-Y12) -> 2.0881861 | AF12: =Y12*AB12*(Y12+0.5) -> 40.853934
E13: 5 | F13: =$C$6 -> 0.04557 | G13: =$C$9 -> 2.125 | H13: =G13/(1+F13)^E13 -> 1.7005655 | I13: =H13/$H$24 -> 0.017360614 | J13: =I13*E13 -> 0.086803068 | K13: =H13*(1+F13)^($E$20-E13) -> 1.9876013 | L13: =E13*(E13+1)*H13 -> 51.016965 | O13: 5 | P13: =P12+$P$2/2 -> 0.05682 | Q13: =$C$9 -> 2.125 | R13: =Q13/(1+P13)^O13 -> 1.6119584 | S13: =R13/$R$24 -> 0.019457611 | T13: =S13*O13 -> 0.097288056 | U13: =R13*(1+P13)^($O$19-O13) -> 1.9026412 | V13: =O13*R13*(O13+0.5) -> 44.328855 | Y13: 5 | Z13: =Z12-$P$2/2 -> 0.03432 | AA13: =$C$9 -> 2.125 | AB13: =AA13/(1+Z13)^Y13 -> 1.7950821 | AC13: =AB13/$AB$24 -> 0.01532968 | AD13: =AC13*Y13 -> 0.0766484 | AE13: =AB13*(1+Z13)^($Y$20-Y13) -> 2.0201171 | AF13: =Y13*AB13*(Y13+0.5) -> 49.364758
E14: 5.5 | F14: =$C$6 -> 0.04557 | G14: =$C$9 -> 2.125 | H14: =G14/(1+F14)^E14 -> 1.663094 | I14: =H14/$H$24 -> 0.016978078 | J14: =I14*E14 -> 0.093379426 | K14: =H14*(1+F14)^($E$20-E14) -> 1.9009739 | L14: =E14*(E14+1)*H14 -> 59.455612 | O14: 5.5 | P14: =P13+$P$2/2 -> 0.05807 | Q14: =$C$9 -> 2.125 | R14: =Q14/(1+P14)^O14 -> 1.5578647 | S14: =R14/$R$24 -> 0.018804658 | T14: =S14*O14 -> 0.10342562 | U14: =R14*(1+P14)^($O$19-O14) -> 1.7939723 | V14: =O14*R14*(O14+0.5) -> 51.409534 | Y14: 5.5 | Z14: =Z13-$P$2/2 -> 0.03307 | AA14: =$C$9 -> 2.125 | AB14: =AA14/(1+Z14)^Y14 -> 1.7768277 | AC14: =AB14/$AB$24 -> 0.01517379 | AD14: =AC14*Y14 -> 0.083455846 | AE14: =AB14*(1+Z14)^($Y$20-Y14) -> 1.9590006 | AF14: =Y14*AB14*(Y14+0.5) -> 58.635313
E15: 6 | F15: =$C$6 -> 0.04557 | G15: =$C$9 -> 2.125 | H15: =G15/(1+F15)^E15 -> 1.6264483 | I15: =H15/$H$24 -> 0.016603971 | J15: =I15*E15 -> 0.099623823 | K15: =H15*(1+F15)^($E$20-E15) -> 1.8181221 | L15: =E15*(E15+1)*H15 -> 68.310827 | O15: 6 | P15: =P14+$P$2/2 -> 0.05932 | Q15: =$C$9 -> 2.125 | R15: =Q15/(1+P15)^O15 -> 1.5038202 | S15: =R15/$R$24 -> 0.018152298 | T15: =S15*O15 -> 0.10891379 | U15: =R15*(1+P15)^($O$19-O15) -> 1.6875251 | V15: =O15*R15*(O15+0.5) -> 58.648986 | Y15: 6 | Z15: =Z14-$P$2/2 -> 0.03182 | AA15: =$C$9 -> 2.125 | AB15: =AA15/(1+Z15)^Y15 -> 1.7609024 | AC15: =AB15/$AB$24 -> 0.015037791 | AD15: =AC15*Y15 -> 0.090226747 | AE15: =AB15*(1+Z15)^($Y$20-Y15) -> 1.9043428 | AF15: =Y15*AB15*(Y15+0.5) -> 68.675193
E16: 6.5 | F16: =$C$6 -> 0.04557 | G16: =$C$9 -> 2.125 | H16: =G16/(1+F16)^E16 -> 1.59061 | I16: =H16/$H$24 -> 0.016238107 | J16: =I16*E16 -> 0.1055477 | K16: =H16*(1+F16)^($E$20-E16) -> 1.7388812 | L16: =E16*(E16+1)*H16 -> 77.542235 | O16: 6.5 | P16: =P15+$P$2/2 -> 0.06057 | Q16: =$C$9 -> 2.125 | R16: =Q16/(1+P16)^O16 -> 1.4499507 | S16: =R16/$R$24 -> 0.017502051 | T16: =S16*O16 -> 0.11376333 | U16: =R16*(1+P16)^($O$19-O16) -> 1.5836611 | V16: =O16*R16*(O16+0.5) -> 65.972757 | Y16: 6.5 | Z16: =Z15-$P$2/2 -> 0.03057 | AA16: =$C$9 -> 2.125 | AB16: =AA16/(1+Z16)^Y16 -> 1.7472506 | AC16: =AB16/$AB$24 -> 0.014921208 | AD16: =AC16*Y16 -> 0.09698785 | AE16: =AB16*(1+Z16)^($Y$20-Y16) -> 1.8557104 | AF16: =Y16*AB16*(Y16+0.5) -> 79.499905
E17: 7 | F17: =$C$6 -> 0.04557 | G17: =$C$9 -> 2.125 | H17: =G17/(1+F17)^E17 -> 1.5555613 | I17: =H17/$H$24 -> 0.015880305 | J17: =I17*E17 -> 0.11116214 | K17: =H17*(1+F17)^($E$20-E17) -> 1.663094 | L17: =E17*(E17+1)*H17 -> 87.111434 | O17: 7 | P17: =P16+$P$2/2 -> 0.06182 | Q17: =$C$9 -> 2.125 | R17: =Q17/(1+P17)^O17 -> 1.3963768 | S17: =R17/$R$24 -> 0.016855371 | T17: =S17*O17 -> 0.1179876 | U17: =R17*(1+P17)^($O$19-O17) -> 1.4827008 | V17: =O17*R17*(O17+0.5) -> 73.309782 | Y17: 7 | Z17: =Z16-$P$2/2 -> 0.02932 | AA17: =$C$9 -> 2.125 | AB17: =AA17/(1+Z17)^Y17 -> 1.7358255 | AC17: =AB17/$AB$24 -> 0.014823639 | AD17: =AC17*Y17 -> 0.10376547 | AE17: =AB17*(1+Z17)^($Y$20-Y17) -> 1.8127239 | AF17: =Y17*AB17*(Y17+0.5) -> 91.130837
E18: 7.5 | F18: =$C$6 -> 0.04557 | G18: =$C$9 -> 2.125 | H18: =G18/(1+F18)^E18 -> 1.521285 | I18: =H18/$H$24 -> 0.015530387 | J18: =I18*E18 -> 0.1164779 | K18: =H18*(1+F18)^($E$20-E18) -> 1.59061 | L18: =E18*(E18+1)*H18 -> 96.981918 | O18: 7.5 | P18: =P17+$P$2/2 -> 0.06307 | Q18: =$C$9 -> 2.125 | R18: =Q18/(1+P18)^O18 -> 1.3432132 | S18: =R18/$R$24 -> 0.016213645 | T18: =S18*O18 -> 0.12160234 | U18: =R18*(1+P18)^($O$19-O18) -> 1.3849239 | V18: =O18*R18*(O18+0.5) -> 80.592795 | Y18: 7.5 | Z18: =Z17-$P$2/2 -> 0.02807 | AA18: =$C$9 -> 2.125 | AB18: =AA18/(1+Z18)^Y18 -> 1.7265883 | AC18: =AB18/$AB$24 -> 0.014744755 | AD18: =AC18*Y18 -> 0.11058566 | AE18: =AB18*(1+Z18)^($Y$20-Y18) -> 1.7750536 | AF18: =Y18*AB18*(Y18+0.5) -> 103.5953
E19: 8 | F19: =$C$6 -> 0.04557 | G19: =$C$9 -> 2.125 | H19: =G19/(1+F19)^E19 -> 1.4877639 | I19: =H19/$H$24 -> 0.01518818 | J19: =I19*E19 -> 0.12150544 | K19: =H19*(1+F19)^($E$20-E19) -> 1.521285 | L19: =E19*(E19+1)*H19 -> 107.119 | O19: 8 | P19: =P18+$P$2/2 -> 0.06432 | Q19: =$C$9 -> 2.125 | R19: =Q19/(1+P19)^O19 -> 1.2905688 | S19: =R19/$R$24 -> 0.015578185 | T19: =S19*O19 -> 0.12462548 | U19: =R19*(1+P19)^($O$19-O19) -> 1.2905688 | V19: =O19*R19*(O19+0.5) -> 87.758676 | Y19: 8 | Z19: =Z18-$P$2/2 -> 0.02682 | AA19: =$C$9 -> 2.125 | AB19: =AA19/(1+Z19)^Y19 -> 1.7195087 | AC19: =AB19/$AB$24 -> 0.014684297 | AD19: =AC19*Y19 -> 0.11747437 | AE19: =AB19*(1+Z19)^($Y$20-Y19) -> 1.7424148 | AF19: =Y19*AB19*(Y19+0.5) -> 116.92659
E20: 8.5 | F20: =$C$6 -> 0.04557 | G20: =$C$9 -> 2.125 | H20: =G20/(1+F20)^E20 -> 1.4549815 | I20: =H20/$H$24 -> 0.014853513 | J20: =I20*E20 -> 0.12625486 | K20: =H20*(1+F20)^($E$20-E20) -> 1.4549815 | L20: =E20*(E20+1)*H20 -> 117.48976 | O20: 8.5 | P20: =P19+$P$2/2 -> 0.06557 | Q20: =$C$9 -> 2.125 | R20: =Q20/(1+P20)^O20 -> 1.2385458 | S20: =R20/$R$24 -> 0.014950226 | T20: =S20*O20 -> 0.12707692 | V20: =O20*R20*(O20+0.5) -> 94.748752 | Y20: 8.5 | Z20: =Z19-$P$2/2 -> 0.02557 | AA20: =$C$9 -> 2.125 | AB20: =AA20/(1+Z20)^Y20 -> 1.7145644 | AC20: =AB20/$AB$24 -> 0.014642073 | AD20: =AC20*Y20 -> 0.12445762 | AE20: =AB20*(1+Z20)^($Y$20-Y20) -> 1.7145644 | AF20: =Y20*AB20*(Y20+0.5) -> 131.16418
E21: 9 | F21: =$C$6 -> 0.04557 | G21: =$C$9 -> 2.125 | H21: =G21/(1+F21)^E21 -> 1.4229214 | I21: =H21/$H$24 -> 0.01452622 | J21: =I21*E21 -> 0.13073598 | L21: =E21*(E21+1)*H21 -> 128.06293 | O21: 9 | P21: =P20+$P$2/2 -> 0.06682 | Q21: =$C$9 -> 2.125 | R21: =Q21/(1+P21)^O21 -> 1.1872402 | S21: =R21/$R$24 -> 0.014330927 | T21: =S21*O21 -> 0.12897835 | V21: =O21*R21*(O21+0.5) -> 101.50904 | Y21: 9 | Z21: =Z20-$P$2/2 -> 0.02432 | AA21: =$C$9 -> 2.125 | AB21: =AA21/(1+Z21)^Y21 -> 1.711741 | AC21: =AB21/$AB$24 -> 0.014617962 | AD21: =AC21*Y21 -> 0.13156166 | AF21: =Y21*AB21*(Y21+0.5) -> 146.35386
E22: 9.5 | F22: =$C$6 -> 0.04557 | G22: =$C$9 -> 2.125 | H22: =G22/(1+F22)^E22 -> 1.3915677 | I22: =H22/$H$24 -> 0.014206139 | J22: =I22*E22 -> 0.13495832 | L22: =E22*(E22+1)*H22 -> 138.80888 | O22: 9.5 | P22: =P21+$P$2/2 -> 0.06807 | Q22: =$C$9 -> 2.125 | R22: =Q22/(1+P22)^O22 -> 1.1367413 | S22: =R22/$R$24 -> 0.013721365 | T22: =S22*O22 -> 0.13035297 | V22: =O22*R22*(O22+0.5) -> 107.99042 | Y22: 9.5 | Z22: =Z21-$P$2/2 -> 0.02307 | AA22: =$C$9 -> 2.125 | AB22: =AA22/(1+Z22)^Y22 -> 1.7110319 | AC22: =AB22/$AB$24 -> 0.014611906 | AD22: =AC22*Y22 -> 0.13881311 | AF22: =Y22*AB22*(Y22+0.5) -> 162.54803
E23: 10 | F23: =$C$6 -> 0.04557 | G23: =$C$9+$C$5 -> 102.125 | H23: =G23/(1+F23)^E23 -> 65.403491 | I23: =H23/$H$24 -> 0.66768656 | J23: =I23*E23 -> 6.6768656 | L23: =E23*(E23+1)*H23 -> 7194.384 | O23: 10 | P23: =P22+$P$2/2 -> 0.06932 | Q23: =$C$9+C5 -> 102.125 | R23: =Q23/(1+P23)^O23 -> 52.246256 | S23: =R23/$R$24 -> 0.63065359 | T23: =S23*O23 -> 6.3065359 | V23: =O23*R23*(O23+0.5) -> 5485.8569 | Y23: 10 | Z23: =Z22-$P$2/2 -> 0.02182 | AA23: =$C$9+C5 -> 102.125 | AB23: =AA23/(1+Z23)^Y23 -> 82.297773 | AC23: =AB23/$AB$24 -> 0.70280824 | AD23: =AC23*Y23 -> 7.0280824 | AF23: =Y23*AB23*(Y23+0.5) -> 8641.2661
H24: =SUM(H4:H23) -> 97.955381 | J24: =SUM(J4:J23) -> 8.2276994 | K24: =SUM(K4:K20) -> 36.176878 | L24: =SUM(L4:L23) -> 8297.1998 | R24: =SUM(R4:R23) -> 82.844618 | T24: =SUM(T4:T23) -> 7.9713043 | U24: =SUM(U4:U19) -> 33.279568 | V24: =SUM(V4:V23) -> 6398.3294 | AB24: =SUM(AB4:AB23) -> 117.09847 | AD24: =SUM(AD4:AD23) -> 8.4651883 | AE24: =SUM(AE4:AE20) -> 37.08594 | AF24: =SUM(AF4:AF23) -> 9803.385
E26: Macaulay Duration | F26: =J24 -> 8.2276994 | O26: Macaulay Duration | P26: =T24 -> 7.9713043 | Y26: Macaulay Duration | Z26: =AD24 -> 8.4651883
E27: Modified Duration | F27: =F26/(1+$C$6) -> 7.8691044 | O27: Modified Duration | P27: =P26/(1+$C$6) -> 7.6238839 | Y27: Modified Duration | Z27: =Z26/(1+$C$6) -> 8.0962425
E28: Convexity | F28: =L24/(H24*(1+$C$6/2)^2) -> 80.971942 | O28: Convexity | P28: =V24/(R24*(1+$C$6/2)^2) -> 73.830123 | Y28: Convexity | Z28: =AF24/(AB24*(1+$C$6/2)^2) -> 80.030609
E29: GBP01 | F29: =H24*F27*0.0001 -> 0.077082111 | O29: GBP01 | P29: =R24*P27*0.0001 -> 0.063159774 | Y29: GBP01 | Z29: =AB24*Z27*0.0001 -> 0.094805764

Sheet 30 year Gilt (2)
B2: 30-Year Bond | F2: Period | G2: Cash Flow | H2: PV of CF | I2: PV as % of Sum of PV | J2: TW PV of CF | K2: TW^2 PV of CF | N2: Yield | O2: Price | P2: Duration Implied Price | Q2: Convexity Implied Price
B3: Price | C3: =H63 -> 86.576454 | F3: 0.5 | G3: =$C$8 -> 2.1875 | H3: =G3/(1+$C$5)^F3 -> 2.1313335 | I3: =H3/$H$63 -> 0.024617934 | J3: =I3*F3 -> 0.012308967 | K3: =F3*H3*(F3+0.5) -> 1.0656667 | N3: 0.01 | O3: 152.07025 | P3: =$H$63*(1-$C$12*(N3-$C$5)) -> 143.59933 | Q3: =(1+((-$C$12*(N3-$C$5))+(0.5*$C$13*(N3-$C$5)^2)))*$H$63 -> 172.75539
B4: Face Value | C4: 100 | F4: 1 | G4: =$C$8 -> 2.1875 | H4: =G4/(1+$C$5)^F4 -> 2.0766091 | I4: =H4/$H$63 -> 0.023985841 | J4: =I4*F4 -> 0.023985841 | K4: =F4*H4*(F4+0.5) -> 3.1149136 | N4: 0.015 | O4: 126.50693 | P4: =$H$63*(1-$C$12*(N4-$C$5)) -> 137.02987 | Q4: =(1+((-$C$12*(N4-$C$5))+(0.5*$C$13*(N4-$C$5)^2)))*$H$63 -> 159.85493
B5: Yield | C5: 0.0534 | F5: 1.5 | G5: =$C$8 -> 2.1875 | H5: =G5/(1+$C$5)^F5 -> 2.0232898 | I5: =H5/$H$63 -> 0.023369978 | J5: =I5*F5 -> 0.035054966 | K5: =F5*H5*(F5+0.5) -> 6.0698694 | N5: 0.02 | O5: 106.40223 | P5: =$H$63*(1-$C$12*(N5-$C$5)) -> 130.46042 | Q5: =(1+((-$C$12*(N5-$C$5))+(0.5*$C$13*(N5-$C$5)^2)))*$H$63 -> 147.72843
B6: Coupon Rate | C6: 0.04375 | F6: 2 | G6: =$C$8 -> 2.1875 | H6: =G6/(1+$C$5)^F6 -> 1.9713395 | I6: =H6/$H$63 -> 0.022769927 | J6: =I6*F6 -> 0.045539854 | K6: =F6*H6*(F6+0.5) -> 9.8566977 | N6: 0.025 | O6: 90.484873 | P6: =$H$63*(1-$C$12*(N6-$C$5)) -> 123.89096 | Q6: =(1+((-$C$12*(N6-$C$5))+(0.5*$C$13*(N6-$C$5)^2)))*$H$63 -> 136.37589
B7: Coupon | C7: =C4*C6 -> 4.375 | F7: 2.5 | G7: =$C$8 -> 2.1875 | H7: =G7/(1+$C$5)^F7 -> 1.9207232 | I7: =H7/$H$63 -> 0.022185283 | J7: =I7*F7 -> 0.055463209 | K7: =F7*H7*(F7+0.5) -> 14.405424 | N7: 0.03 | O7: 77.793558 | P7: =$H$63*(1-$C$12*(N7-$C$5)) -> 117.32151 | Q7: =(1+((-$C$12*(N7-$C$5))+(0.5*$C$13*(N7-$C$5)^2)))*$H$63 -> 125.79732
B8: Semi-Annually Coupon | C8: =C7/2 -> 2.1875 | F8: 3 | G8: =$C$8 -> 2.1875 | H8: =G8/(1+$C$5)^F8 -> 1.8714064 | I8: =H8/$H$63 -> 0.021615651 | J8: =I8*F8 -> 0.064846954 | K8: =F8*H8*(F8+0.5) -> 19.649768 | N8: 0.035 | O8: 67.59907 | P8: =$H$63*(1-$C$12*(N8-$C$5)) -> 110.75205 | Q8: =(1+((-$C$12*(N8-$C$5))+(0.5*$C$13*(N8-$C$5)^2)))*$H$63 -> 115.9927
F9: 3.5 | G9: =$C$8 -> 2.1875 | H9: =G9/(1+$C$5)^F9 -> 1.823356 | I9: =H9/$H$63 -> 0.021060645 | J9: =I9*F9 -> 0.073712257 | K9: =F9*H9*(F9+0.5) -> 25.526984 | N9: 0.04 | O9: 59.34641 | P9: =$H$63*(1-$C$12*(N9-$C$5)) -> 104.1826 | Q9: =(1+((-$C$12*(N9-$C$5))+(0.5*$C$13*(N9-$C$5)^2)))*$H$63 -> 106.96205
F10: 4 | G10: =$C$8 -> 2.1875 | H10: =G10/(1+$C$5)^F10 -> 1.7765392 | I10: =H10/$H$63 -> 0.020519889 | J10: =I10*F10 -> 0.082079557 | K10: =F10*H10*(F10+0.5) -> 31.977706 | N10: 0.045 | O10: 52.611704 | P10: =$H$63*(1-$C$12*(N10-$C$5)) -> 97.61314 | Q10: =(1+((-$C$12*(N10-$C$5))+(0.5*$C$13*(N10-$C$5)^2)))*$H$63 -> 98.705355
B11: Macaulay Duration | C11: =J63 -> 15.986482 | F11: 4.5 | G11: =$C$8 -> 2.1875 | H11: =G11/(1+$C$5)^F11 -> 1.7309246 | I11: =H11/$H$63 -> 0.019993018 | J11: =I11*F11 -> 0.08996858 | K11: =F11*H11*(F11+0.5) -> 38.945803 | N11: 0.05 | O11: 47.070039 | P11: =$H$63*(1-$C$12*(N11-$C$5)) -> 91.043684 | Q11: =(1+((-$C$12*(N11-$C$5))+(0.5*$C$13*(N11-$C$5)^2)))*$H$63 -> 91.222624
B12: Modified Duration | C12: =C11/(1+C5) -> 15.176079 | F12: 5 | G12: =$C$8 -> 2.1875 | H12: =G12/(1+$C$5)^F12 -> 1.6864812 | I12: =H12/$H$63 -> 0.019479675 | J12: =I12*F12 -> 0.097398373 | K12: =F12*H12*(F12+0.5) -> 46.378232 | N12: 0.055 | O12: 42.471402 | P12: =$H$63*(1-$C$12*(N12-$C$5)) -> 84.474229 | Q12: =(1+((-$C$12*(N12-$C$5))+(0.5*$C$13*(N12-$C$5)^2)))*$H$63 -> 84.513855
B13: Convexity | C13: =K63/(H63*(1+C5/2)^2) -> 357.58529 | F13: 5.5 | G13: =$C$8 -> 2.1875 | H13: =G13/(1+$C$5)^F13 -> 1.6431788 | I13: =H13/$H$63 -> 0.018979512 | J13: =I13*F13 -> 0.10438732 | K13: =F13*H13*(F13+0.5) -> 54.224902 | N13: 0.06 | O13: 38.622638 | P13: =$H$63*(1-$C$12*(N13-$C$5)) -> 77.904773 | Q13: =(1+((-$C$12*(N13-$C$5))+(0.5*$C$13*(N13-$C$5)^2)))*$H$63 -> 78.579048
F14: 6 | G14: =$C$8 -> 2.1875 | H14: =G14/(1+$C$5)^F14 -> 1.6009884 | I14: =H14/$H$63 -> 0.018492191 | J14: =I14*F14 -> 0.11095315 | K14: =F14*H14*(F14+0.5) -> 62.438546 | N14: 0.065 | O14: 35.373886 | P14: =$H$63*(1-$C$12*(N14-$C$5)) -> 71.335317 | Q14: =(1+((-$C$12*(N14-$C$5))+(0.5*$C$13*(N14-$C$5)^2)))*$H$63 -> 73.418203
F15: 6.5 | G15: =$C$8 -> 2.1875 | H15: =G15/(1+$C$5)^F15 -> 1.5598812 | I15: =H15/$H$63 -> 0.018017384 | J15: =I15*F15 -> 0.11711299 | K15: =F15*H15*(F15+0.5) -> 70.974594 | N15: 0.07 | O15: 32.608356 | P15: =$H$63*(1-$C$12*(N15-$C$5)) -> 64.765861 | Q15: =(1+((-$C$12*(N15-$C$5))+(0.5*$C$13*(N15-$C$5)^2)))*$H$63 -> 69.031319
F16: 7 | G16: =$C$8 -> 2.1875 | H16: =G16/(1+$C$5)^F16 -> 1.5198295 | I16: =H16/$H$63 -> 0.017554767 | J16: =I16*F16 -> 0.12288337 | K16: =F16*H16*(F16+0.5) -> 79.791048 | N16: 0.075 | O16: 30.234606 | P16: =$H$63*(1-$C$12*(N16-$C$5)) -> 58.196406 | Q16: =(1+((-$C$12*(N16-$C$5))+(0.5*$C$13*(N16-$C$5)^2)))*$H$63 -> 65.418397
F17: 7.5 | G17: =$C$8 -> 2.1875 | H17: =G17/(1+$C$5)^F17 -> 1.4808061 | I17: =H17/$H$63 -> 0.017104028 | J17: =I17*F17 -> 0.12828021 | K17: =F17*H17*(F17+0.5) -> 88.848368 | N17: 0.08 | O17: 28.180692 | P17: =$H$63*(1-$C$12*(N17-$C$5)) -> 51.62695 | Q17: =(1+((-$C$12*(N17-$C$5))+(0.5*$C$13*(N17-$C$5)^2)))*$H$63 -> 62.579436
F18: 8 | G18: =$C$8 -> 2.1875 | H18: =G18/(1+$C$5)^F18 -> 1.4427848 | I18: =H18/$H$63 -> 0.016664863 | J18: =I18*F18 -> 0.13331891 | K18: =F18*H18*(F18+0.5) -> 98.109364
F19: 8.5 | G19: =$C$8 -> 2.1875 | H19: =G19/(1+$C$5)^F19 -> 1.4057396 | I19: =H19/$H$63 -> 0.016236974 | J19: =I19*F19 -> 0.13801428 | K19: =F19*H19*(F19+0.5) -> 107.53908
F20: 9 | G20: =$C$8 -> 2.1875 | H20: =G20/(1+$C$5)^F20 -> 1.3696457 | I20: =H20/$H$63 -> 0.015820071 | J20: =I20*F20 -> 0.14238064 | K20: =F20*H20*(F20+0.5) -> 117.10471
F21: 9.5 | G21: =$C$8 -> 2.1875 | H21: =G21/(1+$C$5)^F21 -> 1.3344785 | I21: =H21/$H$63 -> 0.015413873 | J21: =I21*F21 -> 0.1464318 | K21: =F21*H21*(F21+0.5) -> 126.77546
F22: 10 | G22: =$C$8 -> 2.1875 | H22: =G22/(1+$C$5)^F22 -> 1.3002142 | I22: =H22/$H$63 -> 0.015018105 | J22: =I22*F22 -> 0.15018105 | K22: =F22*H22*(F22+0.5) -> 136.5225
F23: 10.5 | G23: =$C$8 -> 2.1875 | H23: =G23/(1+$C$5)^F23 -> 1.2668298 | I23: =H23/$H$63 -> 0.014632498 | J23: =I23*F23 -> 0.15364123 | K23: =F23*H23*(F23+0.5) -> 146.31884
F24: 11 | G24: =$C$8 -> 2.1875 | H24: =G24/(1+$C$5)^F24 -> 1.2343025 | I24: =H24/$H$63 -> 0.014256792 | J24: =I24*F24 -> 0.15682471 | K24: =F24*H24*(F24+0.5) -> 156.13927
F25: 11.5 | G25: =$C$8 -> 2.1875 | H25: =G25/(1+$C$5)^F25 -> 1.2026104 | I25: =H25/$H$63 -> 0.013890733 | J25: =I25*F25 -> 0.15974343 | K25: =F25*H25*(F25+0.5) -> 165.96023
F26: 12 | G26: =$C$8 -> 2.1875 | H26: =G26/(1+$C$5)^F26 -> 1.171732 | I26: =H26/$H$63 -> 0.013534072 | J26: =I26*F26 -> 0.16240887 | K26: =F26*H26*(F26+0.5) -> 175.7598
F27: 12.5 | G27: =$C$8 -> 2.1875 | H27: =G27/(1+$C$5)^F27 -> 1.1416465 | I27: =H27/$H$63 -> 0.01318657 | J27: =I27*F27 -> 0.16483212 | K27: =F27*H27*(F27+0.5) -> 185.51755
F28: 13 | G28: =$C$8 -> 2.1875 | H28: =G28/(1+$C$5)^F28 -> 1.1123334 | I28: =H28/$H$63 -> 0.01284799 | J28: =I28*F28 -> 0.16702387 | K28: =F28*H28*(F28+0.5) -> 195.21451
F29: 13.5 | G29: =$C$8 -> 2.1875 | H29: =G29/(1+$C$5)^F29 -> 1.083773 | I29: =H29/$H$63 -> 0.012518103 | J29: =I29*F29 -> 0.16899439 | K29: =F29*H29*(F29+0.5) -> 204.83309
... F61: 29.5 | G61: =$C$8 -> 2.1875 | H61: =G61/(1+$C$5)^F61 -> 0.47146048 | I61: =H61/$H$63 -> 0.005445597 | J61: =I61*F61 -> 0.16064511 | K61: =F61*H61*(F61+0.5) -> 417.24253
F62: 30 | G62: =$C$8+C4 -> 102.1875 | H62: =G62/(1+$C$5)^F62 -> 21.45845 | I62: =H62/$H$63 -> 0.2478555 | J62: =I62*F62 -> 7.435665 | K62: =F62*H62*(F62+0.5) -> 19634.482
H63: =SUM(H3:H62) -> 86.576454 | J63: =SUM(J3:J62) -> 15.986482 | K63: =SUM(K3:K62) -> 32633.719

Sheet 30 Year Scenario
O2: Parallel Up | P2: 0.0025 | Y2: Parallel Down | Z2: 0.0025
B3: 30-Year Bond | E3: Period | F3: Scenario Rate | G3: Cash Flow | H3: PV of CF | I3: PV as % of CF | J3: TW PV of CF | K3: Reivestment as per theory | L3: TW^2 PV of CF | O3: Period | P3: Scenario Rate | Q3: Cash Flow | R3: PV of CF | S3: PV as % of CF | T3: TW PV of CF | U3: Reivestment as per theory | V3: TW^2 PV of CF | Y3: Period | Z3: Scenario Rate | AA3: Cash Flow | AB3: PV of CF | AC3: PV as % of CF | AD3: TW PV of CF | AE3: Reivestment as per theory | AF3: TW^2 PV of CF
B4: Price | C4: ='30 year Gilt (2)'!C3 -> 86.576454 | E4: 0.5 | F4: =$C$6 -> 0.0534 | G4: =$C$9 -> 2.1875 | H4: =G4/(1+F4)^E4 -> 2.1313335 | I4: =H4/H$64 -> 0.024617934 | J4: =I4*E4 -> 0.012308967 | K4: =H4*(1+F4)^(E$35-E4) -> 4.7736192 | L4: =E4*H4*(E4+0.5) -> 1.0656667 | O4: 0.5 | P4: =C6 -> 0.0534 | Q4: =$C$9 -> 2.1875 | R4: =Q4/(1+P4)^O4 -> 2.1313335 | S4: =R4/R$64 -> 0.032260979 | T4: =S4*O4 -> 0.01613049 | U4: =R4*(1+P4)^(O$35-O4) -> 4.7736192 | V4: =O4*R4*(O4+0.5) -> 1.0656667 | Y4: 0.5 | Z4: =$C$6 + INT((ROW()-4)/5)*(-$P$2) -> 0.0534 | AA4: =$C$9 -> 2.1875 | AB4: =AA4/(1+Z4)^Y4 -> 2.1313335 | AC4: =AB4/AB$64 -> 0.016861174 | AD4: =AC4*Y4 -> 0.0084305868 | AE4: =AB4*(1+Z4)^(Y$35-Y4) -> 4.7736192 | AF4: =Y4*AB4*(Y4+0.5) -> 1.0656667
B5: Face Value | C5: ='30 year Gilt (2)'!C4 -> 100 | E5: 1 | F5: =$C$6 -> 0.0534 | G5: =$C$9 -> 2.1875 | H5: =G5/(1+F5)^E5 -> 2.0766091 | I5: =H5/H$64 -> 0.023985841 | J5: =I5*E5 -> 0.023985841 | K5: =H5*(1+F5)^(E$35-E5) -> 4.5316302 | L5: =E5*H5*(E5+0.5) -> 3.1149136 | O5: 1 | P5: =$C$6 + INT((ROW()-4)/5)*$P$2 -> 0.0534 | Q5: =$C$9 -> 2.1875 | R5: =Q5/(1+P5)^O5 -> 2.0766091 | S5: =R5/R$64 -> 0.031432642 | T5: =S5*O5 -> 0.031432642 | U5: =R5*(1+P5)^(O$35-O5) -> 4.5316302 | V5: =O5*R5*(O5+0.5) -> 3.1149136 | Y5: 1 | Z5: =$C$6 + INT((ROW()-4)/5)*(-$P$2) -> 0.0534 | AA5: =$C$9 -> 2.1875 | AB5: =AA5/(1+Z5)^Y5 -> 2.0766091 | AC5: =AB5/AB$64 -> 0.016428244 | AD5: =AC5*Y5 -> 0.016428244 | AE5: =AB5*(1+Z5)^(Y$35-Y5) -> 4.5316302 | AF5: =Y5*AB5*(Y5+0.5) -> 3.1149136
B6: Yield | C6: ='30 year Gilt (2)'!C5 -> 0.0534 | E6: 1.5 | F6: =$C$6 -> 0.0534 | G6: =$C$9 -> 2.1875 | H6: =G6/(1+F6)^E6 -> 2.0232898 | I6: =H6/H$64 -> 0.023369978 | J6: =I6*E6 -> 0.035054966 | K6: =H6*(1+F6)^(E$35-E6) -> 4.3019083 | L6: =E6*H6*(E6+0.5) -> 6.0698694 | O6: 1.5 | P6: =$C$6 + INT((ROW()-4)/5)*$P$2 -> 0.0534 | Q6: =$C$9 -> 2.1875 | R6: =Q6/(1+P6)^O6 -> 2.0232898 | S6: =R6/R$64 -> 0.030625574 | T6: =S6*O6 -> 0.04593836 | U6: =R6*(1+P6)^(O$35-O6) -> 4.3019083 | V6: =O6*R6*(O6+0.5) -> 6.0698694 | Y6: 1.5 | Z6: =$C$6 + INT((ROW()-4)/5)*(-$P$2) -> 0.0534 | AA6: =$C$9 -> 2.1875 | AB6: =AA6/(1+Z6)^Y6 -> 2.0232898 | AC6: =AB6/AB$64 -> 0.01600643 | AD6: =AC6*Y6 -> 0.024009645 | AE6: =AB6*(1+Z6)^(Y$35-Y6) -> 4.3019083 | AF6: =Y6*AB6*(Y6+0.5) -> 6.0698694
B7: Coupon Rate | C7: ='30 year Gilt (2)'!C6 -> 0.04375 | E7: 2 | F7: =$C$6 -> 0.0534 | G7: =$C$9 -> 2.1875 | H7: =G7/(1+F7)^E7 -> 1.9713395 | I7: =H7/H$64 -> 0.022769927 | J7: =I7*E7 -> 0.045539854 | K7: =H7*(1+F7)^(E$35-E7) -> 4.0838316 | L7: =E7*H7*(E7+0.5) -> 9.8566977 | O7: 2 | P7: =$C$6 + INT((ROW()-4)/5)*$P$2 -> 0.0534 | Q7: =$C$9 -> 2.1875 | R7: =Q7/(1+P7)^O7 -> 1.9713395 | S7: =R7/R$64 -> 0.029839227 | T7: =S7*O7 -> 0.059678455 | U7: =R7*(1+P7)^(O$35-O7) -> 4.0838316 | V7: =O7*R7*(O7+0.5) -> 9.8566977 | Y7: 2 | Z7: =$C$6 + INT((ROW()-4)/5)*(-$P$2) -> 0.0534 | AA7: =$C$9 -> 2.1875 | AB7: =AA7/(1+Z7)^Y7 -> 1.9713395 | AC7: =AB7/AB$64 -> 0.015595447 | AD7: =AC7*Y7 -> 0.031190894 | AE7: =AB7*(1+Z7)^(Y$35-Y7) -> 4.0838316 | AF7: =Y7*AB7*(Y7+0.5) -> 9.8566977
B8: Coupon | C8: ='30 year Gilt (2)'!C7 -> 4.375 | E8: 2.5 | F8: =$C$6 -> 0.0534 | G8: =$C$9 -> 2.1875 | H8: =G8/(1+F8)^E8 -> 1.9207232 | I8: =H8/H$64 -> 0.022185283 | J8: =I8*E8 -> 0.055463209 | K8: =H8*(1+F8)^(E$35-E8) -> 3.87681 | L8: =E8*H8*(E8+0.5) -> 14.405424 | O8: 2.5 | P8: =$C$6 + INT((ROW()-4)/5)*$P$2 -> 0.0534 | Q8: =$C$9 -> 2.1875 | R8: =Q8/(1+P8)^O8 -> 1.9207232 | S8: =R8/R$64 -> 0.029073072 | T8: =S8*O8 -> 0.072682679 | U8: =R8*(1+P8)^(O$35-O8) -> 3.87681 | V8: =O8*R8*(O8+0.5) -> 14.405424 | Y8: 2.5 | Z8: =$C$6 + INT((ROW()-4)/5)*(-$P$2) -> 0.0534 | AA8: =$C$9 -> 2.1875 | AB8: =AA8/(1+Z8)^Y8 -> 1.9207232 | AC8: =AB8/AB$64 -> 0.015195016 | AD8: =AC8*Y8 -> 0.037987541 | AE8: =AB8*(1+Z8)^(Y$35-Y8) -> 3.87681 | AF8: =Y8*AB8*(Y8+0.5) -> 14.405424
B9: Semi-Annually Coupon | C9: ='30 year Gilt (2)'!C8 -> 2.1875 | E9: 3 | F9: =$C$6 -> 0.0534 | G9: =$C$9 -> 2.1875 | H9: =G9/(1+F9)^E9 -> 1.8714064 | I9: =H9/H$64 -> 0.021615651 | J9: =I9*E9 -> 0.064846954 | K9: =H9*(1+F9)^(E$35-E9) -> 3.6802829 | L9: =E9*H9*(E9+0.5) -> 19.649768 | O9: 3 | P9: =$C$6 + INT((ROW()-4)/5)*$P$2 -> 0.0559 | Q9: =$C$9 -> 2.1875 | R9: =Q9/(1+P9)^O9 -> 1.8581454 | S9: =R9/R$64 -> 0.028125861 | T9: =S9*O9 -> 0.084377584 | U9: =R9*(1+P9)^(O$35-O9) -> 3.7685646 | V9: =O9*R9*(O9+0.5) -> 19.510527 | Y9: 3 | Z9: =$C$6 + INT((ROW()-4)/5)*(-$P$2) -> 0.0509 | AA9: =$C$9 -> 2.1875 | AB9: =AA9/(1+Z9)^Y9 -> 1.884794 | AC9: =AB9/AB$64 -> 0.014910777 | AD9: =AC9*Y9 -> 0.044732332 | AE9: =AB9*(1+Z9)^(Y$35-Y9) -> 3.5938668 | AF9: =Y9*AB9*(Y9+0.5) -> 19.790337
E10: 3.5 | F10: =$C$6 -> 0.0534 | G10: =$C$9 -> 2.1875 | H10: =G10/(1+F10)^E10 -> 1.823356 | I10: =H10/H$64 -> 0.021060645 | J10: =I10*E10 -> 0.073712257 | K10: =H10*(1+F10)^(E$35-E10) -> 3.4937183 | L10: =E10*H10*(E10+0.5) -> 25.526984 | O10: 3.5 | P10: =$C$6 + INT((ROW()-4)/5)*$P$2 -> 0.0559 | Q10: =$C$9 -> 2.1875 | R10: =Q10/(1+P10)^O10 -> 1.8082909 | S10: =R10/R$64 -> 0.027371238 | T10: =S10*O10 -> 0.095799332 | U10: =R10*(1+P10)^(O$35-O10) -> 3.5690544 | V10: =O10*R10*(O10+0.5) -> 25.316073 | Y10: 3.5 | Z10: =$C$6 + INT((ROW()-4)/5)*(-$P$2) -> 0.0509 | AA10: =$C$9 -> 2.1875 | AB10: =AA10/(1+Z10)^Y10 -> 1.8385828 | AC10: =AB10/AB$64 -> 0.014545196 | AD10: =AC10*Y10 -> 0.050908187 | AE10: =AB10*(1+Z10)^(Y$35-Y10) -> 3.4197991 | AF10: =Y10*AB10*(Y10+0.5) -> 25.740159
E11: 4 | F11: =$C$6 -> 0.0534 | G11: =$C$9 -> 2.1875 | H11: =G11/(1+F11)^E11 -> 1.7765392 | I11: =H11/H$64 -> 0.020519889 | J11: =I11*E11 -> 0.082079557 | K11: =H11*(1+F11)^(E$35-E11) -> 3.3166113 | L11: =E11*H11*(E11+0.5) -> 31.977706 | O11: 4 | P11: =$C$6 + INT((ROW()-4)/5)*$P$2 -> 0.0559 | Q11: =$C$9 -> 2.1875 | R11: =Q11/(1+P11)^O11 -> 1.759774 | S11: =R11/R$64 -> 0.026636861 | T11: =S11*O11 -> 0.10654744 | U11: =R11*(1+P11)^(O$35-O11) -> 3.3801065 | V11: =O11*R11*(O11+0.5) -> 31.675932 | Y11: 4 | Z11: =$C$6 + INT((ROW()-4)/5)*(-$P$2) -> 0.0509 | AA11: =$C$9 -> 2.1875 | AB11: =AA11/(1+Z11)^Y11 -> 1.7935046 | AC11: =AB11/AB$64 -> 0.014188579 | AD11: =AC11*Y11 -> 0.056754314 | AE11: =AB11*(1+Z11)^(Y$35-Y11) -> 3.2541622 | AF11: =Y11*AB11*(Y11+0.5) -> 32.283083
E12: 4.5 | F12: =$C$6 -> 0.0534 | G12: =$C$9 -> 2.1875 | H12: =G12/(1+F12)^E12 -> 1.7309246 | I12: =H12/H$64 -> 0.019993018 | J12: =I12*E12 -> 0.08996858 | K12: =H12*(1+F12)^(E$35-E12) -> 3.1484823 | L12: =E12*H12*(E12+0.5) -> 38.945803 | O12: 4.5 | P12: =$C$6 + INT((ROW()-4)/5)*$P$2 -> 0.0559 | Q12: =$C$9 -> 2.1875 | R12: =Q12/(1+P12)^O12 -> 1.7125589 | S12: =R12/R$64 -> 0.025922187 | T12: =S12*O12 -> 0.11664984 | U12: =R12*(1+P12)^(O$35-O12) -> 3.2011615 | V12: =O12*R12*(O12+0.5) -> 38.532574 | Y12: 4.5 | Z12: =$C$6 + INT((ROW()-4)/5)*(-$P$2) -> 0.0509 | AA12: =$C$9 -> 2.1875 | AB12: =AA12/(1+Z12)^Y12 -> 1.7495316 | AC12: =AB12/AB$64 -> 0.013840704 | AD12: =AC12*Y12 -> 0.06228317 | AE12: =AB12*(1+Z12)^(Y$35-Y12) -> 3.0965479 | AF12: =Y12*AB12*(Y12+0.5) -> 39.364462
E13: 5 | F13: =$C$6 -> 0.0534 | G13: =$C$9 -> 2.1875 | H13: =G13/(1+F13)^E13 -> 1.6864812 | I13: =H13/H$64 -> 0.019479675 | J13: =I13*E13 -> 0.097398373 | K13: =H13*(1+F13)^(E$35-E13) -> 2.9888763 | L13: =E13*H13*(E13+0.5) -> 46.378232 | O13: 5 | P13: =$C$6 + INT((ROW()-4)/5)*$P$2 -> 0.0559 | Q13: =$C$9 -> 2.1875 | R13: =Q13/(1+P13)^O13 -> 1.6666105 | S13: =R13/R$64 -> 0.025226689 | T13: =S13*O13 -> 0.12613344 | U13: =R13*(1+P13)^(O$35-O13) -> 3.0316901 | V13: =O13*R13*(O13+0.5) -> 45.831789 | Y13: 5 | Z13: =$C$6 + INT((ROW()-4)/5)*(-$P$2) -> 0.0509 | AA13: =$C$9 -> 2.1875 | AB13: =AA13/(1+Z13)^Y13 -> 1.7066368 | AC13: =AB13/AB$64 -> 0.013501359 | AD13: =AC13*Y13 -> 0.067506797 | AE13: =AB13*(1+Z13)^(Y$35-Y13) -> 2.9465676 | AF13: =Y13*AB13*(Y13+0.5) -> 46.932512
E14: 5.5 | F14: =$C$6 -> 0.0534 | G14: =$C$9 -> 2.1875 | H14: =G14/(1+F14)^E14 -> 1.6431788 | I14: =H14/H$64 -> 0.018979512 | J14: =I14*E14 -> 0.10438732 | K14: =H14*(1+F14)^(E$35-E14) -> 2.8373612 | L14: =E14*H14*(E14+0.5) -> 54.224902 | O14: 5.5 | P14: =$C$6 + INT((ROW()-4)/5)*$P$2 -> 0.0584 | Q14: =$C$9 -> 2.1875 | R14: =Q14/(1+P14)^O14 -> 1.6009361 | S14: =R14/R$64 -> 0.024232606 | T14: =S14*O14 -> 0.13327934 | U14: =R14*(1+P14)^(O$35-O14) -> 2.9053417 | V14: =O14*R14*(O14+0.5) -> 52.83089 | Y14: 5.5 | Z14: =$C$6 + INT((ROW()-4)/5)*(-$P$2) -> 0.0484 | AA14: =$C$9 -> 2.1875 | AB14: =AA14/(1+Z14)^Y14 -> 1.6867452 | AC14: =AB14/AB$64 -> 0.013343996 | AD14: =AC14*Y14 -> 0.073391976 | AE14: =AB14*(1+Z14)^(Y$35-Y14) -> 2.7706593 | AF14: =Y14*AB14*(Y14+0.5) -> 55.662593
E15: 6 | F15: =$C$6 -> 0.0534 | G15: =$C$9 -> 2.1875 | H15: =G15/(1+F15)^E15 -> 1.6009884 | I15: =H15/H$64 -> 0.018492191 | J15: =I15*E15 -> 0.11095315 | K15: =H15*(1+F15)^(E$35-E15) -> 2.6935269 | L15: =E15*H15*(E15+0.5) -> 62.438546 | O15: 6 | P15: =$C$6 + INT((ROW()-4)/5)*$P$2 -> 0.0584 | Q15: =$C$9 -> 2.1875 | R15: =Q15/(1+P15)^O15 -> 1.5561415 | S15: =R15/R$64 -> 0.023554572 | T15: =S15*O15 -> 0.14132743 | U15: =R15*(1+P15)^(O$35-O15) -> 2.7450318 | V15: =O15*R15*(O15+0.5) -> 60.689517 | Y15: 6 | Z15: =$C$6 + INT((ROW()-4)/5)*(-$P$2) -> 0.0484 | AA15: =$C$9 -> 2.1875 | AB15: =AA15/(1+Z15)^Y15 -> 1.6473504 | AC15: =AB15/AB$64 -> 0.01303234 | AD15: =AC15*Y15 -> 0.078194037 | AE15: =AB15*(1+Z15)^(Y$35-Y15) -> 2.6427502 | AF15: =Y15*AB15*(Y15+0.5) -> 64.246666
E16: 6.5 | F16: =$C$6 -> 0.0534 | G16: =$C$9 -> 2.1875 | H16: =G16/(1+F16)^E16 -> 1.5598812 | I16: =H16/H$64 -> 0.018017384 | J16: =I16*E16 -> 0.11711299 | K16: =H16*(1+F16)^(E$35-E16) -> 2.556984 | L16: =E16*H16*(E16+0.5) -> 70.974594 | O16: 6.5 | P16: =$C$6 + INT((ROW()-4)/5)*$P$2 -> 0.0584 | Q16: =$C$9 -> 2.1875 | R16: =Q16/(1+P16)^O16 -> 1.5126002 | S16: =R16/R$64 -> 0.022895509 | T16: =S16*O16 -> 0.14882081 | U16: =R16*(1+P16)^(O$35-O16) -> 2.5935675 | V16: =O16*R16*(O16+0.5) -> 68.82331 | Y16: 6.5 | Z16: =$C$6 + INT((ROW()-4)/5)*(-$P$2) -> 0.0484 | AA16: =$C$9 -> 2.1875 | AB16: =AA16/(1+Z16)^Y16 -> 1.6088757 | AC16: =AB16/AB$64 -> 0.012727962 | AD16: =AC16*Y16 -> 0.082731755 | AE16: =AB16*(1+Z16)^(Y$35-Y16) -> 2.5207461 | AF16: =Y16*AB16*(Y16+0.5) -> 73.203843
E17: 7 | F17: =$C$6 -> 0.0534 | G17: =$C$9 -> 2.1875 | H17: =G17/(1+F17)^E17 -> 1.5198295 | I17: =H17/H$64 -> 0.017554767 | J17: =I17*E17 -> 0.12288337 | K17: =H17*(1+F17)^(E$35-E17) -> 2.4273628 | L17: =E17*H17*(E17+0.5) -> 79.791048 | O17: 7 | P17: =$C$6 + INT((ROW()-4)/5)*$P$2 -> 0.0584 | Q17: =$C$9 -> 2.1875 | R17: =Q17/(1+P17)^O17 -> 1.4702773 | S17: =R17/R$64 -> 0.022254886 | T17: =S17*O17 -> 0.15578421 | U17: =R17*(1+P17)^(O$35-O17) -> 2.4504606 | V17: =O17*R17*(O17+0.5) -> 77.189557 | Y17: 7 | Z17: =$C$6 + INT((ROW()-4)/5)*(-$P$2) -> 0.0484 | AA17: =$C$9 -> 2.1875 | AB17: =AA17/(1+Z17)^Y17 -> 1.5712995 | AC17: =AB17/AB$64 -> 0.012430694 | AD17: =AC17*Y17 -> 0.087014858 | AE17: =AB17*(1+Z17)^(Y$35-Y17) -> 2.4043743 | AF17: =Y17*AB17*(Y17+0.5) -> 82.493224
E18: 7.5 | F18: =$C$6 -> 0.0534 | G18: =$C$9 -> 2.1875 | H18: =G18/(1+F18)^E18 -> 1.4808061 | I18: =H18/H$64 -> 0.017104028 | J18: =I18*E18 -> 0.12828021 | K18: =H18*(1+F18)^(E$35-E18) -> 2.3043125 | L18: =E18*H18*(E18+0.5) -> 88.848368 | O18: 7.5 | P18: =$C$6 + INT((ROW()-4)/5)*$P$2 -> 0.0584 | Q18: =$C$9 -> 2.1875 | R18: =Q18/(1+P18)^O18 -> 1.4291385 | S18: =R18/R$64 -> 0.021632189 | T18: =S18*O18 -> 0.16224142 | U18: =R18*(1+P18)^(O$35-O18) -> 2.31525 | V18: =O18*R18*(O18+0.5) -> 85.748312 | Y18: 7.5 | Z18: =$C$6 + INT((ROW()-4)/5)*(-$P$2) -> 0.0484 | AA18: =$C$9 -> 2.1875 | AB18: =AA18/(1+Z18)^Y18 -> 1.534601 | AC18: =AB18/AB$64 -> 0.012140368 | AD18: =AC18*Y18 -> 0.091052763 | AE18: =AB18*(1+Z18)^(Y$35-Y18) -> 2.293375 | AF18: =Y18*AB18*(Y18+0.5) -> 92.076058
E19: 8 | F19: =$C$6 -> 0.0534 | G19: =$C$9 -> 2.1875 | H19: =G19/(1+F19)^E19 -> 1.4427848 | I19: =H19/H$64 -> 0.016664863 | J19: =I19*E19 -> 0.13331891 | K19: =H19*(1+F19)^(E$35-E19) -> 2.1875 | L19: =E19*H19*(E19+0.5) -> 98.109364 | O19: 8 | P19: =$C$6 + INT((ROW()-4)/5)*$P$2 -> 0.0609 | Q19: =$C$9 -> 2.1875 | R19: =Q19/(1+P19)^O19 -> 1.3631777 | S19: =R19/R$64 -> 0.020633771 | T19: =S19*O19 -> 0.16507017 | U19: =R19*(1+P19)^(O$35-O19) -> 2.1875 | V19: =O19*R19*(O19+0.5) -> 92.696082 | Y19: 8 | Z19: =$C$6 + INT((ROW()-4)/5)*(-$P$2) -> 0.0459 | AA19: =$C$9 -> 2.1875 | AB19: =AA19/(1+Z19)^Y19 -> 1.5276602 | AC19: =AB19/AB$64 -> 0.012085459 | AD19: =AC19*Y19 -> 0.096683673 | AE19: =AB19*(1+Z19)^(Y$35-Y19) -> 2.1875 | AF19: =Y19*AB19*(Y19+0.5) -> 103.88089
E20: 8.5 | F20: =$C$6 -> 0.0534 | G20: =$C$9 -> 2.1875 | H20: =G20/(1+F20)^E20 -> 1.4057396 | I20: =H20/H$64 -> 0.016236974 | J20: =I20*E20 -> 0.13801428 | K20: =H20*(1+F20)^(E$35-E20) -> 2.0766091 | L20: =E20*H20*(E20+0.5) -> 107.53908 | O20: 8.5 | P20: =$C$6 + INT((ROW()-4)/5)*$P$2 -> 0.0609 | Q20: =$C$9 -> 2.1875 | R20: =Q20/(1+P20)^O20 -> 1.3234735 | S20: =R20/R$64 -> 0.020032787 | T20: =S20*O20 -> 0.17027869 | U20: =R20*(1+P20)^(O$35-O20) -> 2.0619286 | V20: =O20*R20*(O20+0.5) -> 101.24572 | Y20: 8.5 | Z20: =$C$6 + INT((ROW()-4)/5)*(-$P$2) -> 0.0459 | AA20: =$C$9 -> 2.1875 | AB20: =AA20/(1+Z20)^Y20 -> 1.4937629 | AC20: =AB20/AB$64 -> 0.011817295 | AD20: =AC20*Y20 -> 0.10044701 | AE20: =AB20*(1+Z20)^(Y$35-Y20) -> 2.0915001 | AF20: =Y20*AB20*(Y20+0.5) -> 114.27286
E21: 9 | F21: =$C$6 -> 0.0534 | G21: =$C$9 -> 2.1875 | H21: =G21/(1+F21)^E21 -> 1.3696457 | I21: =H21/H$64 -> 0.015820071 | J21: =I21*E21 -> 0.14238064 | K21: =H21*(1+F21)^(E$35-E21) -> 1.9713395 | L21: =E21*H21*(E21+0.5) -> 117.10471 | O21: 9 | P21: =$C$6 + INT((ROW()-4)/5)*$P$2 -> 0.0609 | Q21: =$C$9 -> 2.1875 | R21: =Q21/(1+P21)^O21 -> 1.2849257 | S21: =R21/R$64 -> 0.019449308 | T21: =S21*O21 -> 0.17504377 | U21: =R21*(1+P21)^(O$35-O21) -> 1.9435654 | V21: =O21*R21*(O21+0.5) -> 109.86115 | Y21: 9 | Z21: =$C$6 + INT((ROW()-4)/5)*(-$P$2) -> 0.0459 | AA21: =$C$9 -> 2.1875 | AB21: =AA21/(1+Z21)^Y21 -> 1.4606178 | AC21: =AB21/AB$64 -> 0.011555081 | AD21: =AC21*Y21 -> 0.10399573 | AE21: =AB21*(1+Z21)^(Y$35-Y21) -> 1.9997133 | AF21: =Y21*AB21*(Y21+0.5) -> 124.88282
... E29: 13 | F29: =$C$6 -> 0.0534 | G29: =$C$9 -> 2.1875 | H29: =G29/(1+F29)^E29 -> 1.1123334 | I29: =H29/H$64 -> 0.01284799 | J29: =I29*E29 -> 0.16702387 | K29: =H29*(1+F29)^(E$35-E29) -> 1.3002142 | L29: =E29*H29*(E29+0.5) -> 195.21451 | O29: 13 | P29: =$C$6 + INT((ROW()-4)/5)*$P$2 -> 0.0659 | Q29: =$C$9 -> 2.1875 | R29: =Q29/(1+P29)^O29 -> 0.95418823 | S29: =R29/R$64 -> 0.014443093 | T29: =S29*O29 -> 0.1877602 | U29: =R29*(1+P29)^(O$35-O29) -> 1.1555359 | V29: =O29*R29*(O29+0.5) -> 167.46003 | Y29: 13 | Z29: =$C$6 + INT((ROW()-4)/5)*(-$P$2) -> 0.0409 | AA29: =$C$9 -> 2.1875 | AB29: =AA29/(1+Z29)^Y29 -> 1.2990652 | AC29: =AB29/AB$64 -> 0.010277023 | AD29: =AC29*Y29 -> 0.13360131 | AE29: =AB29*(1+Z29)^(Y$35-Y29) -> 1.4650687 | AF29: =Y29*AB29*(Y29+0.5) -> 227.98594
E30: 13.5 | F30: =$C$6 -> 0.0534 | G30: =$C$9 -> 2.1875 | H30: =G30/(1+F30)^E30 -> 1.083773 | I30: =H30/H$64 -> 0.012518103 | J30: =I30*E30 -> 0.16899439 | K30: =H30*(1+F30)^(E$35-E30) -> 1.2343025 | L30: =E30*H30*(E30+0.5) -> 204.83309 | O30: 13.5 | P30: =$C$6 + INT((ROW()-4)/5)*$P$2 -> 0.0659 | Q30: =$C$9 -> 2.1875 | R30: =Q30/(1+P30)^O30 -> 0.92422098 | S30: =R30/R$64 -> 0.013989493 | T30: =S30*O30 -> 0.18885815 | V30: =O30*R30*(O30+0.5) -> 174.67776 | Y30: 13.5 | Z30: =$C$6 + INT((ROW()-4)/5)*(-$P$2) -> 0.0409 | AA30: =$C$9 -> 2.1875 | AB30: =AA30/(1+Z30)^Y30 -> 1.2732874 | AC30: =AB30/AB$64 -> 0.010073093 | AD30: =AC30*Y30 -> 0.13598676 | AE30: =AB30*(1+Z30)^(Y$35-Y30) -> 1.4075018 | AF30: =Y30*AB30*(Y30+0.5) -> 240.65132
E31: 14 | F31: =$C$6 -> 0.0534 | G31: =$C$9 -> 2.1875 | H31: =G31/(1+F31)^E31 -> 1.0559459 | I31: =H31/H$64 -> 0.012196687 | J31: =I31*E31 -> 0.17075361 | K31: =H31*(1+F31)^(E$35-E31) -> 1.171732 | L31: =E31*H31*(E31+0.5) -> 214.35702 | O31: 14 | P31: =$C$6 + INT((ROW()-4)/5)*$P$2 -> 0.0659 | Q31: =$C$9 -> 2.1875 | R31: =Q31/(1+P31)^O31 -> 0.89519488 | S31: =R31/R$64 -> 0.013550138 | T31: =S31*O31 -> 0.18970194 | V31: =O31*R31*(O31+0.5) -> 181.72456 | Y31: 14 | Z31: =$C$6 + INT((ROW()-4)/5)*(-$P$2) -> 0.0409 | AA31: =$C$9 -> 2.1875 | AB31: =AA31/(1+Z31)^Y31 -> 1.2480211 | AC31: =AB31/AB$64 -> 0.0098732092 | AD31: =AC31*Y31 -> 0.13822493 | AE31: =AB31*(1+Z31)^(Y$35-Y31) -> 1.352197 | AF31: =Y31*AB31*(Y31+0.5) -> 253.34829
E32: 14.5 | F32: =$C$6 -> 0.0534 | G32: =$C$9 -> 2.1875 | H32: =G32/(1+F32)^E32 -> 1.0288333 | I32: =H32/H$64 -> 0.011883523 | J32: =I32*E32 -> 0.17231108 | K32: =H32*(1+F32)^(E$35-E32) -> 1.1123334 | L32: =E32*H32*(E32+0.5) -> 223.77124 | O32: 14.5 | P32: =$C$6 + INT((ROW()-4)/5)*$P$2 -> 0.0659 | Q32: =$C$9 -> 2.1875 | R32: =Q32/(1+P32)^O32 -> 0.86708038 | S32: =R32/R$64 -> 0.013124583 | T32: =S32*O32 -> 0.19030645 | V32: =O32*R32*(O32+0.5) -> 188.58998 | Y32: 14.5 | Z32: =$C$6 + INT((ROW()-4)/5)*(-$P$2) -> 0.0409 | AA32: =$C$9 -> 2.1875 | AB32: =AA32/(1+Z32)^Y32 -> 1.2232562 | AC32: =AB32/AB$64 -> 0.0096772918 | AD32: =AC32*Y32 -> 0.14032073 | AE32: =AB32*(1+Z32)^(Y$35-Y32) -> 1.2990652 | AF32: =Y32*AB32*(Y32+0.5) -> 266.05823
E33: 15 | F33: =$C$6 -> 0.0534 | G33: =$C$9 -> 2.1875 | H33: =G33/(1+F33)^E33 -> 1.0024168 | I33: =H33/H$64 -> 0.0115784 | J33: =I33*E33 -> 0.173676 | K33: =H33*(1+F33)^(E$35-E33) -> 1.0559459 | L33: =E33*H33*(E33+0.5) -> 233.06191 | O33: 15 | P33: =$C$6 + INT((ROW()-4)/5)*$P$2 -> 0.0659 | Q33: =$C$9 -> 2.1875 | R33: =Q33/(1+P33)^O33 -> 0.83984884 | S33: =R33/R$64 -> 0.012712392 | T33: =S33*O33 -> 0.19068588 | V33: =O33*R33*(O33+0.5) -> 195.26486 | Y33: 15 | Z33: =$C$6 + INT((ROW()-4)/5)*(-$P$2) -> 0.0409 | AA33: =$C$9 -> 2.1875 | AB33: =AA33/(1+Z33)^Y33 -> 1.1989827 | AC33: =AB33/AB$64 -> 0.009485262 | AD33: =AC33*Y33 -> 0.14227893 | AE33: =AB33*(1+Z33)^(Y$35-Y33) -> 1.2480211 | AF33: =Y33*AB33*(Y33+0.5) -> 278.76349
E34: 15.5 | F34: =$C$6 -> 0.0534 | G34: =$C$9 -> 2.1875 | H34: =G34/(1+F34)^E34 -> 0.97667865 | I34: =H34/H$64 -> 0.011281112 | J34: =I34*E34 -> 0.17485723 | K34: =H34*(1+F34)^(E$35-E34) -> 1.0024168 | L34: =E34*H34*(E34+0.5) -> 242.21631 | O34: 15.5 | P34: =$C$6 + INT((ROW()-4)/5)*$P$2 -> 0.0684 | Q34: =$C$9 -> 2.1875 | R34: =Q34/(1+P34)^O34 -> 0.78446384 | S34: =R34/R$64 -> 0.011874055 | T34: =S34*O34 -> 0.18404786 | V34: =O34*R34*(O34+0.5) -> 194.54703 | Y34: 15.5 | Z34: =$C$6 + INT((ROW()-4)/5)*(-$P$2) -> 0.0384 | AA34: =$C$9 -> 2.1875 | AB34: =AA34/(1+Z34)^Y34 -> 1.2198194 | AC34: =AB34/AB$64 -> 0.0096501025 | AD34: =AC34*Y34 -> 0.14957659 | AE34: =AB34*(1+Z34)^(Y$35-Y34) -> 1.2430193 | AF34: =Y34*AB34*(Y34+0.5) -> 302.51521
E35: 16 | F35: =$C$6 -> 0.0534 | G35: =$C$9 -> 2.1875 | H35: =G35/(1+F35)^E35 -> 0.95160132 | I35: =H35/H$64 -> 0.010991456 | J35: =I35*E35 -> 0.1758633 | K35: =H35*(1+F35)^(E$35-E35) -> 0.95160132 | L35: =E35*H35*(E35+0.5) -> 251.22275 | O35: 16 | P35: =$C$6 + INT((ROW()-4)/5)*$P$2 -> 0.0684 | Q35: =$C$9 -> 2.1875 | R35: =Q35/(1+P35)^O35 -> 0.75893746 | S35: =R35/R$64 -> 0.011487675 | T35: =S35*O35 -> 0.1838028 | V35: =O35*R35*(O35+0.5) -> 200.35949 | Y35: 16 | Z35: =$C$6 + INT((ROW()-4)/5)*(-$P$2) -> 0.0384 | AA35: =$C$9 -> 2.1875 | AB35: =AA35/(1+Z35)^Y35 -> 1.1970525 | AC35: =AB35/AB$64 -> 0.0094699915 | AD35: =AC35*Y35 -> 0.15151986 | AE35: =AB35*(1+Z35)^(Y$35-Y35) -> 1.1970525 | AF35: =Y35*AB35*(Y35+0.5) -> 316.02185
