Workbook

Sheet GBP01 & Convexity
B2: 10-Year Bond | F2: 30-Year Bond | J2: 10 Year Gilt
B3: Price | C3: ='10 year Gilt'!C3 -> 99.770471 | F3: Price | G3: 86.767 | J3: Change in BPs | K3: Change in BPs in Percentage | L3: New Yield | M3: Price (Full reval) | N3: PnL Full | O3: PnL DV01 | P3: PnL DV01+Conv | Q3: Error (GBP01) | R3: Error (GBP01+Conv) | T3: Change in BPs | U3: PnL Full | V3: PnL DV01 | W3: PnL DV01+Conv | Y3: Change in BPs | Z3: Error (GBP01) | AA3: Error (GBP01+Conv)
B4: Face Value | C4: 100 | F4: Face Value | G4: 100 | J4: -200 | K4: =J4/10000 -> -0.02 | L4: =K4+$C$5 -> 0.0253 | M4: 116.54341 | N4: =M4-$M$8 -> 16.772941 | O4: =-$C$34*K4*10000 -> 31.146278 | P4: =(-$M$8*$C$24*K4)+(0.5*$M$8*$C$29*(K4^2)) -> 37.50611 | Q4: =-($N4-O4) -> 14.373337 | R4: =($N4-P4) -> -20.733169 | T4: -200 | U4: 16.772941 | V4: 31.146278 | W4: 37.50611 | Y4: -200 | Z4: 14.373337 | AA4: -20.733169
B5: Yield | C5: 0.0453 | F5: Yield | G5: 0.05276 | J5: -150 | K5: =J5/10000 -> -0.015 | L5: =K5+$C$5 -> 0.0303 | M5: 112.0562 | N5: =M5-$M$8 -> 12.285734 | O5: =-$C$34*K5*10000 -> 23.359708 | P5: =(-$M$8*$C$24*K5)+(0.5*$M$8*$C$29*(K5^2)) -> 26.937675 | Q5: =-($N5-O5) -> 11.073975 | R5: =($N5-P5) -> -14.651942 | T5: -150 | U5: 12.285734 | V5: 23.359708 | W5: 26.937675 | Y5: -150 | Z5: 11.073975 | AA5: -14.651942
B6: Semi-Annually Yield | C6: =C5/2 -> 0.02265 | F6: Semi-Annually Yield | G6: =G5/2 -> 0.02638 | J6: -100 | K6: =J6/10000 -> -0.01 | L6: =K6+$C$5 -> 0.0353 | M6: 107.77147 | N6: =M6-$M$8 -> 8.0010007 | O6: =-$C$34*K6*10000 -> 15.573139 | P6: =(-$M$8*$C$24*K6)+(0.5*$M$8*$C$29*(K6^2)) -> 17.163845 | Q6: =-($N6-O6) -> 7.5721381 | R6: =($N6-P6) -> -9.1628443 | T6: -100 | U6: 8.0010007 | V6: 15.573139 | W6: 17.163845 | Y6: -100 | Z6: 7.5721381 | AA6: -9.1628443
B7: Coupon Rate | C7: 0.045 | F7: Coupon Rate | G7: 0.04375 | J7: -50 | K7: =J7/10000 -> -0.005 | L7: =K7+$C$5 -> 0.0403 | M7: 103.67935 | N7: =M7-$M$8 -> 3.9088755 | O7: =-$C$34*K7*10000 -> 7.7865694 | P7: =(-$M$8*$C$24*K7)+(0.5*$M$8*$C$29*(K7^2)) -> 8.18462 | Q7: =-($N7-O7) -> 3.8776939 | R7: =($N7-P7) -> -4.2757445 | T7: -50 | U7: 3.9088755 | V7: 7.7865694 | W7: 8.18462 | Y7: -50 | Z7: 3.8776939 | AA7: -4.2757445
B8: Coupon | C8: =C4*C7 -> 4.5 | F8: Coupon | G8: =G4*G7 -> 4.375 | J8: 0 | K8: =J8/10000 -> 0 | L8: =K8+$C$5 -> 0.0453 | M8: 99.770471 | N8: =M8-$M$8 -> 0 | O8: =-$C$34*K8*10000 -> 0 | P8: =(-$M$8*$C$24*K8)+(0.5*$M$8*$C$29*(K8^2)) -> 0 | Q8: =-($N8-O8) -> 0 | R8: =($N8-P8) -> 0 | T8: 0 | U8: 0 | V8: 0 | W8: 0 | Y8: 0 | Z8: 0 | AA8: 0
B9: Semi-Annually Coupon | C9: =C8/2 -> 2.25 | F9: Semi-Annually Coupon | G9: =G8/2 -> 2.1875 | J9: 50 | K9: =J9/10000 -> 0.005 | L9: =K9+$C$5 -> 0.0503 | M9: 96.035969 | N9: =M9-$M$8 -> -3.7345023 | O9: =-$C$34*K9*10000 -> -7.7865694 | P9: =(-$M$8*$C$24*K9)+(0.5*$M$8*$C$29*(K9^2)) -> -7.3900149 | Q9: =-($N9-O9) -> -4.0520671 | R9: =($N9-P9) -> 3.6555126 | T9: 50 | U9: -3.7345023 | V9: -7.7865694 | W9: -7.3900149 | Y9: 50 | Z9: -4.0520671 | AA9: 3.6555126
B10: Issue Date | C10: 45723 | F10: Issue Date | G10: 45869 | J10: 100 | K10: =J10/10000 -> 0.01 | L10: =K10+$C$5 -> 0.0553 | M10: 92.467418 | N10: =M10-$M$8 -> -7.3030527 | O10: =-$C$34*K10*10000 -> -15.573139 | P10: =(-$M$8*$C$24*K10)+(0.5*$M$8*$C$29*(K10^2)) -> -13.985425 | Q10: =-($N10-O10) -> -8.2700862 | R10: =($N10-P10) -> 6.6823722 | T10: 100 | U10: -7.3030527 | V10: -15.573139 | W10: -13.985425 | Y10: 100 | Z10: -8.2700862 | AA10: 6.6823722
B11: Last Coupon Payment Date | C11: =EDATE(C10,6) -> 45907 | F11: Last Coupon Payment Date | G11: =G10 -> 45869 | J11: 150 | K11: =J11/10000 -> 0.015 | L11: =K11+$C$5 -> 0.0603 | M11: 89.05683 | N11: =M11-$M$8 -> -10.713641 | O11: =-$C$34*K11*10000 -> -23.359708 | P11: =(-$M$8*$C$24*K11)+(0.5*$M$8*$C$29*(K11^2)) -> -19.78623 | Q11: =-($N11-O11) -> -12.646067 | R11: =($N11-P11) -> 9.0725884 | T11: 150 | U11: -10.713641 | V11: -23.359708 | W11: -19.78623 | Y11: 150 | Z11: -12.646067 | AA11: 9.0725884
B12: Next Coupon Payment Date | C12: =EDATE(C11,6) -> 46088 | F12: Next Coupon Payment Date | G12: =EDATE(G11,6) -> 46053 | J12: 200 | K12: =J12/10000 -> 0.02 | L12: =K12+$C$5 -> 0.0653 | M12: 85.79662 | N12: =M12-$M$8 -> -13.973851 | O12: =-$C$34*K12*10000 -> -31.146278 | P12: =(-$M$8*$C$24*K12)+(0.5*$M$8*$C$29*(K12^2)) -> -24.792429 | Q12: =-($N12-O12) -> -17.172427 | R12: =($N12-P12) -> 10.818579 | T12: 200 | U12: -13.973851 | V12: -31.146278 | W12: -24.792429 | Y12: 200 | Z12: -17.172427 | AA12: 10.818579
B13: Settlement Date | C13: 46005 | F13: Settlement Date | G13: 46005
B14: Maturity Date | C14: 49375 | F14: Maturity Date | G14: 56461
J15: 10 Year Gilt
J16: Change in BPs | K16: Change in BPs in Percentage | L16: New Yield | M16: Price (Full reval) | N16: PnL Full | O16: PnL DV01 | P16: PnL DV01+Conv | Q16: Error (GBP01) | R16: Error (GBP01+Conv) | T16: Change in BPs | U16: PnL Full | V16: PnL DV01 | W16: PnL DV01+Conv | Y16: Change in BPs | Z16: Error (GBP01) | AA16: Error (GBP01+Conv)
B17: Macaulay Duration | J17: -200 | K17: =J17/10000 -> -0.02 | L17: =K17+$G$5 -> 0.03276 | M17: 120.47328 | N17: =M17-$M$21 -> 33.778841 | O17: =-$C$35*K17*10000 -> 52.523234 | P17: =(-$M$21*$C$25*K17)+(0.5*$M$21*$C$30*(K17^2)) -> 78.767934 | Q17: =-($N17-O17) -> 18.744393 | R17: =($N17-P17) -> -44.989093 | T17: -200 | U17: 33.778841 | V17: 52.523234 | W17: 78.767934 | Y17: -200 | Z17: 18.744393 | AA17: -44.989093
B18: Bond | C18: Base | D18: Parallel Up | E18: Parallel Down | J18: -150 | K18: =J18/10000 -> -0.015 | L18: =K18+$G$5 -> 0.03776 | M18: 110.50219 | N18: =M18-$M$21 -> 23.807747 | O18: =-$C$35*K18*10000 -> 39.392426 | P18: =(-$M$21*$C$25*K18)+(0.5*$M$21*$C$30*(K18^2)) -> 54.176859 | Q18: =-($N18-O18) -> 15.584678 | R18: =($N18-P18) -> -30.369111 | T18: -150 | U18: 23.807747 | V18: 39.392426 | W18: 54.176859 | Y18: -150 | Z18: 15.584678 | AA18: -30.369111
B19: 10 Year Gilt | C19: ='10 Year Scenario'!F26 -> 16.31762 | D19: ='10 Year Scenario'!Q26 -> 15.19895 | E19: ='10 Year Scenario'!AB26 -> 17.259326 | J19: -100 | K19: =J19/10000 -> -0.01 | L19: =K19+$G$5 -> 0.04276 | M19: 101.63646 | N19: =M19-$M$21 -> 14.942023 | O19: =-$C$35*K19*10000 -> 26.261617 | P19: =(-$M$21*$C$25*K19)+(0.5*$M$21*$C$30*(K19^2)) -> 32.851845 | Q19: =-($N19-O19) -> 11.319594 | R19: =($N19-P19) -> -17.909822 | T19: -100 | U19: 14.942023 | V19: 26.261617 | W19: 32.851845 | Y19: -100 | Z19: 11.319594 | AA19: -17.909822
B20: 30 Year Gilt | C20: ='30 Year Scenario'!F66 -> 31.960931 | D20: ='30 Year Scenario'!Q66 -> 21.130289 | E20: ='30 Year Scenario'!AB66 -> 45.807244 | J20: -50 | K20: =J20/10000 -> -0.005 | L20: =K20+$G$5 -> 0.04776 | M20: 93.740017 | N20: =M20-$M$21 -> 7.0455751 | O20: =-$C$35*K20*10000 -> 13.130809 | P20: =(-$M$21*$C$25*K20)+(0.5*$M$21*$C$30*(K20^2)) -> 14.792892 | Q20: =-($N20-O20) -> 6.0852334 | R20: =($N20-P20) -> -7.7473166 | T20: -50 | U20: 7.0455751 | V20: 13.130809 | W20: 14.792892 | Y20: -50 | Z20: 6.0852334 | AA20: -7.7473166
J21: 0 | K21: =J21/10000 -> 0 | L21: =K21+$G$5 -> 0.05276 | M21: 86.694441 | N21: =M21-$M$21 -> 0 | O21: =-$C$35*K21*10000 -> 0 | P21: =(-$M$21*$C$25*K21)+(0.5*$M$21*$C$30*(K21^2)) -> 0 | Q21: =-($N21-O21) -> 0 | R21: =($N21-P21) -> 0 | T21: 0 | U21: 0 | V21: 0 | W21: 0 | Y21: 0 | Z21: 0 | AA21: 0
B22: Modified Duration | J22: 50 | K22: =J22/10000 -> 0.005 | L22: =K22+$G$5 -> 0.05776 | M22: 80.396644 | N22: =M22-$M$21 -> -6.2977975 | O22: =-$C$35*K22*10000 -> -13.130809 | P22: =(-$M$21*$C$25*K22)+(0.5*$M$21*$C$30*(K22^2)) -> -11.526831 | Q22: =-($N22-O22) -> -6.833011 | R22: =($N22-P22) -> 5.229033 | T22: 50 | U22: -6.2977975 | V22: -13.130809 | W22: -11.526831 | Y22: 50 | Z22: -6.833011 | AA22: 5.229033
B23: Bond | C23: Base | D23: Parallel Up | E23: Parallel Down | J23: 100 | K23: =J23/10000 -> 0.01 | L23: =K23+$G$5 -> 0.06276 | M23: 74.756785 | N23: =M23-$M$21 -> -11.937656 | O23: =-$C$35*K23*10000 -> -26.261617 | P23: =(-$M$21*$C$25*K23)+(0.5*$M$21*$C$30*(K23^2)) -> -19.7876 | Q23: =-($N23-O23) -> -14.323961 | R23: =($N23-P23) -> 7.8499436 | T23: 100 | U23: -11.937656 | V23: -26.261617 | W23: -19.7876 | Y23: 100 | Z23: -14.323961 | AA23: 7.8499436
B24: 10 Year Gilt | C24: ='10 Year Scenario'!F27 -> 15.610465 | D24: ='10 Year Scenario'!Q27 -> 14.540275 | E24: ='10 Year Scenario'!AB26 -> 17.259326 | J24: 150 | K24: =J24/10000 -> 0.015 | L24: =K24+$G$5 -> 0.06776 | M24: 69.696513 | N24: =M24-$M$21 -> -16.997929 | O24: =-$C$35*K24*10000 -> -39.392426 | P24: =(-$M$21*$C$25*K24)+(0.5*$M$21*$C$30*(K24^2)) -> -24.782308 | Q24: =-($N24-O24) -> -22.394497 | R24: =($N24-P24) -> 7.7843795 | T24: 150 | U24: -16.997929 | V24: -39.392426 | W24: -24.782308 | Y24: 150 | Z24: -22.394497 | AA24: 7.7843795
B25: 30 Year Gilt | C25: ='30 Year Scenario'!F67 -> 30.359181 | D25: ='30 Year Scenario'!Q67 -> 20.071326 | E25: ='30 Year Scenario'!AB67 -> 43.511574 | J25: 200 | K25: =J25/10000 -> 0.02 | L25: =K25+$G$5 -> 0.07276 | M25: 65.147435 | N25: =M25-$M$21 -> -21.547007 | O25: =-$C$35*K25*10000 -> -52.523234 | P25: =(-$M$21*$C$25*K25)+(0.5*$M$21*$C$30*(K25^2)) -> -26.510955 | Q25: =-($N25-O25) -> -30.976227 | R25: =($N25-P25) -> 4.9639485 | T25: 200 | U25: -21.547007 | V25: -52.523234 | W25: -26.510955 | Y25: 200 | Z25: -30.976227 | AA25: 4.9639485
B27: Convexity
B28: Bond | C28: Base | D28: Parallel Up | E28: Parallel Down
B29: 10 Year Gilt | C29: ='10 Year Scenario'!F28 -> 318.57324 | D29: ='10 Year Scenario'!Q28 -> 289.39741 | E29: ='10 Year Scenario'!AB28 -> 343.4445
B30: 30 Year Gilt | C30: ='30 Year Scenario'!F68 -> 1506.9299 | D30: ='30 Year Scenario'!Q68 -> 767.64579 | E30: ='30 Year Scenario'!AB68 -> 2515.8499
B32: GBP01
B33: Bond | C33: Base | D33: Parallel Up | E33: Parallel Down
B34: 10 Year Gilt | C34: ='10 Year Scenario'!F29 -> 0.15573139 | D34: ='10 Year Scenario'!Q29 -> 0.10430267 | E34: ='10 Year Scenario'!AB29 -> 0.23804087
B35: 30 Year Gilt | C35: ='30 Year Scenario'!F69 -> 0.26261617 | D35: ='30 Year Scenario'!Q69 -> 0.10843705 | E35: ='30 Year Scenario'!AB69 -> 0.92165471

Sheet 10 year Gilt
B2: 10-Year Bond | F2: Coupon Payment Date | G2: Period | H2: Cash Flow | I2: PV of CF | J2: PV as % of Sum of PV | K2: TW PV of CF | L2: TW^2 PV of CF | O2: Yield | P2: Price | Q2: Duration Implied Price | R2: Convexity Implied Price
B3: Price | C3: =I24 -> 99.770471 | F3: =C10 -> 45723 | O3: 0.01 | P3: 131.64412 | Q3: =$I$24*(1-$C$18*(O3-$C$5)) -> 152.54354 | R3: =$I$24*(1-$C$18*(O3-$C$5)+0.5*$C$19*((O3-$C$5)^2)) -> 170.71872
B4: Face Value | C4: 100 | F4: =EDATE(F3,6) -> 45907 | O4: 0.015 | P4: 126.47024 | Q4: =$I$24*(1-$C$18*(O4-$C$5)) -> 145.0686 | R4: =$I$24*(1-$C$18*(O4-$C$5)+0.5*$C$19*((O4-$C$5)^2)) -> 158.45965
B5: Yield | C5: 0.0453 | F5: =EDATE(F4,6) -> 46088 | G5: 1 | H5: =$C$9 -> 2.25 | I5: =H5/(1+$C$6)^G5 -> 2.2001662 | J5: =I5/$I$24 -> 0.022052279 | K5: =J5*G5 -> 0.022052279 | L5: =G5*(G5+1)*I5 -> 4.4003325 | O5: 0.02 | P5: 121.53251 | Q5: =$I$24*(1-$C$18*(O5-$C$5)) -> 137.59366 | R5: =$I$24*(1-$C$18*(O5-$C$5)+0.5*$C$19*((O5-$C$5)^2)) -> 146.92986
B6: Semi-Annually Yield | C6: =C5/2 -> 0.02265 | F6: =EDATE(F5,6) -> 46272 | G6: 2 | H6: =$C$9 -> 2.25 | I6: =H6/(1+$C$6)^G6 -> 2.1514362 | J6: =I6/$I$24 -> 0.021563857 | K6: =J6*G6 -> 0.043127715 | L6: =G6*(G6+1)*I6 -> 12.908617 | O6: 0.025 | P6: 116.81931 | Q6: =$I$24*(1-$C$18*(O6-$C$5)) -> 130.11872 | R6: =$I$24*(1-$C$18*(O6-$C$5)+0.5*$C$19*((O6-$C$5)^2)) -> 136.12937
B7: Coupon Rate | C7: 0.045 | F7: =EDATE(F6,6) -> 46453 | G7: 3 | H7: =$C$9 -> 2.25 | I7: =H7/(1+$C$6)^G7 -> 2.1037855 | J7: =I7/$I$24 -> 0.021086254 | K7: =J7*G7 -> 0.063258761 | L7: =G7*(G7+1)*I7 -> 25.245426 | O7: 0.03 | P7: 112.31963 | Q7: =$I$24*(1-$C$18*(O7-$C$5)) -> 122.64378 | R7: =$I$24*(1-$C$18*(O7-$C$5)+0.5*$C$19*((O7-$C$5)^2)) -> 126.05817
B8: Coupon | C8: =C4*C7 -> 4.5 | F8: =EDATE(F7,6) -> 46637 | G8: 4 | H8: =$C$9 -> 2.25 | I8: =H8/(1+$C$6)^G8 -> 2.0571901 | J8: =I8/$I$24 -> 0.020619228 | K8: =J8*G8 -> 0.082476913 | L8: =G8*(G8+1)*I8 -> 41.143802 | O8: 0.035 | P8: 108.02303 | Q8: =$I$24*(1-$C$18*(O8-$C$5)) -> 115.16885 | R8: =$I$24*(1-$C$18*(O8-$C$5)+0.5*$C$19*((O8-$C$5)^2)) -> 116.71625
B9: Semi-Annually Coupon | C9: =C8/2 -> 2.25 | F9: =EDATE(F8,6) -> 46819 | G9: 5 | H9: =$C$9 -> 2.25 | I9: =H9/(1+$C$6)^G9 -> 2.0116268 | J9: =I9/$I$24 -> 0.020162547 | K9: =J9*G9 -> 0.10081273 | L9: =G9*(G9+1)*I9 -> 60.348803 | O9: 0.04 | P9: 103.91962 | Q9: =$I$24*(1-$C$18*(O9-$C$5)) -> 107.69391 | R9: =$I$24*(1-$C$18*(O9-$C$5)+0.5*$C$19*((O9-$C$5)^2)) -> 108.10362
B10: Issue Date | C10: 45723 | F10: =EDATE(F9,6) -> 47003 | G10: 6 | H10: =$C$9 -> 2.25 | I10: =H10/(1+$C$6)^G10 -> 1.9670726 | J10: =I10/$I$24 -> 0.01971598 | K10: =J10*G10 -> 0.11829588 | L10: =G10*(G10+1)*I10 -> 82.617048 | O10: 0.045 | P10: 100 | Q10: =$I$24*(1-$C$18*(O10-$C$5)) -> 100.21897 | R10: =$I$24*(1-$C$18*(O10-$C$5)+0.5*$C$19*((O10-$C$5)^2)) -> 100.22028
B11: Last Coupon Payment Date | C11: =EDATE(C10,6) -> 45907 | F11: =EDATE(F10,6) -> 47184 | G11: 7 | H11: =$C$9 -> 2.25 | I11: =H11/(1+$C$6)^G11 -> 1.9235052 | J11: =I11/$I$24 -> 0.019279303 | K11: =J11*G11 -> 0.13495512 | L11: =G11*(G11+1)*I11 -> 107.71629 | O11: 0.05 | P11: 96.255277 | Q11: =$I$24*(1-$C$18*(O11-$C$5)) -> 92.744028 | R11: =$I$24*(1-$C$18*(O11-$C$5)+0.5*$C$19*((O11-$C$5)^2)) -> 93.066228
B12: Next Coupon Payment Date | C12: =EDATE(C11,6) -> 46088 | F12: =EDATE(F11,6) -> 47368 | G12: 8 | H12: =$C$9 -> 2.25 | I12: =H12/(1+$C$6)^G12 -> 1.8809027 | J12: =I12/$I$24 -> 0.018852299 | K12: =J12*G12 -> 0.15081839 | L12: =G12*(G12+1)*I12 -> 135.425 | O12: 0.055 | P12: 92.676999 | Q12: =$I$24*(1-$C$18*(O12-$C$5)) -> 85.269089 | R12: =$I$24*(1-$C$18*(O12-$C$5)+0.5*$C$19*((O12-$C$5)^2)) -> 86.641464
B13: Settlement Date | C13: =TODAY() -> 46006 | F13: =EDATE(F12,6) -> 47549 | G13: 9 | H13: =$C$9 -> 2.25 | I13: =H13/(1+$C$6)^G13 -> 1.8392439 | J13: =I13/$I$24 -> 0.018434752 | K13: =J13*G13 -> 0.16591276 | L13: =G13*(G13+1)*I13 -> 165.53195 | O13: 0.06 | P13: 89.257151 | Q13: =$I$24*(1-$C$18*(O13-$C$5)) -> 77.79415 | R13: =$I$24*(1-$C$18*(O13-$C$5)+0.5*$C$19*((O13-$C$5)^2)) -> 80.945988
B14: Maturity Date | C14: 49375 | F14: =EDATE(F13,6) -> 47733 | G14: 10 | H14: =$C$9 -> 2.25 | I14: =H14/(1+$C$6)^G14 -> 1.7985077 | J14: =I14/$I$24 -> 0.018026453 | K14: =J14*G14 -> 0.18026453 | L14: =G14*(G14+1)*I14 -> 197.83584 | O14: 0.065 | P14: 85.988125 | Q14: =$I$24*(1-$C$18*(O14-$C$5)) -> 70.319211 | R14: =$I$24*(1-$C$18*(O14-$C$5)+0.5*$C$19*((O14-$C$5)^2)) -> 75.9798
F15: =EDATE(F14,6) -> 47914 | G15: 11 | H15: =$C$9 -> 2.25 | I15: =H15/(1+$C$6)^G15 -> 1.7586737 | J15: =I15/$I$24 -> 0.017627197 | K15: =J15*G15 -> 0.19389916 | L15: =G15*(G15+1)*I15 -> 232.14493 | O15: 0.07 | P15: 82.862703 | Q15: =$I$24*(1-$C$18*(O15-$C$5)) -> 62.844272 | R15: =$I$24*(1-$C$18*(O15-$C$5)+0.5*$C$19*((O15-$C$5)^2)) -> 71.742901
F16: =EDATE(F15,6) -> 48098 | G16: 12 | H16: =$C$9 -> 2.25 | I16: =H16/(1+$C$6)^G16 -> 1.719722 | J16: =I16/$I$24 -> 0.017236783 | K16: =J16*G16 -> 0.2068414 | L16: =G16*(G16+1)*I16 -> 268.27663 | O16: 0.075 | P16: 79.874032 | Q16: =$I$24*(1-$C$18*(O16-$C$5)) -> 55.369333 | R16: =$I$24*(1-$C$18*(O16-$C$5)+0.5*$C$19*((O16-$C$5)^2)) -> 68.23529
B17: Macaulay Duration | C17: =K24 -> 15.663059 | F17: =EDATE(F16,6) -> 48280 | G17: 13 | H17: =$C$9 -> 2.25 | I17: =H17/(1+$C$6)^G17 -> 1.681633 | J17: =I17/$I$24 -> 0.016855017 | K17: =J17*G17 -> 0.21911522 | L17: =G17*(G17+1)*I17 -> 306.05721 | O17: 0.08 | P17: 77.015606 | Q17: =$I$24*(1-$C$18*(O17-$C$5)) -> 47.894394 | R17: =$I$24*(1-$C$18*(O17-$C$5)+0.5*$C$19*((O17-$C$5)^2)) -> 65.456967
B18: Modified Duration | C18: =C17/(1+C5) -> 14.984271 | F18: =EDATE(F17,6) -> 48464 | G18: 14 | H18: =$C$9 -> 2.25 | I18: =H18/(1+$C$6)^G18 -> 1.6443876 | J18: =I18/$I$24 -> 0.016481707 | K18: =J18*G18 -> 0.23074389 | L18: =G18*(G18+1)*I18 -> 345.3214
B19: Convexity | C19: =L24/I24 -> 292.38641 | F19: =EDATE(F18,6) -> 48645 | G19: 15 | H19: =$C$9 -> 2.25 | I19: =H19/(1+$C$6)^G19 -> 1.6079672 | J19: =I19/$I$24 -> 0.016116664 | K19: =J19*G19 -> 0.24174996 | L19: =G19*(G19+1)*I19 -> 385.91212
F20: =EDATE(F19,6) -> 48829 | G20: 16 | H20: =$C$9 -> 2.25 | I20: =H20/(1+$C$6)^G20 -> 1.5723534 | J20: =I20/$I$24 -> 0.015759707 | K20: =J20*G20 -> 0.25215531 | L20: =G20*(G20+1)*I20 -> 427.68012
F21: =EDATE(F20,6) -> 49010 | G21: 17 | H21: =$C$9 -> 2.25 | I21: =H21/(1+$C$6)^G21 -> 1.5375284 | J21: =I21/$I$24 -> 0.015410655 | K21: =J21*G21 -> 0.26198114 | L21: =G21*(G21+1)*I21 -> 470.48368
F22: =EDATE(F21,6) -> 49194 | G22: 18 | H22: =$C$9 -> 2.25 | I22: =H22/(1+$C$6)^G22 -> 1.5034746 | J22: =I22/$I$24 -> 0.015069335 | K22: =J22*G22 -> 0.27124803 | L22: =G22*(G22+1)*I22 -> 514.18833
F23: =EDATE(F22,6) -> 49375 | G23: 19 | H23: =$C$9+C4 -> 102.25 | I23: =H23/(1+$C$6)^G23 -> 66.811294 | J23: =I23/$I$24 -> 0.66964998 | K23: =J23*G23 -> 12.72335 | L23: =G23*(G23+1)*I23 -> 25388.292
I24: =SUM(I5:I23) -> 99.770471 | K24: =SUM(K5:K23) -> 15.663059 | L24: =SUM(L5:L23) -> 29171.529

Sheet 10 Year Scenario
P2: Parallel Up | Q2: 0.0025 | AA2: Parallel Down | AB2: 0.0025
B3: 10-Year Bond | E3: Period | F3: Scenario Rate | G3: Cash Flow | H3: PV of CF | I3: PV as % of CF | J3: TW PV of CF | K3: Reivestment as per theory | M3: TW^2 PV of CF | P3: Period | Q3: Scenario Rate | R3: Cash Flow | S3: PV of CF | T3: PV as % of CF | U3: TW PV of CF | V3: Reivestment as per theory | X3: TW^2 PV of CF | AA3: Period | AB3: Scenario Rate | AC3: Cash Flow | AD3: PV of CF | AE3: PV as % of CF | AF3: TW PV of CF | AG3: Reivestment as per theory | AI3: TW^2 PV of CF
B4: Price | C4: 99.809 | E4: 1 | F4: =$C$7 -> 0.02265 | G4: =$C$10 -> 2.25 | H4: =G4/(1+F4)^E4 -> 2.2001662 | I4: =H4/$H$24 -> 0.022054397 | J4: =I4*E4 -> 0.022054397 | K4: =H4*(1+F4)^($E$19-E4) -> 3.0786537 | M4: =E4*(E4+1)*H4 -> 4.4003325 | P4: 1 | Q4: =$C$7 -> 0.02265 | R4: =$C$10 -> 2.25 | S4: =R4/(1+Q4)^P4 -> 2.2001662 | T4: =S4/$S$24 -> 0.030671336 | U4: =T4*P4 -> 0.030671336 | V4: =S4*(1+Q4)^($P$18-P4) -> 3.0104666 | X4: =P4*(P4+1)*S4 -> 4.4003325 | AA4: 1 | AB4: =$C$7 -> 0.02265 | AC4: =$C$10 -> 2.25 | AD4: =AC4/(1+AB4)^AA4 -> 2.2001662 | AE4: =AD4/$AD$24 -> 0.015261136 | AF4: =AE4*AA4 -> 0.015261136 | AG4: =AD4*(1+AB4)^($P$18-AA4) -> 3.0104666 | AI4: =AA4*(AA4+1)*AD4 -> 4.4003325
B5: Face Value | C5: 100 | E5: 2 | F5: =$C$7 -> 0.02265 | G5: =$C$10 -> 2.25 | H5: =G5/(1+F5)^E5 -> 2.1514362 | I5: =H5/$H$24 -> 0.021565929 | J5: =I5*E5 -> 0.043131858 | K5: =H5*(1+F5)^($E$19-E5) -> 2.9437898 | M5: =E5*(E5+1)*H5 -> 12.908617 | P5: 2 | Q5: =Q4+$Q$2/2 -> 0.0239 | R5: =$C$10 -> 2.25 | S5: =R5/(1+Q5)^P5 -> 2.1461864 | T5: =S5/$S$24 -> 0.029918832 | U5: =T5*P5 -> 0.059837663 | V5: =S5*(1+Q5)^($P$18-P5) -> 2.9175311 | X5: =P5*(P5+1)*S5 -> 12.877118 | AA5: 2 | AB5: =AB4-$Q$2/2 -> 0.0214 | AC5: =$C$10 -> 2.25 | AD5: =AC5/(1+AB5)^AA5 -> 2.1567053 | AE5: =AD5/$AD$24 -> 0.014959676 | AF5: =AE5*AA5 -> 0.029919351 | AG5: =AD5*(1+AB5)^($P$18-AA5) -> 2.8401214 | AI5: =AA5*(AA5+1)*AD5 -> 12.940232
B6: Yield | C6: 0.0453 | E6: 3 | F6: =$C$7 -> 0.02265 | G6: =$C$10 -> 2.25 | H6: =G6/(1+F6)^E6 -> 2.1037855 | I6: =H6/$H$24 -> 0.021088279 | J6: =I6*E6 -> 0.063264838 | K6: =H6*(1+F6)^($E$19-E6) -> 2.8148337 | M6: =E6*(E6+1)*H6 -> 25.245426 | P6: 3 | Q6: =Q5+$Q$2/2 -> 0.02515 | R6: =$C$10 -> 2.25 | S6: =R6/(1+Q6)^P6 -> 2.0884317 | T6: =S6/$S$24 -> 0.029113704 | U6: =T6*P6 -> 0.087341113 | V6: =S6*(1+Q6)^($P$18-P6) -> 2.8136447 | X6: =P6*(P6+1)*S6 -> 25.06118 | AA6: 3 | AB6: =AB5-$Q$2/2 -> 0.02015 | AC6: =$C$10 -> 2.25 | AD6: =AC6/(1+AB6)^AA6 -> 2.1192901 | AE6: =AD6/$AD$24 -> 0.01470015 | AF6: =AE6*AA6 -> 0.044100451 | AG6: =AD6*(1+AB6)^($P$18-AA6) -> 2.6925193 | AI6: =AA6*(AA6+1)*AD6 -> 25.431482
B7: Semi-Annually Yield | C7: =C6/2 -> 0.02265 | E7: 4 | F7: =$C$7 -> 0.02265 | G7: =$C$10 -> 2.25 | H7: =G7/(1+F7)^E7 -> 2.0571901 | I7: =H7/$H$24 -> 0.020621209 | J7: =I7*E7 -> 0.082484836 | K7: =H7*(1+F7)^($E$19-E7) -> 2.6915267 | M7: =E7*(E7+1)*H7 -> 41.143802 | P7: 4 | Q7: =Q6+$Q$2/2 -> 0.0264 | R7: =$C$10 -> 2.25 | S7: =R7/(1+Q7)^P7 -> 2.0272903 | T7: =S7/$S$24 -> 0.028261366 | U7: =T7*P7 -> 0.11304546 | V7: =S7*(1+Q7)^($P$18-P7) -> 2.7002192 | X7: =P7*(P7+1)*S7 -> 40.545806 | AA7: 4 | AB7: =AB6-$Q$2/2 -> 0.0189 | AC7: =$C$10 -> 2.25 | AD7: =AC7/(1+AB7)^AA7 -> 2.0876432 | AE7: =AD7/$AD$24 -> 0.014480636 | AF7: =AE7*AA7 -> 0.057922543 | AG7: =AD7*(1+AB7)^($P$18-AA7) -> 2.565095 | AI7: =AA7*(AA7+1)*AD7 -> 41.752863
B8: Coupon Rate | C8: 0.045 | E8: 5 | F8: =$C$7 -> 0.02265 | G8: =$C$10 -> 2.25 | H8: =G8/(1+F8)^E8 -> 2.0116268 | I8: =H8/$H$24 -> 0.020164484 | J8: =I8*E8 -> 0.10082242 | K8: =H8*(1+F8)^($E$19-E8) -> 2.5736214 | M8: =E8*(E8+1)*H8 -> 60.348803 | P8: 5 | Q8: =Q7+$Q$2/2 -> 0.02765 | R8: =$C$10 -> 2.25 | S8: =R8/(1+Q8)^P8 -> 1.9631631 | T8: =S8/$S$24 -> 0.027367403 | U8: =T8*P8 -> 0.13683701 | V8: =S8*(1+Q8)^($P$18-P8) -> 2.5787465 | X8: =P8*(P8+1)*S8 -> 58.894893 | AA8: 5 | AB8: =AB7-$Q$2/2 -> 0.01765 | AC8: =$C$10 -> 2.25 | AD8: =AC8/(1+AB8)^AA8 -> 2.0615332 | AE8: =AD8/$AD$24 -> 0.014299528 | AF8: =AE8*AA8 -> 0.071497639 | AG8: =AD8*(1+AB8)^($P$18-AA8) -> 2.4556966 | AI8: =AA8*(AA8+1)*AD8 -> 61.845996
B9: Coupon | C9: =C5*C8 -> 4.5 | E9: 6 | F9: =$C$7 -> 0.02265 | G9: =$C$10 -> 2.25 | H9: =G9/(1+F9)^E9 -> 1.9670726 | I9: =H9/$H$24 -> 0.019717874 | J9: =I9*E9 -> 0.11830724 | K9: =H9*(1+F9)^($E$19-E9) -> 2.460881 | M9: =E9*(E9+1)*H9 -> 82.617048 | P9: 6 | Q9: =Q8+$Q$2/2 -> 0.0289 | R9: =$C$10 -> 2.25 | S9: =R9/(1+Q9)^P9 -> 1.8964592 | T9: =S9/$S$24 -> 0.02643752 | U9: =T9*P9 -> 0.15862512 | V9: =S9*(1+Q9)^($P$18-P9) -> 2.450767 | X9: =P9*(P9+1)*S9 -> 79.651288 | AA9: 6 | AB9: =AB8-$Q$2/2 -> 0.0164 | AC9: =$C$10 -> 2.25 | AD9: =AC9/(1+AB9)^AA9 -> 2.0407724 | AE9: =AD9/$AD$24 -> 0.014155524 | AF9: =AE9*AA9 -> 0.084933143 | AG9: =AD9*(1+AB9)^($P$18-AA9) -> 2.3625254 | AI9: =AA9*(AA9+1)*AD9 -> 85.712442
B10: Semi-Annually Coupon | C10: =C9/2 -> 2.25 | E10: 7 | F10: =$C$7 -> 0.02265 | G10: =$C$10 -> 2.25 | H10: =G10/(1+F10)^E10 -> 1.9235052 | I10: =H10/$H$24 -> 0.019281156 | J10: =I10*E10 -> 0.13496809 | K10: =H10*(1+F10)^($E$19-E10) -> 2.3530793 | M10: =E10*(E10+1)*H10 -> 107.71629 | P10: 7 | Q10: =Q9+$Q$2/2 -> 0.03015 | R10: =$C$10 -> 2.25 | S10: =R10/(1+Q10)^P10 -> 1.827592 | T10: =S10/$S$24 -> 0.025477479 | U10: =T10*P10 -> 0.17834235 | V10: =S10*(1+Q10)^($P$18-P10) -> 2.3178375 | X10: =P10*(P10+1)*S10 -> 102.34515 | AA10: 7 | AB10: =AB9-$Q$2/2 -> 0.01515 | AC10: =$C$10 -> 2.25 | AD10: =AC10/(1+AB10)^AA10 -> 2.0252143 | AE10: =AD10/$AD$24 -> 0.014047607 | AF10: =AE10*AA10 -> 0.098333249 | AG10: =AD10*(1+AB10)^($P$18-AA10) -> 2.2840875 | AI10: =AA10*(AA10+1)*AD10 -> 113.412
B11: Issue Date | C11: 45723 | E11: 8 | F11: =$C$7 -> 0.02265 | G11: =$C$10 -> 2.25 | H11: =G11/(1+F11)^E11 -> 1.8809027 | I11: =H11/$H$24 -> 0.01885411 | J11: =I11*E11 -> 0.15083288 | K11: =H11*(1+F11)^($E$19-E11) -> 2.25 | M11: =E11*(E11+1)*H11 -> 135.425 | P11: 8 | Q11: =Q10+$Q$2/2 -> 0.0314 | R11: =$C$10 -> 2.25 | S11: =R11/(1+Q11)^P11 -> 1.7569747 | T11: =S11/$S$24 -> 0.02449304 | U11: =T11*P11 -> 0.19594432 | V11: =S11*(1+Q11)^($P$18-P11) -> 2.1815009 | X11: =P11*(P11+1)*S11 -> 126.50218 | AA11: 8 | AB11: =AB10-$Q$2/2 -> 0.0139 | AC11: =$C$10 -> 2.25 | AD11: =AC11/(1+AB11)^AA11 -> 2.0147517 | AE11: =AD11/$AD$24 -> 0.013975035 | AF11: =AE11*AA11 -> 0.11180028 | AG11: =AD11*(1+AB11)^($P$18-AA11) -> 2.2191538 | AI11: =AA11*(AA11+1)*AD11 -> 145.06212
B12: Last Coupon Payment Date | C12: =EDATE(C11,6) -> 45907 | E12: 9 | F12: =$C$7 -> 0.02265 | G12: =$C$10 -> 2.25 | H12: =G12/(1+F12)^E12 -> 1.8392439 | I12: =H12/$H$24 -> 0.018436523 | J12: =I12*E12 -> 0.1659287 | K12: =H12*(1+F12)^($E$19-E12) -> 2.1514362 | M12: =E12*(E12+1)*H12 -> 165.53195 | P12: 9 | Q12: =Q11+$Q$2/2 -> 0.03265 | R12: =$C$10 -> 2.25 | S12: =R12/(1+Q12)^P12 -> 1.6850166 | T12: =S12/$S$24 -> 0.023489911 | U12: =T12*P12 -> 0.2114092 | V12: =S12*(1+Q12)^($P$18-P12) -> 2.0432574 | X12: =P12*(P12+1)*S12 -> 151.65149 | AA12: 9 | AB12: =AB11-$Q$2/2 -> 0.01265 | AC12: =$C$10 -> 2.25 | AD12: =AC12/(1+AB12)^AA12 -> 2.0093159 | AE12: =AD12/$AD$24 -> 0.01393733 | AF12: =AE12*AA12 -> 0.12543597 | AG12: =AD12*(1+AB12)^($P$18-AA12) -> 2.1667281 | AI12: =AA12*(AA12+1)*AD12 -> 180.83843
B13: Next Coupon Payment Date | C13: =EDATE(C12,6) -> 46088 | E13: 10 | F13: =$C$7 -> 0.02265 | G13: =$C$10 -> 2.25 | H13: =G13/(1+F13)^E13 -> 1.7985077 | I13: =H13/$H$24 -> 0.018028184 | J13: =I13*E13 -> 0.18028184 | K13: =H13*(1+F13)^($E$19-E13) -> 2.0571901 | M13: =E13*(E13+1)*H13 -> 197.83584 | P13: 10 | Q13: =Q12+$Q$2/2 -> 0.0339 | R13: =$C$10 -> 2.25 | S13: =R13/(1+Q13)^P13 -> 1.6121193 | T13: =S13/$S$24 -> 0.022473689 | U13: =T13*P13 -> 0.22473689 | V13: =S13*(1+Q13)^($P$18-P13) -> 1.9045389 | X13: =P13*(P13+1)*S13 -> 177.33312 | AA13: 10 | AB13: =AB12-$Q$2/2 -> 0.0114 | AC13: =$C$10 -> 2.25 | AD13: =AC13/(1+AB13)^AA13 -> 2.0088755 | AE13: =AD13/$AD$24 -> 0.013934275 | AF13: =AE13*AA13 -> 0.13934275 | AG13: =AD13*(1+AB13)^($P$18-AA13) -> 2.1260221 | AI13: =AA13*(AA13+1)*AD13 -> 220.97631
B14: Settlement Date | C14: 46005 | E14: 11 | F14: =$C$7 -> 0.02265 | G14: =$C$10 -> 2.25 | H14: =G14/(1+F14)^E14 -> 1.7586737 | I14: =H14/$H$24 -> 0.01762889 | J14: =I14*E14 -> 0.19391779 | K14: =H14*(1+F14)^($E$19-E14) -> 1.9670726 | M14: =E14*(E14+1)*H14 -> 232.14493 | P14: 11 | Q14: =Q13+$Q$2/2 -> 0.03515 | R14: =$C$10 -> 2.25 | S14: =R14/(1+Q14)^P14 -> 1.5386731 | T14: =S14/$S$24 -> 0.021449816 | U14: =T14*P14 -> 0.23594797 | V14: =S14*(1+Q14)^($P$18-P14) -> 1.7666866 | X14: =P14*(P14+1)*S14 -> 203.10485 | AA14: 11 | AB14: =AB13-$Q$2/2 -> 0.01015 | AC14: =$C$10 -> 2.25 | AD14: =AC14/(1+AB14)^AA14 -> 2.0134366 | AE14: =AD14/$AD$24 -> 0.013965913 | AF14: =AE14*AA14 -> 0.15362504 | AG14: =AD14*(1+AB14)^($P$18-AA14) -> 2.0964352 | AI14: =AA14*(AA14+1)*AD14 -> 265.77364
B15: Maturity Date | C15: 49375 | E15: 12 | F15: =$C$7 -> 0.02265 | G15: =$C$10 -> 2.25 | H15: =G15/(1+F15)^E15 -> 1.719722 | I15: =H15/$H$24 -> 0.017238439 | J15: =I15*E15 -> 0.20686127 | K15: =H15*(1+F15)^($E$19-E15) -> 1.8809027 | M15: =E15*(E15+1)*H15 -> 268.27663 | P15: 12 | Q15: =Q14+$Q$2/2 -> 0.0364 | R15: =$C$10 -> 2.25 | S15: =R15/(1+Q15)^P15 -> 1.4650541 | T15: =S15/$S$24 -> 0.020423533 | U15: =T15*P15 -> 0.24508239 | V15: =S15*(1+Q15)^($P$18-P15) -> 1.6309321 | X15: =P15*(P15+1)*S15 -> 228.54844 | AA15: 12 | AB15: =AB14-$Q$2/2 -> 0.0089 | AC15: =$C$10 -> 2.25 | AD15: =AC15/(1+AB15)^AA15 -> 2.0230427 | AE15: =AD15/$AD$24 -> 0.014032544 | AF15: =AE15*AA15 -> 0.16839053 | AG15: =AD15*(1+AB15)^($P$18-AA15) -> 2.0775401 | AI15: =AA15*(AA15+1)*AD15 -> 315.59466
E16: 13 | F16: =$C$7 -> 0.02265 | G16: =$C$10 -> 2.25 | H16: =G16/(1+F16)^E16 -> 1.681633 | I16: =H16/$H$24 -> 0.016856636 | J16: =I16*E16 -> 0.21913627 | K16: =H16*(1+F16)^($E$19-E16) -> 1.7985077 | M16: =E16*(E16+1)*H16 -> 306.05721 | P16: 13 | Q16: =Q15+$Q$2/2 -> 0.03765 | R16: =$C$10 -> 2.25 | S16: =R16/(1+Q16)^P16 -> 1.3916209 | T16: =S16/$S$24 -> 0.01939984 | U16: =T16*P16 -> 0.25219792 | V16: =S16*(1+Q16)^($P$18-P16) -> 1.4983826 | X16: =P16*(P16+1)*S16 -> 253.275 | AA16: 13 | AB16: =AB15-$Q$2/2 -> 0.00765 | AC16: =$C$10 -> 2.25 | AD16: =AC16/(1+AB16)^AA16 -> 2.0377753 | AE16: =AD16/$AD$24 -> 0.014134735 | AF16: =AE16*AA16 -> 0.18375155 | AG16: =AD16*(1+AB16)^($P$18-AA16) -> 2.0690725 | AI16: =AA16*(AA16+1)*AD16 -> 370.87511
E17: 14 | F17: =$C$7 -> 0.02265 | G17: =$C$10 -> 2.25 | H17: =G17/(1+F17)^E17 -> 1.6443876 | I17: =H17/$H$24 -> 0.01648329 | J17: =I17*E17 -> 0.23076606 | K17: =H17*(1+F17)^($E$19-E17) -> 1.719722 | M17: =E17*(E17+1)*H17 -> 345.3214 | P17: 14 | Q17: =Q16+$Q$2/2 -> 0.0389 | R17: =$C$10 -> 2.25 | S17: =R17/(1+Q17)^P17 -> 1.3187123 | T17: =S17/$S$24 -> 0.018383461 | U17: =T17*P17 -> 0.25736845 | V17: =S17*(1+Q17)^($P$18-P17) -> 1.3700103 | X17: =P17*(P17+1)*S17 -> 276.92959 | AA17: 14 | AB17: =AB16-$Q$2/2 -> 0.0064 | AC17: =$C$10 -> 2.25 | AD17: =AC17/(1+AB17)^AA17 -> 2.0577553 | AE17: =AD17/$AD$24 -> 0.014273323 | AF17: =AE17*AA17 -> 0.19982652 | AG17: =AD17*(1+AB17)^($P$18-AA17) -> 2.0709249 | AI17: =AA17*(AA17+1)*AD17 -> 432.12861
E18: 15 | F18: =$C$7 -> 0.02265 | G18: =$C$10 -> 2.25 | H18: =G18/(1+F18)^E18 -> 1.6079672 | I18: =H18/$H$24 -> 0.016118212 | J18: =I18*E18 -> 0.24177319 | K18: =H18*(1+F18)^($E$19-E18) -> 1.6443876 | M18: =E18*(E18+1)*H18 -> 385.91212 | P18: 15 | Q18: =Q17+$Q$2/2 -> 0.04015 | R18: =$C$10 -> 2.25 | S18: =R18/(1+Q18)^P18 -> 1.2466453 | T18: =S18/$S$24 -> 0.017378813 | U18: =T18*P18 -> 0.2606822 | V18: =S18*(1+Q18)^($P$18-P18) -> 1.2466453 | X18: =P18*(P18+1)*S18 -> 299.19488 | AA18: 15 | AB18: =AB17-$Q$2/2 -> 0.00515 | AC18: =$C$10 -> 2.25 | AD18: =AC18/(1+AB18)^AA18 -> 2.0831443 | AE18: =AD18/$AD$24 -> 0.01444943 | AF18: =AE18*AA18 -> 0.21674146 | AG18: =AD18*(1+AB18)^($P$18-AA18) -> 2.0831443 | AI18: =AA18*(AA18+1)*AD18 -> 499.95464
E19: 16 | F19: =$C$7 -> 0.02265 | G19: =$C$10 -> 2.25 | H19: =G19/(1+F19)^E19 -> 1.5723534 | I19: =H19/$H$24 -> 0.015761221 | J19: =I19*E19 -> 0.25217953 | K19: =H19*(1+F19)^($E$19-E19) -> 1.5723534 | M19: =E19*(E19+1)*H19 -> 427.68012 | P19: 16 | Q19: =Q18+$Q$2/2 -> 0.0414 | R19: =$C$10 -> 2.25 | S19: =R19/(1+Q19)^P19 -> 1.1757131 | T19: =S19/$S$24 -> 0.016389984 | U19: =T19*P19 -> 0.26223975 | W19: =SUM(V4:V18) -> 32.431167 | X19: =P19*(P19+1)*S19 -> 319.79395 | AA19: 16 | AB19: =AB18-$Q$2/2 -> 0.0039 | AC19: =$C$10 -> 2.25 | AD19: =AC19/(1+AB19)^AA19 -> 2.1141473 | AE19: =AD19/$AD$24 -> 0.014664478 | AF19: =AE19*AA19 -> 0.23463165 | AG19: =AD19*(1+AB19)^($P$18-AA19) -> 2.1059342 | AI19: =AA19*(AA19+1)*AD19 -> 575.04808
E20: 17 | F20: =$C$7 -> 0.02265 | G20: =$C$10 -> 2.25 | H20: =G20/(1+F20)^E20 -> 1.5375284 | I20: =H20/$H$24 -> 0.015412136 | J20: =I20*E20 -> 0.26200631 | L20: =SUM(K4:K19) -> 35.957958 | M20: =E20*(E20+1)*H20 -> 470.48368 | P20: 17 | Q20: =Q19+$Q$2/2 -> 0.04265 | R20: =$C$10 -> 2.25 | S20: =R20/(1+Q20)^P20 -> 1.1061836 | T20: =S20/$S$24 -> 0.015420711 | U20: =T20*P20 -> 0.26215209 | X20: =P20*(P20+1)*S20 -> 338.49218 | AA20: 17 | AB20: =AB19-$Q$2/2 -> 0.00265 | AC20: =$C$10 -> 2.25 | AD20: =AC20/(1+AB20)^AA20 -> 2.151015 | AE20: =AD20/$AD$24 -> 0.014920205 | AF20: =AE20*AA20 -> 0.25364349 | AH20: =SUM(AG4:AG18) -> 35.119533 | AI20: =AA20*(AA20+1)*AD20 -> 658.21058
E21: 18 | F21: =$C$7 -> 0.02265 | G21: =$C$10 -> 2.25 | H21: =G21/(1+F21)^E21 -> 1.5034746 | I21: =H21/$H$24 -> 0.015070783 | J21: =I21*E21 -> 0.27127409 | M21: =E21*(E21+1)*H21 -> 514.18833 | P21: 18 | Q21: =Q20+$Q$2/2 -> 0.0439 | R21: =$C$10 -> 2.25 | S21: =R21/(1+Q21)^P21 -> 1.0382988 | T21: =S21/$S$24 -> 0.014474366 | U21: =T21*P21 -> 0.26053859 | X21: =P21*(P21+1)*S21 -> 355.0982 | AA21: 18 | AB21: =AB20-$Q$2/2 -> 0.0014 | AC21: =$C$10 -> 2.25 | AD21: =AC21/(1+AB21)^AA21 -> 2.1940471 | AE21: =AD21/$AD$24 -> 0.015218692 | AF21: =AE21*AA21 -> 0.27393645 | AI21: =AA21*(AA21+1)*AD21 -> 750.36412
E22: 19 | F22: =$C$7 -> 0.02265 | G22: =$C$10 -> 2.25 | H22: =G22/(1+F22)^E22 -> 1.4701752 | I22: =H22/$H$24 -> 0.01473699 | J22: =I22*E22 -> 0.28000281 | M22: =E22*(E22+1)*H22 -> 558.66657 | P22: 19 | Q22: =Q21+$Q$2/2 -> 0.04515 | R22: =$C$10 -> 2.25 | S22: =R22/(1+Q22)^P22 -> 0.97227394 | T22: =S22/$S$24 -> 0.013553949 | U22: =T22*P22 -> 0.25752503 | X22: =P22*(P22+1)*S22 -> 369.4641 | AA22: 19 | AB22: =AB21-$Q$2/2 -> 0.00015 | AC22: =$C$10 -> 2.25 | AD22: =AC22/(1+AB22)^AA22 -> 2.2435971 | AE22: =AD22/$AD$24 -> 0.015562388 | AF22: =AE22*AA22 -> 0.29568537 | AI22: =AA22*(AA22+1)*AD22 -> 852.5669
E23: 20 | F23: =$C$7 -> 0.02265 | G23: =$C$10+$C$5 -> 102.25 | H23: =G23/(1+F23)^E23 -> 65.331535 | I23: =H23/$H$24 -> 0.65488126 | J23: =I23*E23 -> 13.097625 | M23: =E23*(E23+1)*H23 -> 27439.245 | P23: 20 | Q23: =Q22+$Q$2/2 -> 0.0464 | R23: =$C$10+$C$5 -> 102.25 | S23: =R23/(1+Q23)^P23 -> 41.277054 | T23: =S23/$S$24 -> 0.57542125 | U23: =T23*P23 -> 11.508425 | X23: =P23*(P23+1)*S23 -> 17336.363 | AA23: 20 | AB23: =AB22-$Q$2/2 -> -0.0011 | AC23: =$C$10+$C$5 -> 102.25 | AD23: =AC23/(1+AB23)^AA23 -> 104.52569 | AE23: =AD23/$AD$24 -> 0.7250274 | AF23: =AE23*AA23 -> 14.500548 | AI23: =AA23*(AA23+1)*AD23 -> 43900.791
H24: =SUM(H4:H23) -> 99.760887 | J24: =SUM(J4:J23) -> 16.31762 | M24: =SUM(M4:M23) -> 31781.149 | S24: =SUM(S4:S23) -> 71.733629 | U24: =SUM(U4:U23) -> 15.19895 | X24: =SUM(X4:X23) -> 20759.527 | AD24: =SUM(AD4:AD23) -> 144.16792 | AF24: =SUM(AF4:AF23) -> 17.259326 | AI24: =SUM(AI4:AI23) -> 49513.679
E26: Macaulay Duration | F26: =J24 -> 16.31762 | P26: Macaulay Duration | Q26: =U24 -> 15.19895 | AA26: Macaulay Duration | AB26: =AF24 -> 17.259326
E27: Modified Duration | F27: =F26/(1+$C$6) -> 15.610465 | P27: Modified Duration | Q27: =Q26/(1+$C$6) -> 14.540275 | AA27: Modified Duration | AB27: =AB26/(1+$C$6) -> 16.511362
E28: Convexity | F28: =M24/H24 -> 318.57324 | P28: Convexity | Q28: =X24/S24 -> 289.39741 | AA28: Convexity | AB28: =AI24/AD24 -> 343.4445
E29: GBP01 | F29: =H24*F27*0.0001 -> 0.15573139 | P29: GBP01 | Q29: =S24*Q27*0.0001 -> 0.10430267 | AA29: GBP01 | AB29: =AD24*AB27*0.0001 -> 0.23804087

Sheet 30 year Gilt
B2: 30-Year Bond | F2: Coupon Payment Date | G2: Period | H2: Cash Flow | I2: PV of CF | J2: PV as % of Sum of PV | K2: TW PV of CF | L2: TW^2 PV of CF | O2: Yield | P2: Price | Q2: Duration Implied Price | R2: Convexity Implied Price
B3: Price | C3: =I62 -> 86.694441 | F3: =C10 -> 45869 | O3: 0.01 | P3: 152.07025 | Q3: =$I$62*(1-$C$18*(O3-$C$5)) -> 197.68049 | R3: =$I$62*(1-$C$18*(O3-$C$5)+0.5*$C$19*((O3-$C$5)^2)) -> 312.73773
B4: Face Value | C4: 100 | F4: =EDATE(F3,6) -> 46053 | G4: 1 | H4: =$C$9 -> 2.1875 | I4: =H4/(1+$C$6)^G4 -> 2.1312769 | J4: =I4/$I$62 -> 0.024583778 | K4: =J4*G4 -> 0.024583778 | L4: =G4*(G4+1)*I4 -> 4.2625538 | O4: 0.015 | P4: 126.50693 | Q4: =$I$62*(1-$C$18*(O4-$C$5)) -> 184.7027 | R4: =$I$62*(1-$C$18*(O4-$C$5)+0.5*$C$19*((O4-$C$5)^2)) -> 274.42544
B5: Yield | C5: 0.05276 | F5: =EDATE(F4,6) -> 46234 | G5: 2 | H5: =$C$9 -> 2.1875 | I5: =H5/(1+$C$6)^G5 -> 2.0764989 | J5: =I5/$I$62 -> 0.023951926 | K5: =J5*G5 -> 0.047903853 | L5: =G5*(G5+1)*I5 -> 12.458993 | O5: 0.02 | P5: 106.40223 | Q5: =$I$62*(1-$C$18*(O5-$C$5)) -> 171.72491 | R5: =$I$62*(1-$C$18*(O5-$C$5)+0.5*$C$19*((O5-$C$5)^2)) -> 239.25952
B6: Semi-Annually Yield | C6: =C5/2 -> 0.02638 | F6: =EDATE(F5,6) -> 46418 | G6: 3 | H6: =$C$9 -> 2.1875 | I6: =H6/(1+$C$6)^G6 -> 2.0231287 | J6: =I6/$I$62 -> 0.023336314 | K6: =J6*G6 -> 0.070008943 | L6: =G6*(G6+1)*I6 -> 24.277545 | O6: 0.025 | P6: 90.484873 | Q6: =$I$62*(1-$C$18*(O6-$C$5)) -> 158.74713 | R6: =$I$62*(1-$C$18*(O6-$C$5)+0.5*$C$19*((O6-$C$5)^2)) -> 207.23995
B7: Coupon Rate | C7: 0.04375 | F7: =EDATE(F6,6) -> 46599 | G7: 4 | H7: =$C$9 -> 2.1875 | I7: =H7/(1+$C$6)^G7 -> 1.9711303 | J7: =I7/$I$62 -> 0.022736525 | K7: =J7*G7 -> 0.090946099 | L7: =G7*(G7+1)*I7 -> 39.422606 | O7: 0.03 | P7: 77.793558 | Q7: =$I$62*(1-$C$18*(O7-$C$5)) -> 145.76934 | R7: =$I$62*(1-$C$18*(O7-$C$5)+0.5*$C$19*((O7-$C$5)^2)) -> 178.36675
B8: Coupon | C8: =C4*C7 -> 4.375 | F8: =EDATE(F7,6) -> 46783 | G8: 5 | H8: =$C$9 -> 2.1875 | I8: =H8/(1+$C$6)^G8 -> 1.9204684 | J8: =I8/$I$62 -> 0.022152151 | K8: =J8*G8 -> 0.11076076 | L8: =G8*(G8+1)*I8 -> 57.614051 | O8: 0.035 | P8: 67.59907 | Q8: =$I$62*(1-$C$18*(O8-$C$5)) -> 132.79155 | R8: =$I$62*(1-$C$18*(O8-$C$5)+0.5*$C$19*((O8-$C$5)^2)) -> 152.6399
B9: Semi-Annually Coupon | C9: =C8/2 -> 2.1875 | F9: =EDATE(F8,6) -> 46965 | G9: 6 | H9: =$C$9 -> 2.1875 | I9: =H9/(1+$C$6)^G9 -> 1.8711085 | J9: =I9/$I$62 -> 0.021582797 | K9: =J9*G9 -> 0.12949678 | L9: =G9*(G9+1)*I9 -> 78.586558 | O9: 0.04 | P9: 59.34641 | Q9: =$I$62*(1-$C$18*(O9-$C$5)) -> 119.81376 | R9: =$I$62*(1-$C$18*(O9-$C$5)+0.5*$C$19*((O9-$C$5)^2)) -> 130.05942
B10: Issue Date | C10: 45869 | F10: =EDATE(F9,6) -> 47149 | G10: 7 | H10: =$C$9 -> 2.1875 | I10: =H10/(1+$C$6)^G10 -> 1.8230173 | J10: =I10/$I$62 -> 0.021028076 | K10: =J10*G10 -> 0.14719653 | L10: =G10*(G10+1)*I10 -> 102.08897 | O10: 0.045 | P10: 52.611704 | Q10: =$I$62*(1-$C$18*(O10-$C$5)) -> 106.83597 | R10: =$I$62*(1-$C$18*(O10-$C$5)+0.5*$C$19*((O10-$C$5)^2)) -> 110.6253
B11: Last Coupon Payment Date | C11: =C10 -> 45869 | F11: =EDATE(F10,6) -> 47330 | G11: 8 | H11: =$C$9 -> 2.1875 | I11: =H11/(1+$C$6)^G11 -> 1.7761622 | J11: =I11/$I$62 -> 0.020487613 | K11: =J11*G11 -> 0.1639009 | L11: =G11*(G11+1)*I11 -> 127.88368 | O11: 0.05 | P11: 47.070039 | Q11: =$I$62*(1-$C$18*(O11-$C$5)) -> 93.858181 | R11: =$I$62*(1-$C$18*(O11-$C$5)+0.5*$C$19*((O11-$C$5)^2)) -> 94.337535
B12: Next Coupon Payment Date | C12: =EDATE(C11,6) -> 46053 | F12: =EDATE(F11,6) -> 47514 | G12: 9 | H12: =$C$9 -> 2.1875 | I12: =H12/(1+$C$6)^G12 -> 1.7305113 | J12: =I12/$I$62 -> 0.019961041 | K12: =J12*G12 -> 0.17964937 | L12: =G12*(G12+1)*I12 -> 155.74602 | O12: 0.055 | P12: 42.471402 | Q12: =$I$62*(1-$C$18*(O12-$C$5)) -> 80.880392 | R12: =$I$62*(1-$C$18*(O12-$C$5)+0.5*$C$19*((O12-$C$5)^2)) -> 81.196136
B13: Settlement Date | C13: 46005 | F13: =EDATE(F12,6) -> 47695 | G13: 10 | H13: =$C$9 -> 2.1875 | I13: =H13/(1+$C$6)^G13 -> 1.6860337 | J13: =I13/$I$62 -> 0.019448002 | K13: =J13*G13 -> 0.19448002 | L13: =G13*(G13+1)*I13 -> 185.46371 | O13: 0.06 | P13: 38.622638 | Q13: =$I$62*(1-$C$18*(O13-$C$5)) -> 67.902603 | R13: =$I$62*(1-$C$18*(O13-$C$5)+0.5*$C$19*((O13-$C$5)^2)) -> 71.201097
B14: Maturity Date | C14: 56461 | F14: =EDATE(F13,6) -> 47879 | G14: 11 | H14: =$C$9 -> 2.1875 | I14: =H14/(1+$C$6)^G14 -> 1.6426993 | J14: =I14/$I$62 -> 0.01894815 | K14: =J14*G14 -> 0.20842965 | L14: =G14*(G14+1)*I14 -> 216.83631 | O14: 0.065 | P14: 35.373886 | Q14: =$I$62*(1-$C$18*(O14-$C$5)) -> 54.924814 | R14: =$I$62*(1-$C$18*(O14-$C$5)+0.5*$C$19*((O14-$C$5)^2)) -> 64.35242
F15: =EDATE(F14,6) -> 48060 | G15: 12 | H15: =$C$9 -> 2.1875 | I15: =H15/(1+$C$6)^G15 -> 1.6004787 | J15: =I15/$I$62 -> 0.018461145 | K15: =J15*G15 -> 0.22153374 | L15: =G15*(G15+1)*I15 -> 249.67467 | O15: 0.07 | P15: 32.608356 | Q15: =$I$62*(1-$C$18*(O15-$C$5)) -> 41.947025 | R15: =$I$62*(1-$C$18*(O15-$C$5)+0.5*$C$19*((O15-$C$5)^2)) -> 60.650103
F16: =EDATE(F15,6) -> 48244 | G16: 13 | H16: =$C$9 -> 2.1875 | I16: =H16/(1+$C$6)^G16 -> 1.5593432 | J16: =I16/$I$62 -> 0.017986657 | K16: =J16*G16 -> 0.23382654 | L16: =G16*(G16+1)*I16 -> 283.80046 | O16: 0.075 | P16: 30.234606 | Q16: =$I$62*(1-$C$18*(O16-$C$5)) -> 28.969236 | R16: =$I$62*(1-$C$18*(O16-$C$5)+0.5*$C$19*((O16-$C$5)^2)) -> 60.094148
B17: Macaulay Duration | C17: =K62 -> 31.518738 | F17: =EDATE(F16,6) -> 48426 | G17: 14 | H17: =$C$9 -> 2.1875 | I17: =H17/(1+$C$6)^G17 -> 1.519265 | J17: =I17/$I$62 -> 0.017524364 | K17: =J17*G17 -> 0.2453411 | L17: =G17*(G17+1)*I17 -> 319.04565 | O17: 0.08 | P17: 28.180692 | Q17: =$I$62*(1-$C$18*(O17-$C$5)) -> 15.991447 | R17: =$I$62*(1-$C$18*(O17-$C$5)+0.5*$C$19*((O17-$C$5)^2)) -> 62.684554
B18: Modified Duration | C18: =C17/(1+C5) -> 29.939149 | F18: =EDATE(F17,6) -> 48610 | G18: 15 | H18: =$C$9 -> 2.1875 | I18: =H18/(1+$C$6)^G18 -> 1.4802169 | J18: =I18/$I$62 -> 0.017073954 | K18: =J18*G18 -> 0.2561093 | L18: =G18*(G18+1)*I18 -> 355.25205
B19: Convexity | C19: =L62/I62 -> 1451.7014 | F19: =EDATE(F18,6) -> 48791 | G19: 16 | H19: =$C$9 -> 2.1875 | I19: =H19/(1+$C$6)^G19 -> 1.4421724 | J19: =I19/$I$62 -> 0.016635119 | K19: =J19*G19 -> 0.26616191 | L19: =G19*(G19+1)*I19 -> 392.27088
F20: =EDATE(F19,6) -> 48975 | G20: 17 | H20: =$C$9 -> 2.1875 | I20: =H20/(1+$C$6)^G20 -> 1.4051057 | J20: =I20/$I$62 -> 0.016207564 | K20: =J20*G20 -> 0.27552858 | L20: =G20*(G20+1)*I20 -> 429.96234
F21: =EDATE(F20,6) -> 49156 | G21: 18 | H21: =$C$9 -> 2.1875 | I21: =H21/(1+$C$6)^G21 -> 1.3689917 | J21: =I21/$I$62 -> 0.015790997 | K21: =J21*G21 -> 0.28423795 | L21: =G21*(G21+1)*I21 -> 468.19515
F22: =EDATE(F21,6) -> 49340 | G22: 19 | H22: =$C$9 -> 2.1875 | I22: =H22/(1+$C$6)^G22 -> 1.3338059 | J22: =I22/$I$62 -> 0.015385137 | K22: =J22*G22 -> 0.29231761 | L22: =G22*(G22+1)*I22 -> 506.84623
F23: =EDATE(F22,6) -> 49521 | G23: 20 | H23: =$C$9 -> 2.1875 | I23: =H23/(1+$C$6)^G23 -> 1.2995244 | J23: =I23/$I$62 -> 0.014989709 | K23: =J23*G23 -> 0.29979417 | L23: =G23*(G23+1)*I23 -> 545.80026
F24: =EDATE(F23,6) -> 49705 | G24: 21 | H24: =$C$9 -> 2.1875 | I24: =H24/(1+$C$6)^G24 -> 1.2661241 | J24: =I24/$I$62 -> 0.014604443 | K24: =J24*G24 -> 0.30669331 | L24: =G24*(G24+1)*I24 -> 584.94932
F25: =EDATE(F24,6) -> 49887 | G25: 22 | H25: =$C$9 -> 2.1875 | I25: =H25/(1+$C$6)^G25 -> 1.2335822 | J25: =I25/$I$62 -> 0.01422908 | K25: =J25*G25 -> 0.31303977 | L25: =G25*(G25+1)*I25 -> 624.19258
F26: =EDATE(F25,6) -> 50071 | G26: 23 | H26: =$C$9 -> 2.1875 | I26: =H26/(1+$C$6)^G26 -> 1.2018767 | J26: =I26/$I$62 -> 0.013863365 | K26: =J26*G26 -> 0.31885739 | L26: =G26*(G26+1)*I26 -> 663.43592
F27: =EDATE(F26,6) -> 50252 | G27: 24 | H27: =$C$9 -> 2.1875 | I27: =H27/(1+$C$6)^G27 -> 1.1709861 | J27: =I27/$I$62 -> 0.013507049 | K27: =J27*G27 -> 0.32416917 | L27: =G27*(G27+1)*I27 -> 702.59163
F28: =EDATE(F27,6) -> 50436 | G28: 25 | H28: =$C$9 -> 2.1875 | I28: =H28/(1+$C$6)^G28 -> 1.1408894 | J28: =I28/$I$62 -> 0.013159891 | K28: =J28*G28 -> 0.32899727 | L28: =G28*(G28+1)*I28 -> 741.5781
F29: =EDATE(F28,6) -> 50617 | G29: 26 | H29: =$C$9 -> 2.1875 | I29: =H29/(1+$C$6)^G29 -> 1.1115663 | J29: =I29/$I$62 -> 0.012821656 | K29: =J29*G29 -> 0.33336305 | L29: =G29*(G29+1)*I29 -> 780.31952
F30: =EDATE(F29,6) -> 50801 | G30: 27 | H30: =$C$9 -> 2.1875 | I30: =H30/(1+$C$6)^G30 -> 1.0829968 | J30: =I30/$I$62 -> 0.012492114 | K30: =J30*G30 -> 0.33728707 | L30: =G30*(G30+1)*I30 -> 818.74559
F31: =EDATE(F30,6) -> 50982 | G31: 28 | H31: =$C$9 -> 2.1875 | I31: =H31/(1+$C$6)^G31 -> 1.0551617 | J31: =I31/$I$62 -> 0.012171042 | K31: =J31*G31 -> 0.34078916 | L31: =G31*(G31+1)*I31 -> 856.79126
... F60: =EDATE(F59,6) -> 56280 | G60: 57 | H60: =$C$9 -> 2.1875 | I60: =H60/(1+$C$6)^G60 -> 0.4958859 | J60: =I60/$I$62 -> 0.0057199272 | K60: =J60*G60 -> 0.32603585 | L60: =G60*(G60+1)*I60 -> 1639.3988
F61: =EDATE(F60,6) -> 56461 | G61: 58 | H61: =$C$9+C4 -> 102.1875 | I61: =H61/(1+$C$6)^G61 -> 22.56957 | J61: =I61/$I$62 -> 0.26033469 | K61: =J61*G61 -> 15.099412 | L61: =G61*(G61+1)*I61 -> 77233.069
I62: =SUM(I4:I61) -> 86.694441 | K62: =SUM(K4:K61) -> 31.518738 | L62: =SUM(L4:L61) -> 125854.44

Sheet 30 Year Scenario
P2: Parallel Up | Q2: 0.0025 | AA2: Parallel Down | AB2: 0.0025
B3: 30-Year Bond | E3: Period | F3: Scenario Rate | G3: Cash Flow | H3: PV of CF | I3: PV as % of CF | J3: TW PV of CF | K3: Reivestment as per theory | M3: TW^2 PV of CF | P3: Period | Q3: Scenario Rate | R3: Cash Flow | S3: PV of CF | T3: PV as % of CF | U3: TW PV of CF | V3: Reivestment as per theory | X3: TW^2 PV of CF | AA3: Period | AB3: Scenario Rate | AC3: Cash Flow | AD3: PV of CF | AE3: PV as % of CF | AF3: TW PV of CF | AG3: Reivestment as per theory | AI3: TW^2 PV of CF
B4: Price | C4: 86.767 | E4: 1 | F4: =$C$7 -> 0.02638 | G4: =$C$10 -> 2.1875 | H4: =G4/(1+F4)^E4 -> 2.1312769 | I4: =H4/H$64 -> 0.024638171 | J4: =I4*E4 -> 0.024638171 | K4: =H4*(1+F4)^(E$35-E4) -> 4.7774207 | M4: =E4*(E4+1)*H4 -> 4.2625538 | P4: 1 | Q4: =$C$7 + INT((ROW()-4)/5)*$Q$2 -> 0.02638 | R4: =$C$10 -> 2.1875 | S4: =R4/(1+Q4)^P4 -> 2.1312769 | T4: =S4/S$64 -> 0.039449205 | U4: =T4*P4 -> 0.039449205 | V4: =S4*(1+Q4)^(P$35-P4) -> 4.7774207 | X4: =P4*(P4+1)*S4 -> 4.2625538 | AA4: 1 | AB4: =$C$7 + INT((ROW()-4)/5)*(-$Q$2) -> 0.02638 | AC4: =$C$10 -> 2.1875 | AD4: =AC4/(1+AB4)^AA4 -> 2.1312769 | AE4: =AD4/AD$64 -> 0.010061817 | AF4: =AE4*AA4 -> 0.010061817 | AG4: =AD4*(1+AB4)^(AA$35-AA4) -> 4.7774207 | AI4: =AA4*(AA4+1)*AD4 -> 4.2625538
B5: Face Value | C5: 100 | E5: 2 | F5: =$C$7 -> 0.02638 | G5: =$C$10 -> 2.1875 | H5: =G5/(1+F5)^E5 -> 2.0764989 | I5: =H5/H$64 -> 0.024004921 | J5: =I5*E5 -> 0.048009842 | K5: =H5*(1+F5)^(E$35-E5) -> 4.5349983 | M5: =E5*(E5+1)*H5 -> 12.458993 | P5: 2 | Q5: =$C$7 + INT((ROW()-4)/5)*$Q$2 -> 0.02638 | R5: =$C$10 -> 2.1875 | S5: =R5/(1+Q5)^P5 -> 2.0764989 | T5: =S5/S$64 -> 0.038435283 | U5: =T5*P5 -> 0.076870565 | V5: =S5*(1+Q5)^(P$35-P5) -> 4.5349983 | X5: =P5*(P5+1)*S5 -> 12.458993 | AA5: 2 | AB5: =$C$7 + INT((ROW()-4)/5)*(-$Q$2) -> 0.02638 | AC5: =$C$10 -> 2.1875 | AD5: =AC5/(1+AB5)^AA5 -> 2.0764989 | AE5: =AD5/AD$64 -> 0.0098032086 | AF5: =AE5*AA5 -> 0.019606417 | AG5: =AD5*(1+AB5)^(AA$35-AA5) -> 4.5349983 | AI5: =AA5*(AA5+1)*AD5 -> 12.458993
B6: Yield | C6: 0.05276 | E6: 3 | F6: =$C$7 -> 0.02638 | G6: =$C$10 -> 2.1875 | H6: =G6/(1+F6)^E6 -> 2.0231287 | I6: =H6/H$64 -> 0.023387947 | J6: =I6*E6 -> 0.070163841 | K6: =H6*(1+F6)^(E$35-E6) -> 4.3048772 | M6: =E6*(E6+1)*H6 -> 24.277545 | P6: 3 | Q6: =$C$7 + INT((ROW()-4)/5)*$Q$2 -> 0.02638 | R6: =$C$10 -> 2.1875 | S6: =R6/(1+Q6)^P6 -> 2.0231287 | T6: =S6/S$64 -> 0.03744742 | U6: =T6*P6 -> 0.11234226 | V6: =S6*(1+Q6)^(P$35-P6) -> 4.3048772 | X6: =P6*(P6+1)*S6 -> 24.277545 | AA6: 3 | AB6: =$C$7 + INT((ROW()-4)/5)*(-$Q$2) -> 0.02638 | AC6: =$C$10 -> 2.1875 | AD6: =AC6/(1+AB6)^AA6 -> 2.0231287 | AE6: =AD6/AD$64 -> 0.0095512468 | AF6: =AE6*AA6 -> 0.02865374 | AG6: =AD6*(1+AB6)^(AA$35-AA6) -> 4.3048772 | AI6: =AA6*(AA6+1)*AD6 -> 24.277545
B7: Semi-Annually Yield | C7: =C6/2 -> 0.02638 | E7: 4 | F7: =$C$7 -> 0.02638 | G7: =$C$10 -> 2.1875 | H7: =G7/(1+F7)^E7 -> 1.9711303 | I7: =H7/H$64 -> 0.022786831 | J7: =I7*E7 -> 0.091147322 | K7: =H7*(1+F7)^(E$35-E7) -> 4.0864332 | M7: =E7*(E7+1)*H7 -> 39.422606 | P7: 4 | Q7: =$C$7 + INT((ROW()-4)/5)*$Q$2 -> 0.02638 | R7: =$C$10 -> 2.1875 | S7: =R7/(1+Q7)^P7 -> 1.9711303 | T7: =S7/S$64 -> 0.036484947 | U7: =T7*P7 -> 0.14593979 | V7: =S7*(1+Q7)^(P$35-P7) -> 4.0864332 | X7: =P7*(P7+1)*S7 -> 39.422606 | AA7: 4 | AB7: =$C$7 + INT((ROW()-4)/5)*(-$Q$2) -> 0.02638 | AC7: =$C$10 -> 2.1875 | AD7: =AC7/(1+AB7)^AA7 -> 1.9711303 | AE7: =AD7/AD$64 -> 0.0093057608 | AF7: =AE7*AA7 -> 0.037223043 | AG7: =AD7*(1+AB7)^(AA$35-AA7) -> 4.0864332 | AI7: =AA7*(AA7+1)*AD7 -> 39.422606
B8: Coupon Rate | C8: 0.04375 | E8: 5 | F8: =$C$7 -> 0.02638 | G8: =$C$10 -> 2.1875 | H8: =G8/(1+F8)^E8 -> 1.9204684 | I8: =H8/H$64 -> 0.022201164 | J8: =I8*E8 -> 0.11100582 | K8: =H8*(1+F8)^(E$35-E8) -> 3.8790738 | M8: =E8*(E8+1)*H8 -> 57.614051 | P8: 5 | Q8: =$C$7 + INT((ROW()-4)/5)*$Q$2 -> 0.02638 | R8: =$C$10 -> 2.1875 | S8: =R8/(1+Q8)^P8 -> 1.9204684 | T8: =S8/S$64 -> 0.035547211 | U8: =T8*P8 -> 0.17773606 | V8: =S8*(1+Q8)^(P$35-P8) -> 3.8790738 | X8: =P8*(P8+1)*S8 -> 57.614051 | AA8: 5 | AB8: =$C$7 + INT((ROW()-4)/5)*(-$Q$2) -> 0.02638 | AC8: =$C$10 -> 2.1875 | AD8: =AC8/(1+AB8)^AA8 -> 1.9204684 | AE8: =AD8/AD$64 -> 0.0090665843 | AF8: =AE8*AA8 -> 0.045332921 | AG8: =AD8*(1+AB8)^(AA$35-AA8) -> 3.8790738 | AI8: =AA8*(AA8+1)*AD8 -> 57.614051
B9: Coupon | C9: =C5*C8 -> 4.375 | E9: 6 | F9: =$C$7 -> 0.02638 | G9: =$C$10 -> 2.1875 | H9: =G9/(1+F9)^E9 -> 1.8711085 | I9: =H9/H$64 -> 0.02163055 | J9: =I9*E9 -> 0.1297833 | K9: =H9*(1+F9)^(E$35-E9) -> 3.6822365 | M9: =E9*(E9+1)*H9 -> 78.586558 | P9: 6 | Q9: =$C$7 + INT((ROW()-4)/5)*$Q$2 -> 0.02888 | R9: =$C$10 -> 2.1875 | S9: =R9/(1+Q9)^P9 -> 1.8439949 | T9: =S9/S$64 -> 0.034131713 | U9: =T9*P9 -> 0.20479028 | V9: =S9*(1+Q9)^(P$35-P9) -> 3.8658283 | X9: =P9*(P9+1)*S9 -> 77.447785 | AA9: 6 | AB9: =$C$7 + INT((ROW()-4)/5)*(-$Q$2) -> 0.02388 | AC9: =$C$10 -> 2.1875 | AD9: =AC9/(1+AB9)^AA9 -> 1.8986884 | AE9: =AD9/AD$64 -> 0.0089637606 | AF9: =AE9*AA9 -> 0.053782564 | AG9: =AD9*(1+AB9)^(AA$35-AA9) -> 3.5069474 | AI9: =AA9*(AA9+1)*AD9 -> 79.744914
B10: Semi-Annually Coupon | C10: =C9/2 -> 2.1875 | E10: 7 | F10: =$C$7 -> 0.02638 | G10: =$C$10 -> 2.1875 | H10: =G10/(1+F10)^E10 -> 1.8230173 | I10: =H10/H$64 -> 0.021074602 | J10: =I10*E10 -> 0.14752221 | K10: =H10*(1+F10)^(E$35-E10) -> 3.4953874 | M10: =E10*(E10+1)*H10 -> 102.08897 | P10: 7 | Q10: =$C$7 + INT((ROW()-4)/5)*$Q$2 -> 0.02888 | R10: =$C$10 -> 2.1875 | S10: =R10/(1+Q10)^P10 -> 1.7922351 | T10: =S10/S$64 -> 0.033173658 | U10: =T10*P10 -> 0.23221561 | V10: =S10*(1+Q10)^(P$35-P10) -> 3.6518516 | X10: =P10*(P10+1)*S10 -> 100.36517 | AA10: 7 | AB10: =$C$7 + INT((ROW()-4)/5)*(-$Q$2) -> 0.02388 | AC10: =$C$10 -> 2.1875 | AD10: =AC10/(1+AB10)^AA10 -> 1.8544052 | AE10: =AD10/AD$64 -> 0.0087546984 | AF10: =AE10*AA10 -> 0.061282889 | AG10: =AD10*(1+AB10)^(AA$35-AA10) -> 3.3452697 | AI10: =AA10*(AA10+1)*AD10 -> 103.84669
B11: Issue Date | C11: 45869 | E11: 8 | F11: =$C$7 -> 0.02638 | G11: =$C$10 -> 2.1875 | H11: =G11/(1+F11)^E11 -> 1.7761622 | I11: =H11/H$64 -> 0.020532943 | J11: =I11*E11 -> 0.16426354 | K11: =H11*(1+F11)^(E$35-E11) -> 3.3180197 | M11: =E11*(E11+1)*H11 -> 127.88368 | P11: 8 | Q11: =$C$7 + INT((ROW()-4)/5)*$Q$2 -> 0.02888 | R11: =$C$10 -> 2.1875 | S11: =R11/(1+Q11)^P11 -> 1.7419282 | T11: =S11/S$64 -> 0.032242495 | U11: =T11*P11 -> 0.25793996 | V11: =S11*(1+Q11)^(P$35-P11) -> 3.4497186 | X11: =P11*(P11+1)*S11 -> 125.41883 | AA11: 8 | AB11: =$C$7 + INT((ROW()-4)/5)*(-$Q$2) -> 0.02388 | AC11: =$C$10 -> 2.1875 | AD11: =AC11/(1+AB11)^AA11 -> 1.8111549 | AE11: =AD11/AD$64 -> 0.0085505122 | AF11: =AE11*AA11 -> 0.068404097 | AG11: =AD11*(1+AB11)^(AA$35-AA11) -> 3.1910457 | AI11: =AA11*(AA11+1)*AD11 -> 130.40315
B12: Last Coupon Payment Date | C12: =C11 -> 45869 | E12: 9 | F12: =$C$7 -> 0.02638 | G12: =$C$10 -> 2.1875 | H12: =G12/(1+F12)^E12 -> 1.7305113 | I12: =H12/H$64 -> 0.020005206 | J12: =I12*E12 -> 0.18004685 | K12: =H12*(1+F12)^(E$35-E12) -> 3.1496522 | M12: =E12*(E12+1)*H12 -> 155.74602 | P12: 9 | Q12: =$C$7 + INT((ROW()-4)/5)*$Q$2 -> 0.02888 | R12: =$C$10 -> 2.1875 | S12: =R12/(1+Q12)^P12 -> 1.6930334 | T12: =S12/S$64 -> 0.031337469 | U12: =T12*P12 -> 0.28203722 | V12: =S12*(1+Q12)^(P$35-P12) -> 3.2587738 | X12: =P12*(P12+1)*S12 -> 152.37301 | AA12: 9 | AB12: =$C$7 + INT((ROW()-4)/5)*(-$Q$2) -> 0.02388 | AC12: =$C$10 -> 2.1875 | AD12: =AC12/(1+AB12)^AA12 -> 1.7689132 | AE12: =AD12/AD$64 -> 0.0083510882 | AF12: =AE12*AA12 -> 0.075159794 | AG12: =AD12*(1+AB12)^(AA$35-AA12) -> 3.0439317 | AI12: =AA12*(AA12+1)*AD12 -> 159.20219
B13: Next Coupon Payment Date | C13: =EDATE(C12,6) -> 46053 | E13: 10 | F13: =$C$7 -> 0.02638 | G13: =$C$10 -> 2.1875 | H13: =G13/(1+F13)^E13 -> 1.6860337 | I13: =H13/H$64 -> 0.019491032 | J13: =I13*E13 -> 0.19491032 | K13: =H13*(1+F13)^(E$35-E13) -> 2.9898282 | M13: =E13*(E13+1)*H13 -> 185.46371 | P13: 10 | Q13: =$C$7 + INT((ROW()-4)/5)*$Q$2 -> 0.02888 | R13: =$C$10 -> 2.1875 | S13: =R13/(1+Q13)^P13 -> 1.6455111 | T13: =S13/S$64 -> 0.030457846 | U13: =T13*P13 -> 0.30457846 | V13: =S13*(1+Q13)^(P$35-P13) -> 3.078398 | X13: =P13*(P13+1)*S13 -> 181.00622 | AA13: 10 | AB13: =$C$7 + INT((ROW()-4)/5)*(-$Q$2) -> 0.02388 | AC13: =$C$10 -> 2.1875 | AD13: =AC13/(1+AB13)^AA13 -> 1.7276568 | AE13: =AD13/AD$64 -> 0.0081563154 | AF13: =AE13*AA13 -> 0.081563154 | AG13: =AD13*(1+AB13)^(AA$35-AA13) -> 2.9035999 | AI13: =AA13*(AA13+1)*AD13 -> 190.04224
B14: Settlement Date | C14: =TODAY() -> 46006 | E14: 11 | F14: =$C$7 -> 0.02638 | G14: =$C$10 -> 2.1875 | H14: =G14/(1+F14)^E14 -> 1.6426993 | I14: =H14/H$64 -> 0.018990074 | J14: =I14*E14 -> 0.20889081 | K14: =H14*(1+F14)^(E$35-E14) -> 2.8381142 | M14: =E14*(E14+1)*H14 -> 216.83631 | P14: 11 | Q14: =$C$7 + INT((ROW()-4)/5)*$Q$2 -> 0.03138 | R14: =$C$10 -> 2.1875 | S14: =R14/(1+Q14)^P14 -> 1.5571925 | T14: =S14/S$64 -> 0.028823099 | U14: =T14*P14 -> 0.31705409 | V14: =S14*(1+Q14)^(P$35-P14) -> 2.9794432 | X14: =P14*(P14+1)*S14 -> 205.54941 | AA14: 11 | AB14: =$C$7 + INT((ROW()-4)/5)*(-$Q$2) -> 0.02138 | AC14: =$C$10 -> 2.1875 | AD14: =AC14/(1+AB14)^AA14 -> 1.7333538 | AE14: =AD14/AD$64 -> 0.0081832112 | AF14: =AE14*AA14 -> 0.090015324 | AG14: =AD14*(1+AB14)^(AA$35-AA14) -> 2.7028476 | AI14: =AA14*(AA14+1)*AD14 -> 228.8027
B15: Maturity Date | C15: 56461 | E15: 12 | F15: =$C$7 -> 0.02638 | G15: =$C$10 -> 2.1875 | H15: =G15/(1+F15)^E15 -> 1.6004787 | I15: =H15/H$64 -> 0.018501991 | J15: =I15*E15 -> 0.2220239 | K15: =H15*(1+F15)^(E$35-E15) -> 2.6940987 | M15: =E15*(E15+1)*H15 -> 249.67467 | P15: 12 | Q15: =$C$7 + INT((ROW()-4)/5)*$Q$2 -> 0.03138 | R15: =$C$10 -> 2.1875 | S15: =R15/(1+Q15)^P15 -> 1.5098145 | T15: =S15/S$64 -> 0.027946149 | U15: =T15*P15 -> 0.33535379 | V15: =S15*(1+Q15)^(P$35-P15) -> 2.8009007 | X15: =P15*(P15+1)*S15 -> 235.53106 | AA15: 12 | AB15: =$C$7 + INT((ROW()-4)/5)*(-$Q$2) -> 0.02138 | AC15: =$C$10 -> 2.1875 | AD15: =AC15/(1+AB15)^AA15 -> 1.6970704 | AE15: =AD15/AD$64 -> 0.0080119165 | AF15: =AE15*AA15 -> 0.096142998 | AG15: =AD15*(1+AB15)^(AA$35-AA15) -> 2.5908774 | AI15: =AA15*(AA15+1)*AD15 -> 264.74299
E16: 13 | F16: =$C$7 -> 0.02638 | G16: =$C$10 -> 2.1875 | H16: =G16/(1+F16)^E16 -> 1.5593432 | I16: =H16/H$64 -> 0.018026454 | J16: =I16*E16 -> 0.2343439 | K16: =H16*(1+F16)^(E$35-E16) -> 2.5573911 | M16: =E16*(E16+1)*H16 -> 283.80046 | P16: 13 | Q16: =$C$7 + INT((ROW()-4)/5)*$Q$2 -> 0.03138 | R16: =$C$10 -> 2.1875 | S16: =R16/(1+Q16)^P16 -> 1.463878 | T16: =S16/S$64 -> 0.027095881 | U16: =T16*P16 -> 0.35224645 | V16: =S16*(1+Q16)^(P$35-P16) -> 2.6330572 | X16: =P16*(P16+1)*S16 -> 266.4258 | AA16: 13 | AB16: =$C$7 + INT((ROW()-4)/5)*(-$Q$2) -> 0.02138 | AC16: =$C$10 -> 2.1875 | AD16: =AC16/(1+AB16)^AA16 -> 1.6615466 | AE16: =AD16/AD$64 -> 0.0078442073 | AF16: =AE16*AA16 -> 0.1019747 | AG16: =AD16*(1+AB16)^(AA$35-AA16) -> 2.4835457 | AI16: =AA16*(AA16+1)*AD16 -> 302.40148
E17: 14 | F17: =$C$7 -> 0.02638 | G17: =$C$10 -> 2.1875 | H17: =G17/(1+F17)^E17 -> 1.519265 | I17: =H17/H$64 -> 0.017563138 | J17: =I17*E17 -> 0.24588393 | K17: =H17*(1+F17)^(E$35-E17) -> 2.4276204 | M17: =E17*(E17+1)*H17 -> 319.04565 | P17: 14 | Q17: =$C$7 + INT((ROW()-4)/5)*$Q$2 -> 0.03138 | R17: =$C$10 -> 2.1875 | S17: =R17/(1+Q17)^P17 -> 1.4193392 | T17: =S17/S$64 -> 0.026271481 | U17: =T17*P17 -> 0.36780074 | V17: =S17*(1+Q17)^(P$35-P17) -> 2.4752717 | X17: =P17*(P17+1)*S17 -> 298.06122 | AA17: 14 | AB17: =$C$7 + INT((ROW()-4)/5)*(-$Q$2) -> 0.02138 | AC17: =$C$10 -> 2.1875 | AD17: =AC17/(1+AB17)^AA17 -> 1.6267663 | AE17: =AD17/AD$64 -> 0.0076800087 | AF17: =AE17*AA17 -> 0.10752012 | AG17: =AD17*(1+AB17)^(AA$35-AA17) -> 2.3806605 | AI17: =AA17*(AA17+1)*AD17 -> 341.62092
E18: 15 | F18: =$C$7 -> 0.02638 | G18: =$C$10 -> 2.1875 | H18: =G18/(1+F18)^E18 -> 1.4802169 | I18: =H18/H$64 -> 0.017111731 | J18: =I18*E18 -> 0.25667596 | K18: =H18*(1+F18)^(E$35-E18) -> 2.3044348 | M18: =E18*(E18+1)*H18 -> 355.25205 | P18: 15 | Q18: =$C$7 + INT((ROW()-4)/5)*$Q$2 -> 0.03138 | R18: =$C$10 -> 2.1875 | S18: =R18/(1+Q18)^P18 -> 1.3761554 | T18: =S18/S$64 -> 0.025472165 | U18: =T18*P18 -> 0.38208247 | V18: =S18*(1+Q18)^(P$35-P18) -> 2.3269415 | X18: =P18*(P18+1)*S18 -> 330.2773 | AA18: 15 | AB18: =$C$7 + INT((ROW()-4)/5)*(-$Q$2) -> 0.02138 | AC18: =$C$10 -> 2.1875 | AD18: =AC18/(1+AB18)^AA18 -> 1.5927141 | AE18: =AD18/AD$64 -> 0.0075192472 | AF18: =AE18*AA18 -> 0.11278871 | AG18: =AD18*(1+AB18)^(AA$35-AA18) -> 2.2820374 | AI18: =AA18*(AA18+1)*AD18 -> 382.25138
E19: 16 | F19: =$C$7 -> 0.02638 | G19: =$C$10 -> 2.1875 | H19: =G19/(1+F19)^E19 -> 1.4421724 | I19: =H19/H$64 -> 0.016671925 | J19: =I19*E19 -> 0.2667508 | K19: =H19*(1+F19)^(E$35-E19) -> 2.1875 | M19: =E19*(E19+1)*H19 -> 392.27088 | P19: 16 | Q19: =$C$7 + INT((ROW()-4)/5)*$Q$2 -> 0.03388 | R19: =$C$10 -> 2.1875 | S19: =R19/(1+Q19)^P19 -> 1.2835888 | T19: =S19/S$64 -> 0.023758789 | U19: =T19*P19 -> 0.38014062 | V19: =S19*(1+Q19)^(P$35-P19) -> 2.1875 | X19: =P19*(P19+1)*S19 -> 349.13615 | AA19: 16 | AB19: =$C$7 + INT((ROW()-4)/5)*(-$Q$2) -> 0.01888 | AC19: =$C$10 -> 2.1875 | AD19: =AC19/(1+AB19)^AA19 -> 1.6217334 | AE19: =AD19/AD$64 -> 0.0076562483 | AF19: =AE19*AA19 -> 0.12249997 | AG19: =AD19*(1+AB19)^(AA$35-AA19) -> 2.1875 | AI19: =AA19*(AA19+1)*AD19 -> 441.11149
E20: 17 | F20: =$C$7 -> 0.02638 | G20: =$C$10 -> 2.1875 | H20: =G20/(1+F20)^E20 -> 1.4051057 | I20: =H20/H$64 -> 0.016243424 | J20: =I20*E20 -> 0.2761382 | K20: =H20*(1+F20)^(E$35-E20) -> 2.0764989 | M20: =E20*(E20+1)*H20 -> 429.96234 | P20: 17 | Q20: =$C$7 + INT((ROW()-4)/5)*$Q$2 -> 0.03388 | R20: =$C$10 -> 2.1875 | S20: =R20/(1+Q20)^P20 -> 1.2415259 | T20: =S20/S$64 -> 0.022980219 | U20: =T20*P20 -> 0.39066372 | V20: =S20*(1+Q20)^(P$35-P20) -> 2.0464814 | X20: =P20*(P20+1)*S20 -> 379.90692 | AA20: 17 | AB20: =$C$7 + INT((ROW()-4)/5)*(-$Q$2) -> 0.01888 | AC20: =$C$10 -> 2.1875 | AD20: =AC20/(1+AB20)^AA20 -> 1.5916824 | AE20: =AD20/AD$64 -> 0.0075143769 | AF20: =AE20*AA20 -> 0.12774441 | AG20: =AD20*(1+AB20)^(AA$35-AA20) -> 2.1071817 | AI20: =AA20*(AA20+1)*AD20 -> 487.05483
E21: 18 | F21: =$C$7 -> 0.02638 | G21: =$C$10 -> 2.1875 | H21: =G21/(1+F21)^E21 -> 1.3689917 | I21: =H21/H$64 -> 0.015825936 | J21: =I21*E21 -> 0.28486684 | K21: =H21*(1+F21)^(E$35-E21) -> 1.9711303 | M21: =E21*(E21+1)*H21 -> 468.19515 | P21: 18 | Q21: =$C$7 + INT((ROW()-4)/5)*$Q$2 -> 0.03388 | R21: =$C$10 -> 2.1875 | S21: =R21/(1+Q21)^P21 -> 1.2008414 | T21: =S21/S$64 -> 0.022227163 | U21: =T21*P21 -> 0.40008893 | V21: =S21*(1+Q21)^(P$35-P21) -> 1.9145536 | X21: =P21*(P21+1)*S21 -> 410.68775 | AA21: 18 | AB21: =$C$7 + INT((ROW()-4)/5)*(-$Q$2) -> 0.01888 | AC21: =$C$10 -> 2.1875 | AD21: =AC21/(1+AB21)^AA21 -> 1.5621883 | AE21: =AD21/AD$64 -> 0.0073751343 | AF21: =AE21*AA21 -> 0.13275242 | AG21: =AD21*(1+AB21)^(AA$35-AA21) -> 2.0298125 | AI21: =AA21*(AA21+1)*AD21 -> 534.26841
E22: 19 | F22: =$C$7 -> 0.02638 | G22: =$C$10 -> 2.1875 | H22: =G22/(1+F22)^E22 -> 1.3338059 | I22: =H22/H$64 -> 0.015419178 | J22: =I22*E22 -> 0.29296437 | K22: =H22*(1+F22)^(E$35-E22) -> 1.8711085 | M22: =E22*(E22+1)*H22 -> 506.84623 | P22: 19 | Q22: =$C$7 + INT((ROW()-4)/5)*$Q$2 -> 0.03388 | R22: =$C$10 -> 2.1875 | S22: =R22/(1+Q22)^P22 -> 1.1614901 | T22: =S22/S$64 -> 0.021498784 | U22: =T22*P22 -> 0.40847689 | V22: =S22*(1+Q22)^(P$35-P22) -> 1.7911306 | X22: =P22*(P22+1)*S22 -> 441.36624 | AA22: 19 | AB22: =$C$7 + INT((ROW()-4)/5)*(-$Q$2) -> 0.01888 | AC22: =$C$10 -> 2.1875 | AD22: =AC22/(1+AB22)^AA22 -> 1.5332407 | AE22: =AD22/AD$64 -> 0.007238472 | AF22: =AE22*AA22 -> 0.13753097 | AG22: =AD22*(1+AB22)^(AA$35-AA22) -> 1.955284 | AI22: =AA22*(AA22+1)*AD22 -> 582.63148
E23: 20 | F23: =$C$7 -> 0.02638 | G23: =$C$10 -> 2.1875 | H23: =G23/(1+F23)^E23 -> 1.2995244 | I23: =H23/H$64 -> 0.015022874 | J23: =I23*E23 -> 0.30045748 | K23: =H23*(1+F23)^(E$35-E23) -> 1.7761622 | M23: =E23*(E23+1)*H23 -> 545.80026 | P23: 20 | Q23: =$C$7 + INT((ROW()-4)/5)*$Q$2 -> 0.03388 | R23: =$C$10 -> 2.1875 | S23: =R23/(1+Q23)^P23 -> 1.1234283 | T23: =S23/S$64 -> 0.020794274 | U23: =T23*P23 -> 0.41588548 | V23: =S23*(1+Q23)^(P$35-P23) -> 1.6756642 | X23: =P23*(P23+1)*S23 -> 471.83991 | AA23: 20 | AB23: =$C$7 + INT((ROW()-4)/5)*(-$Q$2) -> 0.01888 | AC23: =$C$10 -> 2.1875 | AD23: =AC23/(1+AB23)^AA23 -> 1.5048296 | AE23: =AD23/AD$64 -> 0.007104342 | AF23: =AE23*AA23 -> 0.14208684 | AG23: =AD23*(1+AB23)^(AA$35-AA23) -> 1.8834919 | AI23: =AA23*(AA23+1)*AD23 -> 632.02842
E24: 21 | F24: =$C$7 -> 0.02638 | G24: =$C$10 -> 2.1875 | H24: =G24/(1+F24)^E24 -> 1.2661241 | I24: =H24/H$64 -> 0.014636757 | J24: =I24*E24 -> 0.30737189 | K24: =H24*(1+F24)^(E$35-E24) -> 1.6860337 | M24: =E24*(E24+1)*H24 -> 584.94932 | P24: 21 | Q24: =$C$7 + INT((ROW()-4)/5)*$Q$2 -> 0.03638 | R24: =$C$10 -> 2.1875 | S24: =R24/(1+Q24)^P24 -> 1.0328769 | T24: =S24/S$64 -> 0.019118198 | U24: =T24*P24 -> 0.40148215 | V24: =S24*(1+Q24)^(P$35-P24) -> 1.5302339 | X24: =P24*(P24+1)*S24 -> 477.18913 | AA24: 21 | AB24: =$C$7 + INT((ROW()-4)/5)*(-$Q$2) -> 0.01638 | AC24: =$C$10 -> 2.1875 | AD24: =AC24/(1+AB24)^AA24 -> 1.5551409 | AE24: =AD24/AD$64 -> 0.0073418632 | AF24: =AE24*AA24 -> 0.15417913 | AG24: =AD24*(1+AB24)^(AA$35-AA24) -> 1.8594605 | AI24: =AA24*(AA24+1)*AD24 -> 718.47509
E25: 22 | F25: =$C$7 -> 0.02638 | G25: =$C$10 -> 2.1875 | H25: =G25/(1+F25)^E25 -> 1.2335822 | I25: =H25/H$64 -> 0.014260563 | J25: =I25*E25 -> 0.31373238 | K25: =H25*(1+F25)^(E$35-E25) -> 1.6004787 | M25: =E25*(E25+1)*H25 -> 624.19258 | P25: 22 | Q25: =$C$7 + INT((ROW()-4)/5)*$Q$2 -> 0.03638 | R25: =$C$10 -> 2.1875 | S25: =R25/(1+Q25)^P25 -> 0.99661988 | T25: =S25/S$64 -> 0.018447092 | U25: =T25*P25 -> 0.40583603 | W25: =SUM(V4:V24) -> 63.248551 | X25: =P25*(P25+1)*S25 -> 504.28966 | AA25: 22 | AB25: =$C$7 + INT((ROW()-4)/5)*(-$Q$2) -> 0.01638 | AC25: =$C$10 -> 2.1875 | AD25: =AC25/(1+AB25)^AA25 -> 1.5300782 | AE25: =AD25/AD$64 -> 0.0072235415 | AF25: =AE25*AA25 -> 0.15891791 | AG25: =AD25*(1+AB25)^(AA$35-AA25) -> 1.8000092 | AI25: =AA25*(AA25+1)*AD25 -> 774.21957
